Workbook
Name DATA1: #REF!
Name DATA10: #REF!
Name DATA11: #REF!
Name DATA12: #REF!
Name DATA13: #REF!
Name DATA14: #REF!
Name DATA15: #REF!
Name DATA16: #REF!
Name DATA17: #REF!
Name DATA18: #REF!
Name DATA19: #REF!
Name DATA2: #REF!
Name DATA20: #REF!
Name DATA21: #REF!
Name DATA22: #REF!
Name DATA23: #REF!
Name DATA24: #REF!
Name DATA25: #REF!
Name DATA26: #REF!
Name DATA27: #REF!
Name DATA28: #REF!
Name DATA29: #REF!
Name DATA3: #REF!
Name DATA30: #REF!
Name DATA31: #REF!
Name DATA32: #REF!
Name DATA33: #REF!
Name DATA34: #REF!
Name DATA35: #REF!
Name DATA36: #REF!
Name DATA37: #REF!
Name DATA38: #REF!
Name DATA39: #REF!
Name DATA4: #REF!
Name DATA40: #REF!
Name DATA41: #REF!
Name DATA42: #REF!
Name DATA43: #REF!
Name DATA44: #REF!
Name DATA45: #REF!
Name DATA46: #REF!
Name DATA47: #REF!
Name DATA48: #REF!
Name DATA49: #REF!
Name DATA5: #REF!
Name DATA50: #REF!
Name DATA51: #REF!
Name DATA52: #REF!
Name DATA53: #REF!
Name DATA54: #REF!
Name DATA55: #REF!
Name DATA6: #REF!
Name DATA7: #REF!
Name DATA8: #REF!
Name DATA9: #REF!
Name TEST1: #REF!
Name TEST10: #REF!
Name TEST11: #REF!
Name TEST2: #REF!
Name TEST3: #REF!

Sheet 表紙
A1: AMI-Q411 ver.340 | F1: 滅菌対象品一覧 | R1: 品質保証G
A5: 【目的】
A6: 本文書は、朝日インテック株式会社の医療機器で無菌性および製品性能保証される最大滅菌回数を示すものである。
A7: 製品ごとの情報は、3ページ目記載のリストを参照すること。なお各製品の文書に記載されてある有効長、製品外径、製品内径は、
A8: 滅菌品のワーストサンプルを選択する際に用いる参考情報である。
A9: 朝日インテックで実施される無菌試験、バイオバーデン試験およびエンドトキシン試験は下記に従い分類される。
A10: また、エアレーションファミリーも下記に従い分類される。
A12: 無菌試験及びバイオバーデン試験ファミリー | M12: エンドトキシン試験ファミリー
A13: # | B13: 区分 | M13: # | N13: 区分
A14: A | B14: AG | M14: A | N14: AG
A15: B | B15: AGH | M15: B | N15: AGH
A16: C | B16: AGP | M16: C | N16: AGP
A17: D | B17: Jacket | M17: D | N17: Jacket
A18: E | B18: プラスチックガイドワイヤ | M18: E | N18: プラスチックガイドワイヤ
A19: F | B19: カテーテル1 （ガイディングカテーテルヒアルロン酸コート） | M19: F | N19: カテーテル1 （ガイディングカテーテルヒアルロン酸コート）
A20: G | B20: カテーテル2 （ガイディングカテーテルヒアルロン酸コートなし/ 血管造影用カテーテル(CAGカテーテル)） | M20: G | N20: カテーテル2 （ガイディングカテーテルヒアルロン酸コートなし/ 血管造影用カテーテル(CAGカテーテル)）
A21: H | B21: マイクロカテーテル （マイクロカテーテル/貫通カテーテル） | M21: H | N21: マイクロカテーテル （マイクロカテーテル/貫通カテーテル）
A22: I | B22: バルーンカテーテル（RXタイプ） | M22: I | N22: バルーンカテーテル（RXタイプ）
A23: J | B23: バルーンカテーテル（OTWタイプ） | M23: J | N23: バルーンカテーテル（OTWタイプ）
A24: K | B24: Micro catheter accessory | M24: K | N24: Micro catheter accessory
... A29: P | B29: Torque device | M29: P | N29: AIMNGTOME
M30: Q | N30: Torque device
A32: エアレーションファミリー | M32: 微粒汚染ファミリー
A33: # | B33: 区分 | M33: # | N33: 区分
A34: ① | B34: Guide wire, circular type | M34: A | N34: Guide wire
A35: ② | B35: Non balloon catheter, Straight type | M35: B | N35: Non balloon catheter (CatheterⅠ/Micro Catheter)
A36: ③ | B36: Non balloon catheter, Circular type | M36: C | N36: Non balloon catheter (CatheterⅡ)
A37: ④ | B37: Tornus Catheter | M37: D | N37: SASUKE
A38: ⑤ | B38: Balloon Catheter, Circular type （50℃×300min sterilization） | M38: E | N38: Accessory
A39: ⑥ | B39: Balloon Catheter, Circular type （43 ℃×360min sterilization）
A40: ⑦ | B40: Balloon Catheter, Straight type （50℃×300min sterilization）
A41: ⑧ | B41: Balloon Catheter, Straight type （43 ℃×360min sterilization）
A42: ⑨ | B42: Accessories and Oter Items （50℃×300min sterilization）
A43: ⑩ | B43: Accessories and Oter Items （50℃×2000min sterilization）
A44: ⑪ | B44: Endoscopy device（Tornus ES）
A45: ⑫ | B45: Endoscopy device（AIMINGTOME）
A46: ⑬ | B46: Endoscopy device（Endoligar）
A49: 【改訂履歴】
A50: Ver. | C50: 改訂年月日 | G50: 改定内容
A51: 338 | C51: 46029 | G51: ・変更提案№AMW-Q02050130(#53947)に伴い、MDR製品にＴＦＣ C号機追加（2131014, 2131015, 2131021, 2131023, 2131024, 2131026, 2131027, 2131029, 2131031, 2131033, 2131035, 2131037, 2131052, 2131054, 2131056, 2131058, 2131076, 2131077, 2131080,～2131083, 2131110, 2131111, 2131114, 2131115, 2331087) 引用文書：滅菌バリレポート AMD-Q251593, 滅菌回数に関するレポート AMD-Q250314 品質連絡書：AMC-C250409（承認取得連絡）
...

Sheet リスト
A1: =[1]表紙!A1 -> AMI-Q411 ver.340 | B1: 滅菌対象品一覧 | E1: 品質保証G
A3: 文書番号リスト
A4: 製品シリーズ | B4: 対象拠点
B5: Seto | C5: AITM | D5: AIHM | E5: TFCM
A6: SION series | B6: AMI-Q411-S001 | D6: AMI-Q411-H001 | E6: AMI-Q411-C001
A7: Gaia series | D7: AMI-Q411-H002 | E7: AMI-Q411-C002
A8: Fielder series | D8: AMI-Q411-H003 | E8: AMI-Q411-C003
A9: Gladius and Halberd | D9: AMI-Q411-H004 | E9: AMI-Q411-C004
A10: Crosslead
A11: MINAMO series
A12: CHIKAI series | D12: AMI-Q411-H007 | E12: AMI-Q411-C007
A13: CELLHAWK
A14: CROSSLOOP | D14: AMI-Q411-H009
A15: Penetration catheter | D15: AMI-Q411-H010
A16: Microcatheter | D16: AMI-Q411-H011
A17: Hyperion | D17: AMI-Q411-H012
A18: Hyperion SheathLess
A19: FUBUKI | D19: AMI-Q411-H014
A20: Branchor series
A21: Kamui series | D21: AMI-Q411-H016
A22: SASUKE
A23: Endoscopy Guidewire | D23: AMI-Q411-H018
A24: Endoscopy Devices | D24: AMI-Q411-H019
A25: SP Guidewire | D25: AMI-Q411-H020
A26: CAG | D26: AMI-Q411-H021
A27: PL Guidewire | D27: AMI-Q411-H022
A28: Other Guidewire(AG) | D28: AMI-Q411-H101 | E28: AMI-Q411-C101
A29: Other Guidewire(AGH) | D29: AMI-Q411-H102 | E29: AMI-Q411-C102
A30: Other Guidewire(AGP) | D30: AMI-Q411-H103 | E30: AMI-Q411-C103
A31: Other Guidewire(Jacket) | D31: AMI-Q411-H104 | E31: AMI-Q411-C104
A32: Other Guiding catheter
A33: Other Balloon catheter
A34: GW | C34: AMI-Q411-T101
A35: Catheter | C35: AMI-Q411-T102
A36: Penetration catheter | C36: AMI-Q411-T103
A37: Micro catheter | C37: AMI-Q411-T104
A38: Balloon catheter | C38: AMI-Q411-T105
A39: The Others | C39: AMI-Q411-T107 | D39: AMI-Q411-H107
A40: Filmecc | C40: AMI-Q411-T108 | D40: AMI-Q411-H108 | E40: AMI-Q411-H108

Sheet ALL
B1: AMI-Q411 ver.340 | C1: 滅菌対象品一覧AIHM(SION series) | S1: 品質保証G
B4: 製品名 | C4: Product Information | D4: 図番 | E4: カタログコード | F4: 仕向け先 | G4: Chamber | K4: 滅菌ファミリー | L4: 滅菌条件 | M4: 無菌試験 ファミリー | N4: バイオバーデン ファミリー | O4: ｴﾝﾄﾞﾄｷｼﾝ試験 ファミリー | P4: エアレーション ファミリー | Q4: 微粒汚染 ファミリー | R4: Length [mm] | S4: O.D.[mm] (Shaft or core) | T4: I.D. [mm] (Shaft) | U4: 滅菌バリデーション | V4: 製品評価レポート | W4: 薬事承認書 | X4: 変更提案、品質関連連絡書 | Z4: No | AA4: Group
G5: A | H5: B | I5: C | J5: D
A7: =D7&E7 -> 1036068AHW14R001S CN (use Tyvek) | B7: ASAHI PTCA Guide Wire ASAHI SION 180cm | C7: PTCA(AGH) | D7: 1036068 | E7: AHW14R001S CN (use Tyvek) | F7: CHINA | G7: 2 | H7: 2 | I7: 2 | J7: 2 | K7: Guide wire circular type | L7: 50°C, 300 minutes Sterilization | M7: B | N7: B | O7: B | P7: ① | Q7: N/A | R7: 1817 | S7: 0.36 | T7: NA | Z7: 1 | AA7: H001
A8: =D8&E8 -> 1036068AHW14R001S CN (use PS-55) | B8: ASAHI PTCA Guide Wire ASAHI SION 180cm | C8: PTCA(AGH) | D8: 1036068 | E8: AHW14R001S CN (use PS-55) | F8: CHINA | G8: 2 | H8: 2 | I8: 2 | J8: 2 | K8: Guide wire circular type | L8: 50°C, 300 minutes Sterilization | M8: B | N8: B | O8: B | P8: ① | Q8: N/A | R8: 1817 | S8: 0.36 | T8: NA | U8: VAL2308011-21 | X8: AMW-Q20230289(#37671) | Z8: 2 | AA8: H001
A9: =D9&E9 -> 1036069AHW14R301S CN | B9: ASAHI PTCA Guide Wire ASAHI SION 300cm | C9: PTCA(AGH) | D9: 1036069 | E9: AHW14R301S CN | F9: CHINA | G9: 2 | H9: 2 | I9: 2 | J9: 2 | K9: Guide wire circular type | L9: 50°C, 300 minutes Sterilization | M9: B | N9: B | O9: B | P9: ① | Q9: N/A | R9: 3037 | S9: 0.36 | T9: NA | Z9: 3 | AA9: H001
A10: =D10&E10 -> 1436196AHW14R004S CN (use Tyvek) | B10: ASAHI PTCA Guide Wire ASAHI SION blue 180cm | C10: PTCA(AGH) | D10: 1436196 | E10: AHW14R004S CN (use Tyvek) | F10: CHINA | G10: 3 | H10: 3 | I10: 2 | J10: 2 | K10: Guide wire circular type | L10: 50°C, 300 minutes Sterilization | M10: B | N10: B | O10: B | P10: ① | Q10: N/A | R10: 1810 | S10: 0.36 | T10: NA | U10: VA0223-01, VA0226-01 | Z10: 4 | AA10: H001
A11: =D11&E11 -> 1436196AHW14R004S CN (use PS-55) | B11: ASAHI PTCA Guide Wire ASAHI SION blue 180cm | C11: PTCA(AGH) | D11: 1436196 | E11: AHW14R004S CN (use PS-55) | F11: CHINA | G11: 2 | H11: 2 | I11: × | J11: × | K11: Guide wire circular type | L11: 50°C, 300 minutes Sterilization | M11: B | N11: B | O11: B | P11: ① | Q11: N/A | R11: 1810 | S11: 0.36 | T11: NA | U11: VAL2308011-21 | X11: AMW-Q20230289(#37671) | Z11: 5 | AA11: H001
A12: =D12&E12 -> 1436197AHW14R304S CN | B12: ASAHI PTCA Guide Wire ASAHI SION blue 300cm | C12: PTCA(AGH) | D12: 1436197 | E12: AHW14R304S CN | F12: CHINA | G12: 3 | H12: 3 | I12: 2 | J12: 2 | K12: Guide wire circular type | L12: 50°C, 300 minutes Sterilization | M12: B | N12: B | O12: B | P12: ① | Q12: N/A | R12: 3030 | S12: 0.36 | T12: NA | U12: VA0223-01, VA0226-01 | Z12: 6 | AA12: H001
A13: =D13&E13 -> 1436198AHW14R004J CN | B13: ASAHI PTCA Guide Wire ASAHI SION blue 180cm J | C13: PTCA(AGH) | D13: 1436198 | E13: AHW14R004J CN | F13: CHINA | G13: 3 | H13: 3 | I13: 2 | J13: 2 | K13: Guide wire circular type | L13: 50°C, 300 minutes Sterilization | M13: B | N13: B | O13: B | P13: ① | Q13: N/A | R13: 1810 | S13: 0.36 | T13: NA | U13: VA0223-01, VA0226-01 | Z13: 7 | AA13: H001
A14: =D14&E14 -> 1436199AHW14R304J CN | B14: ASAHI PTCA Guide Wire ASAHI SION blue 300cm J | C14: PTCA(AGH) | D14: 1436199 | E14: AHW14R304J CN | F14: CHINA | G14: 3 | H14: 3 | I14: 2 | J14: 2 | K14: Guide wire circular type | L14: 50°C, 300 minutes Sterilization | M14: B | N14: B | O14: B | P14: ① | Q14: N/A | R14: 3030 | S14: 0.36 | T14: NA | U14: VA0223-01, VA0226-01 | Z14: 8 | AA14: H001
A15: =D15&E15 -> 1436300APW14R010P CN | B15: ASAHI PTCA Guide Wire ASAHI SION black Pre-shpe 190cm | C15: PTCA(AGP) | D15: 1436300 | E15: APW14R010P CN | F15: CHINA | G15: 2 | H15: 2 | I15: 2 | J15: 2 | K15: Guide wire circular type | L15: 50°C, 300 minutes Sterilization | M15: C | N15: C | O15: C | P15: ① | Q15: N/A | R15: 1910 | S15: 0.35 | T15: NA | Z15: 9 | AA15: H001
A16: =D16&E16 -> 1436301APW14R310P CN | B16: ASAHI PTCA Guide Wire ASAHI SION black Pre-shpe 300cm | C16: PTCA(AGP) | D16: 1436301 | E16: APW14R310P CN | F16: CHINA | G16: 2 | H16: 2 | I16: 2 | J16: 2 | K16: Guide wire circular type | L16: 50°C, 300 minutes Sterilization | M16: C | N16: C | O16: C | P16: ① | Q16: N/A | R16: 3020 | S16: 0.35 | T16: NA | Z16: 10 | AA16: H001
A17: =D17&E17 -> 1436302APW14R010S CN | B17: ASAHI PTCA Guide Wire ASAHI SION black Straight 190cm | C17: PTCA(AGP) | D17: 1436302 | E17: APW14R010S CN | F17: CHINA | G17: 2 | H17: 2 | I17: 2 | J17: 2 | K17: Guide wire circular type | L17: 50°C, 300 minutes Sterilization | M17: C | N17: C | O17: C | P17: ① | Q17: N/A | R17: 1910 | S17: 0.35 | T17: NA | Z17: 11 | AA17: H001
A18: =D18&E18 -> 1436303APW14R310S CN | B18: ASAHI PTCA Guide Wire ASAHI SION black Straight 300cm | C18: PTCA(AGP) | D18: 1436303 | E18: APW14R310S CN | F18: CHINA | G18: 2 | H18: 2 | I18: 2 | J18: 2 | K18: Guide wire circular type | L18: 50°C, 300 minutes Sterilization | M18: C | N18: C | O18: C | P18: ① | Q18: N/A | R18: 3020 | S18: 0.35 | T18: NA | Z18: 12 | AA18: H001
A19: =D19&E19 -> 1436304APW14R010J CN | B19: ASAHI PTCA Guide Wire ASAHI SION black 190cm J | C19: PTCA(AGP) | D19: 1436304 | E19: APW14R010J CN | F19: CHINA | G19: 2 | H19: 2 | I19: 2 | J19: 2 | K19: Guide wire circular type | L19: 50°C, 300 minutes Sterilization | M19: C | N19: C | O19: C | P19: ① | Q19: N/A | R19: 1910 | S19: 0.35 | T19: NA | Z19: 13 | AA19: H001
A20: =D20&E20 -> 1436305APW14R310J CN | B20: ASAHI PTCA Guide Wire ASAHI SION black 300cm J | C20: PTCA(AGP) | D20: 1436305 | E20: APW14R310J CN | F20: CHINA | G20: 2 | H20: 2 | I20: 2 | J20: 2 | K20: Guide wire circular type | L20: 50°C, 300 minutes Sterilization | M20: C | N20: C | O20: C | P20: ① | Q20: N/A | R20: 3020 | S20: 0.35 | T20: NA | Z20: 14 | AA20: H001
A21: =D21&E21 -> 1536015APW14R010S KR | B21: ASAHI PTCA Guide Wire ASAHI SION black STRAIGHT | C21: PTCA(AGP) | D21: 1536015 | E21: APW14R010S KR | F21: KR | G21: 2 | H21: 2 | I21: 2 | J21: 2 | K21: Guide wire circular type | L21: 50°C, 300 minutes Sterilization | M21: C | N21: C | O21: C | P21: ① | Q21: N/A | R21: 1910 | S21: 0.35 | T21: NA | Z21: 15 | AA21: H001
A22: =D22&E22 -> 1536016APW14R310S KR | B22: ASAHI PTCA Guide Wire ASAHI SION black STRAIGHT 300cm | C22: PTCA(AGP) | D22: 1536016 | E22: APW14R310S KR | F22: KR | G22: 2 | H22: 2 | I22: 2 | J22: 2 | K22: Guide wire circular type | L22: 50°C, 300 minutes Sterilization | M22: C | N22: C | O22: C | P22: ① | Q22: N/A | R22: 3020 | S22: 0.35 | T22: NA | Z22: 16 | AA22: H001
A23: =D23&E23 -> 1536017APW14R010P KR | B23: ASAHI PTCA Guide Wire ASAHI SION black pre-shape | C23: PTCA(AGP) | D23: 1536017 | E23: APW14R010P KR | F23: KR | G23: 2 | H23: 2 | I23: 2 | J23: 2 | K23: Guide wire circular type | L23: 50°C, 300 minutes Sterilization | M23: C | N23: C | O23: C | P23: ① | Q23: N/A | R23: 1910 | S23: 0.35 | T23: NA | Z23: 17 | AA23: H001
A24: =D24&E24 -> 1536018APW14R310P KR | B24: ASAHI PTCA Guide Wire ASAHI SION black pre-shape 300cm | C24: PTCA(AGP) | D24: 1536018 | E24: APW14R310P KR | F24: KR | G24: 2 | H24: 2 | I24: 2 | J24: 2 | K24: Guide wire circular type | L24: 50°C, 300 minutes Sterilization | M24: C | N24: C | O24: C | P24: ① | Q24: N/A | R24: 3020 | S24: 0.35 | T24: NA | Z24: 18 | AA24: H001
A25: =D25&E25 -> 1536019APW14R010J KR | B25: ASAHI PTCA Guide Wire ASAHI SION black J | C25: PTCA(AGP) | D25: 1536019 | E25: APW14R010J KR | F25: KR | G25: 2 | H25: 2 | I25: 2 | J25: 2 | K25: Guide wire circular type | L25: 50°C, 300 minutes Sterilization | M25: C | N25: C | O25: C | P25: ① | Q25: N/A | R25: 1910 | S25: 0.35 | T25: NA | Z25: 19 | AA25: H001
A26: =D26&E26 -> 1536020APW14R310J KR | B26: ASAHI PTCA Guide Wire ASAHI SION black 300cm J | C26: PTCA(AGP) | D26: 1536020 | E26: APW14R310J KR | F26: KR | G26: 2 | H26: 2 | I26: 2 | J26: 2 | K26: Guide wire circular type | L26: 50°C, 300 minutes Sterilization | M26: C | N26: C | O26: C | P26: ① | Q26: N/A | R26: 3020 | S26: 0.35 | T26: NA | Z26: 20 | AA26: H001
... A34: =D34&E34 -> 1536095AHW14R304J KR | B34: ASAHI PTCA Guide Wire ASAHI SION blue 300cm J | C34: PTCA(AGH) | D34: 1536095 | E34: AHW14R304J KR | F34: KR | G34: 3 | H34: 3 | I34: 2 | J34: 2 | K34: Guide wire circular type | L34: 50°C, 300 minutes Sterilization | M34: B | N34: B | O34: B | P34: ① | Q34: N/A | R34: 3030 | S34: 0.36 | T34: NA | Z34: 28 | AA34: H001
A35: =D35&E35 -> 1731115AHW14R001S US | B35: ASAHI PTCA Guide Wire ASAHI SION 180cm | C35: PTCA(AGH) | D35: 1731115 | E35: AHW14R001S US | F35: US | G35: 2 | H35: 2 | I35: 2 | J35: 2 | K35: Guide wire circular type | L35: 50°C, 300 minutes Sterilization | M35: B | N35: B | O35: B | P35: ① | Q35: N/A | R35: 1817 | S35: 0.36 | T35: NA | U35: VAL2003002-2、VAL2008008-21 | Z35: 29 | AA35: H001
A36: =D36&E36 -> 1731116AHW14R301S US | B36: ASAHI PTCA Guide Wire ASAHI SION 300cm | C36: PTCA(AGH) | D36: 1731116 | E36: AHW14R301S US | F36: US | G36: 2 | H36: 2 | I36: 2 | J36: 2 | K36: Guide wire circular type | L36: 50°C, 300 minutes Sterilization | M36: B | N36: B | O36: B | P36: ① | Q36: N/A | R36: 3037 | S36: 0.36 | T36: NA | U36: VAL2003002-2、VAL2008008-21 | Z36: 30 | AA36: H001
A37: =D37&E37 -> 1731147AHW14R001J US | B37: ASAHI PTCA Guide Wire ASAHI SION 180cm J | C37: PTCA(AGH) | D37: 1731147 | E37: AHW14R001J US | F37: US | G37: 2 | H37: 2 | I37: 2 | J37: 2 | K37: Guide wire circular type | L37: 50°C, 300 minutes Sterilization | M37: B | N37: B | O37: B | P37: ① | Q37: N/A | R37: 1817 | S37: 0.36 | T37: NA | U37: VAL2003002-2、VAL2008008-21 | Z37: 31 | AA37: H001
A38: =D38&E38 -> 1731148AHW14R301J US | B38: ASAHI PTCA Guide Wire ASAHI SION 300cm J | C38: PTCA(AGH) | D38: 1731148 | E38: AHW14R301J US | F38: US | G38: 2 | H38: 2 | I38: 2 | J38: 2 | K38: Guide wire circular type | L38: 50°C, 300 minutes Sterilization | M38: B | N38: B | O38: B | P38: ① | Q38: N/A | R38: 3037 | S38: 0.36 | T38: NA | U38: VAL2003002-2、VAL2008008-21 | Z38: 32 | AA38: H001
A39: =D39&E39 -> 1731149AHW14R004S US | B39: ASAHI PTCA Guide Wire ASAHI SION blue 180cm | C39: PTCA(AGH) | D39: 1731149 | E39: AHW14R004S US | F39: US | G39: 3 | H39: 3 | I39: 2 | J39: 2 | K39: Guide wire circular type | L39: 50°C, 300 minutes Sterilization | M39: B | N39: B | O39: B | P39: ① | Q39: N/A | R39: 1810 | S39: 0.36 | T39: NA | U39: VAL2003002-2、VAL2008008-21 | Z39: 33 | AA39: H001
A40: =D40&E40 -> 1731150AHW14R004J US | B40: ASAHI PTCA Guide Wire ASAHI SION blue 180cm J | C40: PTCA(AGH) | D40: 1731150 | E40: AHW14R004J US | F40: US | G40: 3 | H40: 3 | I40: 2 | J40: 2 | K40: Guide wire circular type | L40: 50°C, 300 minutes Sterilization | M40: B | N40: B | O40: B | P40: ① | Q40: N/A | R40: 1810 | S40: 0.36 | T40: NA | U40: VAL2003002-2、VAL2008008-21 | Z40: 34 | AA40: H001
A41: =D41&E41 -> 1731151AHW14R304S US | B41: ASAHI PTCA Guide Wire ASAHI SION blue 300cm | C41: PTCA(AGH) | D41: 1731151 | E41: AHW14R304S US | F41: US | G41: 3 | H41: 3 | I41: 2 | J41: 2 | K41: Guide wire circular type | L41: 50°C, 300 minutes Sterilization | M41: B | N41: B | O41: B | P41: ① | Q41: N/A | R41: 3030 | S41: 0.36 | T41: NA | U41: VAL2003002-2、VAL2008008-21 | Z41: 35 | AA41: H001
A42: =D42&E42 -> 1731152AHW14R304J US | B42: ASAHI PTCA Guide Wire ASAHI SION blue 300cm J | C42: PTCA(AGH) | D42: 1731152 | E42: AHW14R304J US | F42: US | G42: 3 | H42: 3 | I42: 2 | J42: 2 | K42: Guide wire circular type | L42: 50°C, 300 minutes Sterilization | M42: B | N42: B | O42: B | P42: ① | Q42: N/A | R42: 3030 | S42: 0.36 | T42: NA | U42: VAL2003002-2、VAL2008008-21 | Z42: 36 | AA42: H001
A43: =D43&E43 -> 1731153APW14R010S US | B43: ASAHI PTCA Guide Wire ASAHI SION black Straight 190cm | C43: PTCA(AGP) | D43: 1731153 | E43: APW14R010S US | F43: US | G43: 2 | H43: 2 | I43: 2 | J43: 2 | K43: Guide wire circular type | L43: 50°C, 300 minutes Sterilization | M43: C | N43: C | O43: C | P43: ① | Q43: N/A | R43: 1910 | S43: 0.35 | T43: NA | U43: VAL2003002-2、VAL2008008-21, AMD-Q220859, AMD-Q230875, TMVAL2302001-2 | V43: AMD-Q240305, AMD-Q240308, AMD-Q240306 | Z43: 37 | AA43: H001
A44: =D44&E44 -> 1731154APW14R310S US | B44: ASAHI PTCA Guide Wire ASAHI SION black Straight 300cm | C44: PTCA(AGP) | D44: 1731154 | E44: APW14R310S US | F44: US | G44: 2 | H44: 2 | I44: 2 | J44: 2 | K44: Guide wire circular type | L44: 50°C, 300 minutes Sterilization | M44: C | N44: C | O44: C | P44: ① | Q44: N/A | R44: 3020 | S44: 0.35 | T44: NA | U44: VAL2003002-2、VAL2008008-21, AMD-Q220859, AMD-Q230875, TMVAL2302001-2 | V44: AMD-Q240305, AMD-Q240308, AMD-Q240306 | Z44: 38 | AA44: H001
A45: =D45&E45 -> 1731155APW14R010P US | B45: ASAHI PTCA Guide Wire ASAHI SION black Pre-shape 190cm | C45: PTCA(AGP) | D45: 1731155 | E45: APW14R010P US | F45: US | G45: 2 | H45: 2 | I45: 2 | J45: 2 | K45: Guide wire circular type | L45: 50°C, 300 minutes Sterilization | M45: C | N45: C | O45: C | P45: ① | Q45: N/A | R45: 1910 | S45: 0.35 | T45: NA | U45: VAL2003002-2、VAL2008008-21, AMD-Q220859, AMD-Q230875, TMVAL2302001-2 | V45: AMD-Q240305, AMD-Q240308, AMD-Q240306 | Z45: 39 | AA45: H001
A46: =D46&E46 -> 1731156APW14R310P US | B46: ASAHI PTCA Guide Wire ASAHI SION black Pre-shape 300cm | C46: PTCA(AGP) | D46: 1731156 | E46: APW14R310P US | F46: US | G46: 2 | H46: 2 | I46: 2 | J46: 2 | K46: Guide wire circular type | L46: 50°C, 300 minutes Sterilization | M46: C | N46: C | O46: C | P46: ① | Q46: N/A | R46: 3020 | S46: 0.35 | T46: NA | U46: VAL2003002-2、VAL2008008-21, AMD-Q220859, AMD-Q230875, TMVAL2302001-2 | V46: AMD-Q240305, AMD-Q240308, AMD-Q240306 | Z46: 40 | AA46: H001
A47: =D47&E47 -> 1731157APW14R010J US | B47: ASAHI PTCA Guide Wire ASAHI SION black 190cm J | C47: PTCA(AGP) | D47: 1731157 | E47: APW14R010J US | F47: US | G47: 2 | H47: 2 | I47: 2 | J47: 2 | K47: Guide wire circular type | L47: 50°C, 300 minutes Sterilization | M47: C | N47: C | O47: C | P47: ① | Q47: N/A | R47: 1910 | S47: 0.35 | T47: NA | U47: VAL2003002-2、VAL2008008-21, AMD-Q220859, AMD-Q230875, TMVAL2302001-2 | V47: AMD-Q240305, AMD-Q240308, AMD-Q240306 | Z47: 41 | AA47: H001
A48: =D48&E48 -> 1731158APW14R310J US | B48: ASAHI PTCA Guide Wire ASAHI SION black 300cm J | C48: PTCA(AGP) | D48: 1731158 | E48: APW14R310J US | F48: US | G48: 2 | H48: 2 | I48: 2 | J48: 2 | K48: Guide wire circular type | L48: 50°C, 300 minutes Sterilization | M48: C | N48: C | O48: C | P48: ① | Q48: N/A | R48: 3020 | S48: 0.35 | T48: NA | U48: VAL2003002-2、VAL2008008-21, AMD-Q220859, AMD-Q230875, TMVAL2302001-2 | V48: AMD-Q240305, AMD-Q240308, AMD-Q240306 | Z48: 42 | AA48: H001
A49: =D49&E49 -> 1831178AH14R104SR JP | B49: ASAHI PTCA Guide Wire ASAHI SION blue 190cm | C49: PTCA(AGH) | D49: 1831178 | E49: AH14R104SR JP | F49: J-sales | G49: 3 | H49: 3 | I49: 3 | J49: 3 | K49: Guide wire circular type | L49: 50°C, 300 minutes Sterilization | M49: B | N49: B | O49: B | P49: ① | Q49: N/A | R49: 1910 | S49: 0.36 | T49: NA | U49: VAL2003002-2、VAL2008008-21, TMVAL2104004-2［V1］、AMD-I210603 | V49: AMD-DA41431031, AMD-Q210326,AMD-Q220850 | W49: AMC-C181530, AMC-C210506 | Z49: 43 | AA49: H001
A50: =D50&E50 -> 1831179AH14R004SR JP | B50: ASAHI PTCA Guide Wire ASAHI SION blue | C50: PTCA(AGH) | D50: 1831179 | E50: AH14R004SR JP | F50: J-sales | G50: 3 | H50: 3 | I50: 3 | J50: 3 | K50: Guide wire circular type | L50: 50°C, 300 minutes Sterilization | M50: B | N50: B | O50: B | P50: ① | Q50: N/A | R50: 1810 | S50: 0.36 | T50: NA | U50: VAL2003002-2、VAL2008008-21, TMVAL2104004-2［V1］、AMD-I210603 | V50: AMD-DA41431032, AMD-Q210326,AMD-Q220850 | W50: AMC-C181530 AMC-C210506 | Z50: 44 | AA50: H001
...

Sheet H001 Ver2
A1: AMI-Q411-H001 Ver.2 | B1: 滅菌対象品一覧AIHM(SION series) | R1: 品質保証G
A4: 製品名 | B4: Product Information | C4: 図番 | D4: カタログコード | E4: 仕向け先 | F4: Chamber | J4: 滅菌ファミリー | K4: 滅菌条件 | L4: 無菌試験 ファミリー | M4: バイオバーデン ファミリー | N4: ｴﾝﾄﾞﾄｷｼﾝ試験 ファミリー | O4: エアレーション ファミリー | P4: 微粒汚染 ファミリー | Q4: Length [mm] | R4: O.D.[mm] (Shaft or core) | S4: I.D. [mm] (Shaft) | T4: 滅菌バリデーション | U4: 製品評価レポート | V4: 薬事承認書 | W4: 変更提案、品質関連連絡書
F5: A | G5: B | H5: C | I5: D
A6: ASAHI PTCA Guide Wire ASAHI SION 180cm | B6: PTCA(AGH) | C6: 1036068 | D6: AHW14R001S CN (use Tyvek) | E6: CHINA | F6: 2 | G6: 2 | H6: 2 | I6: 2 | J6: Guide wire circular type | K6: 50°C, 300 minutes Sterilization | L6: B | M6: B | N6: B | O6: ① | P6: N/A | Q6: 1817 | R6: 0.36 | S6: NA
A7: ASAHI PTCA Guide Wire ASAHI SION 180cm | B7: PTCA(AGH) | C7: 1036068 | D7: AHW14R001S CN (use PS-55) | E7: CHINA | F7: 2 | G7: 2 | H7: × | I7: × | J7: Guide wire circular type | K7: 50°C, 300 minutes Sterilization | L7: B | M7: B | N7: B | O7: ① | P7: N/A | Q7: 1817 | R7: 0.36 | S7: NA | T7: VAL2308011-21 | W7: AMW-Q20230289(#37671)
A8: ASAHI PTCA Guide Wire ASAHI SION 300cm | B8: PTCA(AGH) | C8: 1036069 | D8: AHW14R301S CN | E8: CHINA | F8: 2 | G8: 2 | H8: 2 | I8: 2 | J8: Guide wire circular type | K8: 50°C, 300 minutes Sterilization | L8: B | M8: B | N8: B | O8: ① | P8: N/A | Q8: 3037 | R8: 0.36 | S8: NA
A9: ASAHI PTCA Guide Wire ASAHI SION blue 180cm | B9: PTCA(AGH) | C9: 1436196 | D9: AHW14R004S CN (use Tyvek) | E9: CHINA | F9: 3 | G9: 3 | H9: 2 | I9: 2 | J9: Guide wire circular type | K9: 50°C, 300 minutes Sterilization | L9: B | M9: B | N9: B | O9: ① | P9: N/A | Q9: 1810 | R9: 0.36 | S9: NA | T9: VA0223-01, VA0226-01
A10: ASAHI PTCA Guide Wire ASAHI SION blue 180cm | B10: PTCA(AGH) | C10: 1436196 | D10: AHW14R004S CN (use PS-55) | E10: CHINA | F10: 2 | G10: 2 | H10: × | I10: × | J10: Guide wire circular type | K10: 50°C, 300 minutes Sterilization | L10: B | M10: B | N10: B | O10: ① | P10: N/A | Q10: 1810 | R10: 0.36 | S10: NA | T10: VAL2308011-21 | W10: AMW-Q20230289(#37671)
A11: ASAHI PTCA Guide Wire ASAHI SION blue 300cm | B11: PTCA(AGH) | C11: 1436197 | D11: AHW14R304S CN | E11: CHINA | F11: 3 | G11: 3 | H11: 2 | I11: 2 | J11: Guide wire circular type | K11: 50°C, 300 minutes Sterilization | L11: B | M11: B | N11: B | O11: ① | P11: N/A | Q11: 3030 | R11: 0.36 | S11: NA | T11: VA0223-01, VA0226-01
A12: ASAHI PTCA Guide Wire ASAHI SION blue 180cm J | B12: PTCA(AGH) | C12: 1436198 | D12: AHW14R004J CN | E12: CHINA | F12: 3 | G12: 3 | H12: 2 | I12: 2 | J12: Guide wire circular type | K12: 50°C, 300 minutes Sterilization | L12: B | M12: B | N12: B | O12: ① | P12: N/A | Q12: 1810 | R12: 0.36 | S12: NA | T12: VA0223-01, VA0226-01
A13: ASAHI PTCA Guide Wire ASAHI SION blue 300cm J | B13: PTCA(AGH) | C13: 1436199 | D13: AHW14R304J CN | E13: CHINA | F13: 3 | G13: 3 | H13: 2 | I13: 2 | J13: Guide wire circular type | K13: 50°C, 300 minutes Sterilization | L13: B | M13: B | N13: B | O13: ① | P13: N/A | Q13: 3030 | R13: 0.36 | S13: NA | T13: VA0223-01, VA0226-01
A14: ASAHI PTCA Guide Wire ASAHI SION black Pre-shpe 190cm | B14: PTCA(AGP) | C14: 1436300 | D14: APW14R010P CN | E14: CHINA | F14: 2 | G14: 2 | H14: 2 | I14: 2 | J14: Guide wire circular type | K14: 50°C, 300 minutes Sterilization | L14: C | M14: C | N14: C | O14: ① | P14: N/A | Q14: 1910 | R14: 0.35 | S14: NA
A15: ASAHI PTCA Guide Wire ASAHI SION black Pre-shpe 300cm | B15: PTCA(AGP) | C15: 1436301 | D15: APW14R310P CN | E15: CHINA | F15: 2 | G15: 2 | H15: 2 | I15: 2 | J15: Guide wire circular type | K15: 50°C, 300 minutes Sterilization | L15: C | M15: C | N15: C | O15: ① | P15: N/A | Q15: 3020 | R15: 0.35 | S15: NA
A16: ASAHI PTCA Guide Wire ASAHI SION black Straight 190cm | B16: PTCA(AGP) | C16: 1436302 | D16: APW14R010S CN | E16: CHINA | F16: 2 | G16: 2 | H16: 2 | I16: 2 | J16: Guide wire circular type | K16: 50°C, 300 minutes Sterilization | L16: C | M16: C | N16: C | O16: ① | P16: N/A | Q16: 1910 | R16: 0.35 | S16: NA
A17: ASAHI PTCA Guide Wire ASAHI SION black Straight 300cm | B17: PTCA(AGP) | C17: 1436303 | D17: APW14R310S CN | E17: CHINA | F17: 2 | G17: 2 | H17: 2 | I17: 2 | J17: Guide wire circular type | K17: 50°C, 300 minutes Sterilization | L17: C | M17: C | N17: C | O17: ① | P17: N/A | Q17: 3020 | R17: 0.35 | S17: NA
A18: ASAHI PTCA Guide Wire ASAHI SION black 190cm J | B18: PTCA(AGP) | C18: 1436304 | D18: APW14R010J CN | E18: CHINA | F18: 2 | G18: 2 | H18: 2 | I18: 2 | J18: Guide wire circular type | K18: 50°C, 300 minutes Sterilization | L18: C | M18: C | N18: C | O18: ① | P18: N/A | Q18: 1910 | R18: 0.35 | S18: NA
A19: ASAHI PTCA Guide Wire ASAHI SION black 300cm J | B19: PTCA(AGP) | C19: 1436305 | D19: APW14R310J CN | E19: CHINA | F19: 2 | G19: 2 | H19: 2 | I19: 2 | J19: Guide wire circular type | K19: 50°C, 300 minutes Sterilization | L19: C | M19: C | N19: C | O19: ① | P19: N/A | Q19: 3020 | R19: 0.35 | S19: NA
A20: ASAHI PTCA Guide Wire ASAHI SION black STRAIGHT | B20: PTCA(AGP) | C20: 1536015 | D20: APW14R010S KR | E20: KR | F20: 2 | G20: 2 | H20: 2 | I20: 2 | J20: Guide wire circular type | K20: 50°C, 300 minutes Sterilization | L20: C | M20: C | N20: C | O20: ① | P20: N/A | Q20: 1910 | R20: 0.35 | S20: NA
A21: ASAHI PTCA Guide Wire ASAHI SION black STRAIGHT 300cm | B21: PTCA(AGP) | C21: 1536016 | D21: APW14R310S KR | E21: KR | F21: 2 | G21: 2 | H21: 2 | I21: 2 | J21: Guide wire circular type | K21: 50°C, 300 minutes Sterilization | L21: C | M21: C | N21: C | O21: ① | P21: N/A | Q21: 3020 | R21: 0.35 | S21: NA
A22: ASAHI PTCA Guide Wire ASAHI SION black pre-shape | B22: PTCA(AGP) | C22: 1536017 | D22: APW14R010P KR | E22: KR | F22: 2 | G22: 2 | H22: 2 | I22: 2 | J22: Guide wire circular type | K22: 50°C, 300 minutes Sterilization | L22: C | M22: C | N22: C | O22: ① | P22: N/A | Q22: 1910 | R22: 0.35 | S22: NA
A23: ASAHI PTCA Guide Wire ASAHI SION black pre-shape 300cm | B23: PTCA(AGP) | C23: 1536018 | D23: APW14R310P KR | E23: KR | F23: 2 | G23: 2 | H23: 2 | I23: 2 | J23: Guide wire circular type | K23: 50°C, 300 minutes Sterilization | L23: C | M23: C | N23: C | O23: ① | P23: N/A | Q23: 3020 | R23: 0.35 | S23: NA
A24: ASAHI PTCA Guide Wire ASAHI SION black J | B24: PTCA(AGP) | C24: 1536019 | D24: APW14R010J KR | E24: KR | F24: 2 | G24: 2 | H24: 2 | I24: 2 | J24: Guide wire circular type | K24: 50°C, 300 minutes Sterilization | L24: C | M24: C | N24: C | O24: ① | P24: N/A | Q24: 1910 | R24: 0.35 | S24: NA
A25: ASAHI PTCA Guide Wire ASAHI SION black 300cm J | B25: PTCA(AGP) | C25: 1536020 | D25: APW14R310J KR | E25: KR | F25: 2 | G25: 2 | H25: 2 | I25: 2 | J25: Guide wire circular type | K25: 50°C, 300 minutes Sterilization | L25: C | M25: C | N25: C | O25: ① | P25: N/A | Q25: 3020 | R25: 0.35 | S25: NA
... A33: ASAHI PTCA Guide Wire ASAHI SION blue 300cm J | B33: PTCA(AGH) | C33: 1536095 | D33: AHW14R304J KR | E33: KR | F33: 3 | G33: 3 | H33: 2 | I33: 2 | J33: Guide wire circular type | K33: 50°C, 300 minutes Sterilization | L33: B | M33: B | N33: B | O33: ① | P33: N/A | Q33: 3030 | R33: 0.36 | S33: NA
A34: ASAHI PTCA Guide Wire ASAHI SION 180cm | B34: PTCA(AGH) | C34: 1731115 | D34: AHW14R001S US | E34: US | F34: 2 | G34: 2 | H34: 2 | I34: 2 | J34: Guide wire circular type | K34: 50°C, 300 minutes Sterilization | L34: B | M34: B | N34: B | O34: ① | P34: N/A | Q34: 1817 | R34: 0.36 | S34: NA | T34: VAL2003002-2、VAL2008008-21
A35: ASAHI PTCA Guide Wire ASAHI SION 300cm | B35: PTCA(AGH) | C35: 1731116 | D35: AHW14R301S US | E35: US | F35: 2 | G35: 2 | H35: 2 | I35: 2 | J35: Guide wire circular type | K35: 50°C, 300 minutes Sterilization | L35: B | M35: B | N35: B | O35: ① | P35: N/A | Q35: 3037 | R35: 0.36 | S35: NA | T35: VAL2003002-2、VAL2008008-21
A36: ASAHI PTCA Guide Wire ASAHI SION 180cm J | B36: PTCA(AGH) | C36: 1731147 | D36: AHW14R001J US | E36: US | F36: 2 | G36: 2 | H36: 2 | I36: 2 | J36: Guide wire circular type | K36: 50°C, 300 minutes Sterilization | L36: B | M36: B | N36: B | O36: ① | P36: N/A | Q36: 1817 | R36: 0.36 | S36: NA | T36: VAL2003002-2、VAL2008008-21
A37: ASAHI PTCA Guide Wire ASAHI SION 300cm J | B37: PTCA(AGH) | C37: 1731148 | D37: AHW14R301J US | E37: US | F37: 2 | G37: 2 | H37: 2 | I37: 2 | J37: Guide wire circular type | K37: 50°C, 300 minutes Sterilization | L37: B | M37: B | N37: B | O37: ① | P37: N/A | Q37: 3037 | R37: 0.36 | S37: NA | T37: VAL2003002-2、VAL2008008-21
A38: ASAHI PTCA Guide Wire ASAHI SION blue 180cm | B38: PTCA(AGH) | C38: 1731149 | D38: AHW14R004S US | E38: US | F38: 3 | G38: 3 | H38: 2 | I38: 2 | J38: Guide wire circular type | K38: 50°C, 300 minutes Sterilization | L38: B | M38: B | N38: B | O38: ① | P38: N/A | Q38: 1810 | R38: 0.36 | S38: NA | T38: VAL2003002-2、VAL2008008-21
A39: ASAHI PTCA Guide Wire ASAHI SION blue 180cm J | B39: PTCA(AGH) | C39: 1731150 | D39: AHW14R004J US | E39: US | F39: 3 | G39: 3 | H39: 2 | I39: 2 | J39: Guide wire circular type | K39: 50°C, 300 minutes Sterilization | L39: B | M39: B | N39: B | O39: ① | P39: N/A | Q39: 1810 | R39: 0.36 | S39: NA | T39: VAL2003002-2、VAL2008008-21
A40: ASAHI PTCA Guide Wire ASAHI SION blue 300cm | B40: PTCA(AGH) | C40: 1731151 | D40: AHW14R304S US | E40: US | F40: 3 | G40: 3 | H40: 2 | I40: 2 | J40: Guide wire circular type | K40: 50°C, 300 minutes Sterilization | L40: B | M40: B | N40: B | O40: ① | P40: N/A | Q40: 3030 | R40: 0.36 | S40: NA | T40: VAL2003002-2、VAL2008008-21
A41: ASAHI PTCA Guide Wire ASAHI SION blue 300cm J | B41: PTCA(AGH) | C41: 1731152 | D41: AHW14R304J US | E41: US | F41: 3 | G41: 3 | H41: 2 | I41: 2 | J41: Guide wire circular type | K41: 50°C, 300 minutes Sterilization | L41: B | M41: B | N41: B | O41: ① | P41: N/A | Q41: 3030 | R41: 0.36 | S41: NA | T41: VAL2003002-2、VAL2008008-21
A42: ASAHI PTCA Guide Wire ASAHI SION black Straight 190cm | B42: PTCA(AGP) | C42: 1731153 | D42: APW14R010S US | E42: US | F42: 2 | G42: 2 | H42: 2 | I42: 2 | J42: Guide wire circular type | K42: 50°C, 300 minutes Sterilization | L42: C | M42: C | N42: C | O42: ① | P42: N/A | Q42: 1910 | R42: 0.35 | S42: NA | T42: VAL2003002-2、VAL2008008-21, AMD-Q220859, AMD-Q230875, TMVAL2302001-2 | U42: AMD-Q240305, AMD-Q240308, AMD-Q240306
A43: ASAHI PTCA Guide Wire ASAHI SION black Straight 300cm | B43: PTCA(AGP) | C43: 1731154 | D43: APW14R310S US | E43: US | F43: 2 | G43: 2 | H43: 2 | I43: 2 | J43: Guide wire circular type | K43: 50°C, 300 minutes Sterilization | L43: C | M43: C | N43: C | O43: ① | P43: N/A | Q43: 3020 | R43: 0.35 | S43: NA | T43: VAL2003002-2、VAL2008008-21, AMD-Q220859, AMD-Q230875, TMVAL2302001-2 | U43: AMD-Q240305, AMD-Q240308, AMD-Q240306
A44: ASAHI PTCA Guide Wire ASAHI SION black Pre-shape 190cm | B44: PTCA(AGP) | C44: 1731155 | D44: APW14R010P US | E44: US | F44: 2 | G44: 2 | H44: 2 | I44: 2 | J44: Guide wire circular type | K44: 50°C, 300 minutes Sterilization | L44: C | M44: C | N44: C | O44: ① | P44: N/A | Q44: 1910 | R44: 0.35 | S44: NA | T44: VAL2003002-2、VAL2008008-21, AMD-Q220859, AMD-Q230875, TMVAL2302001-2 | U44: AMD-Q240305, AMD-Q240308, AMD-Q240306
A45: ASAHI PTCA Guide Wire ASAHI SION black Pre-shape 300cm | B45: PTCA(AGP) | C45: 1731156 | D45: APW14R310P US | E45: US | F45: 2 | G45: 2 | H45: 2 | I45: 2 | J45: Guide wire circular type | K45: 50°C, 300 minutes Sterilization | L45: C | M45: C | N45: C | O45: ① | P45: N/A | Q45: 3020 | R45: 0.35 | S45: NA | T45: VAL2003002-2、VAL2008008-21, AMD-Q220859, AMD-Q230875, TMVAL2302001-2 | U45: AMD-Q240305, AMD-Q240308, AMD-Q240306
A46: ASAHI PTCA Guide Wire ASAHI SION black 190cm J | B46: PTCA(AGP) | C46: 1731157 | D46: APW14R010J US | E46: US | F46: 2 | G46: 2 | H46: 2 | I46: 2 | J46: Guide wire circular type | K46: 50°C, 300 minutes Sterilization | L46: C | M46: C | N46: C | O46: ① | P46: N/A | Q46: 1910 | R46: 0.35 | S46: NA | T46: VAL2003002-2、VAL2008008-21, AMD-Q220859, AMD-Q230875, TMVAL2302001-2 | U46: AMD-Q240305, AMD-Q240308, AMD-Q240306
A47: ASAHI PTCA Guide Wire ASAHI SION black 300cm J | B47: PTCA(AGP) | C47: 1731158 | D47: APW14R310J US | E47: US | F47: 2 | G47: 2 | H47: 2 | I47: 2 | J47: Guide wire circular type | K47: 50°C, 300 minutes Sterilization | L47: C | M47: C | N47: C | O47: ① | P47: N/A | Q47: 3020 | R47: 0.35 | S47: NA | T47: VAL2003002-2、VAL2008008-21, AMD-Q220859, AMD-Q230875, TMVAL2302001-2 | U47: AMD-Q240305, AMD-Q240308, AMD-Q240306
A48: ASAHI PTCA Guide Wire ASAHI SION blue 190cm | B48: PTCA(AGH) | C48: 1831178 | D48: AH14R104SR JP | E48: J-sales | F48: 3 | G48: 3 | H48: 3 | I48: 3 | J48: Guide wire circular type | K48: 50°C, 300 minutes Sterilization | L48: B | M48: B | N48: B | O48: ① | P48: N/A | Q48: 1910 | R48: 0.36 | S48: NA | T48: VAL2003002-2、VAL2008008-21, TMVAL2104004-2［V1］、AMD-I210603 | U48: AMD-DA41431031, AMD-Q210326,AMD-Q220850 | V48: AMC-C181530, AMC-C210506
A49: ASAHI PTCA Guide Wire ASAHI SION blue | B49: PTCA(AGH) | C49: 1831179 | D49: AH14R004SR JP | E49: J-sales | F49: 3 | G49: 3 | H49: 3 | I49: 3 | J49: Guide wire circular type | K49: 50°C, 300 minutes Sterilization | L49: B | M49: B | N49: B | O49: ① | P49: N/A | Q49: 1810 | R49: 0.36 | S49: NA | T49: VAL2003002-2、VAL2008008-21, TMVAL2104004-2［V1］、AMD-I210603 | U49: AMD-DA41431032, AMD-Q210326,AMD-Q220850 | V49: AMC-C181530 AMC-C210506
...

Sheet H002
A1: =[2]表紙!A1 -> AMI-Q411-H002 Ver.1 | B1: 滅菌対象品一覧AIHM(Gaia series) | R1: 品質保証G
A4: 製品名 | B4: Product Information | C4: 図番 | D4: カタログコード | E4: 仕向け先 | F4: Chamber | J4: 滅菌ファミリー | K4: 滅菌条件 | L4: 無菌試験 ファミリー | M4: バイオバーデン ファミリー | N4: ｴﾝﾄﾞﾄｷｼﾝ試験 ファミリー | O4: エアレーション ファミリー | P4: 微粒汚染 ファミリー | Q4: Length [mm] | R4: O.D.[mm] (Shaft or core) | S4: I.D. [mm] (Shaft) | T4: 滅菌バリデーション | U4: 製品評価レポート | V4: 薬事承認書 | W4: 変更提案、品質関連連絡書
F5: A | G5: B | H5: C | I5: D
A6: ASAHI PTCA Guide Wire ASAHI Gaia Firsr Pre-shape 190cm | B6: PTCA(AGH) | C6: 1136431 | D6: AHW14R007P CN | E6: CHINA | F6: 2 | G6: 2 | H6: 2 | I6: 2 | J6: Guide wire circular type | K6: 50°C, 300 minutes Sterilization | L6: B | M6: B | N6: B | O6: ① | P6: N/A | Q6: 1906 | R6: 0.36 | S6: NA
A7: ASAHI PTCA Guide Wire ASAHI Gaia Firsr Pre-shape 300cm | B7: PTCA(AGH) | C7: 1136432 | D7: AHW14R307P CN | E7: CHINA | F7: 2 | G7: 2 | H7: 2 | I7: 2 | J7: Guide wire circular type | K7: 50°C, 300 minutes Sterilization | L7: B | M7: B | N7: B | O7: ① | P7: N/A | Q7: 3026 | R7: 0.36 | S7: NA
A8: ASAHI PTCA Guide Wire ASAHI Gaia Firsr Straight 190cm | B8: PTCA(AGH) | C8: 1136433 | D8: AHW14R007S CN | E8: CHINA | F8: 2 | G8: 2 | H8: 2 | I8: 2 | J8: Guide wire circular type | K8: 50°C, 300 minutes Sterilization | L8: B | M8: B | N8: B | O8: ① | P8: N/A | Q8: 1906 | R8: 0.36 | S8: NA
A9: ASAHI PTCA Guide Wire ASAHI Gaia Firsr Straight 300cm | B9: PTCA(AGH) | C9: 1136434 | D9: AHW14R307S CN | E9: CHINA | F9: 2 | G9: 2 | H9: 2 | I9: 2 | J9: Guide wire circular type | K9: 50°C, 300 minutes Sterilization | L9: B | M9: B | N9: B | O9: ① | P9: N/A | Q9: 3026 | R9: 0.36 | S9: NA
A10: ASAHI PTCA Guide Wire ASAHI Gaia Second Pre-shape 190cm | B10: PTCA(AGH) | C10: 1436288 | D10: AHW14R008P CN | E10: CHINA | F10: 2 | G10: 2 | H10: 2 | I10: 2 | J10: Guide wire circular type | K10: 50°C, 300 minutes Sterilization | L10: B | M10: B | N10: B | O10: ① | P10: N/A | Q10: 1900 | R10: 0.36 | S10: NA
A11: ASAHI PTCA Guide Wire ASAHI Gaia Second Pre-shape 300cm | B11: PTCA(AGH) | C11: 1436289 | D11: AHW14R308P CN | E11: CHINA | F11: 2 | G11: 2 | H11: 2 | I11: 2 | J11: Guide wire circular type | K11: 50°C, 300 minutes Sterilization | L11: B | M11: B | N11: B | O11: ① | P11: N/A | Q11: 3020 | R11: 0.36 | S11: NA
A12: ASAHI PTCA Guide Wire ASAHI Gaia Second Straight 190cm | B12: PTCA(AGH) | C12: 1436290 | D12: AHW14R008S CN | E12: CHINA | F12: 2 | G12: 2 | H12: 2 | I12: 2 | J12: Guide wire circular type | K12: 50°C, 300 minutes Sterilization | L12: B | M12: B | N12: B | O12: ① | P12: N/A | Q12: 1900 | R12: 0.36 | S12: NA
A13: ASAHI PTCA Guide Wire ASAHI Gaia Second Straight 300cm | B13: PTCA(AGH) | C13: 1436291 | D13: AHW14R308S CN | E13: CHINA | F13: 2 | G13: 2 | H13: 2 | I13: 2 | J13: Guide wire circular type | K13: 50°C, 300 minutes Sterilization | L13: B | M13: B | N13: B | O13: ① | P13: N/A | Q13: 3020 | R13: 0.36 | S13: NA
A14: ASAHI PTCA Guide Wire ASAHI Gaia Third Pre-shape 190cm | B14: PTCA(AGH) | C14: 1436292 | D14: AHW14R011P CN | E14: CHINA | F14: 2 | G14: 2 | H14: 2 | I14: 2 | J14: Guide wire circular type | K14: 50°C, 300 minutes Sterilization | L14: B | M14: B | N14: B | O14: ① | P14: N/A | Q14: 1900 | R14: 0.36 | S14: NA
A15: ASAHI PTCA Guide Wire ASAHI Gaia Third Pre-shape 300cm | B15: PTCA(AGH) | C15: 1436293 | D15: AHW14R311P CN | E15: CHINA | F15: 2 | G15: 2 | H15: 2 | I15: 2 | J15: Guide wire circular type | K15: 50°C, 300 minutes Sterilization | L15: B | M15: B | N15: B | O15: ① | P15: N/A | Q15: 3020 | R15: 0.36 | S15: NA
A16: ASAHI PTCA Guide Wire ASAHI Gaia Third Straight 190cm | B16: PTCA(AGH) | C16: 1436294 | D16: AHW14R011S CN | E16: CHINA | F16: 2 | G16: 2 | H16: 2 | I16: 2 | J16: Guide wire circular type | K16: 50°C, 300 minutes Sterilization | L16: B | M16: B | N16: B | O16: ① | P16: N/A | Q16: 1900 | R16: 0.36 | S16: NA
A17: ASAHI PTCA Guide Wire ASAHI Gaia Third Straight 300cm | B17: PTCA(AGH) | C17: 1436295 | D17: AHW14R311S CN | E17: CHINA | F17: 2 | G17: 2 | H17: 2 | I17: 2 | J17: Guide wire circular type | K17: 50°C, 300 minutes Sterilization | L17: B | M17: B | N17: B | O17: ① | P17: N/A | Q17: 3020 | R17: 0.36 | S17: NA
... A29: ASAHI PTCA Guide Wire ASAHI Gaia Third Straight 300cm | B29: PTCA(AGH) | C29: 1536032 | D29: AHW14R311S KR | E29: KR | F29: 2 | G29: 2 | H29: 2 | I29: 2 | J29: Guide wire circular type | K29: 50°C, 300 minutes Sterilization | L29: B | M29: B | N29: B | O29: ① | P29: N/A | Q29: 3020 | R29: 0.36 | S29: NA
A30: ASAHI Peripheral Guide Wire ASAHI Gaia PV18 Straight 200cm | B30: IVR(AGH) | C30: 1731058 | D30: PHW18R102S KR | E30: KR | F30: 2 | G30: 2 | H30: 2 | I30: 2 | J30: Guide wire circular type | K30: 50°C, 300 minutes Sterilization | L30: B | M30: B | N30: B | O30: ① | P30: N/A | Q30: 2000 | R30: 0.45 | S30: NA | T30: VAL2003002-2、VAL2008008-21 | U30: PENG1907017 | V30: AMC-C171513
A31: ASAHI Peripheral Guide Wire ASAHI Gaia PV18 Pre-shape 200cm | B31: IVR(AGH) | C31: 1731059 | D31: PHW18R102P KR | E31: KR | F31: 2 | G31: 2 | H31: 2 | I31: 2 | J31: Guide wire circular type | K31: 50°C, 300 minutes Sterilization | L31: B | M31: B | N31: B | O31: ① | P31: N/A | Q31: 2000 | R31: 0.45 | S31: NA | T31: VAL2003002-2、VAL2008008-21 | U31: PENG1907017 | V31: AMC-C171513
A32: ASAHI Peripheral Guide Wire ASAHI Gaia PV18 Straight 235cm | B32: IVR(AGH) | C32: 1731060 | D32: PHW18R202S KR | E32: KR | F32: 2 | G32: 2 | H32: 2 | I32: 2 | J32: Guide wire circular type | K32: 50°C, 300 minutes Sterilization | L32: B | M32: B | N32: B | O32: ① | P32: N/A | Q32: 2350 | R32: 0.45 | S32: NA | T32: VAL2003002-2、VAL2008008-21 | U32: PENG1907017 | V32: AMC-C171513
A33: ASAHI Peripheral Guide Wire ASAHI Gaia PV18 Pre-shape 235cm | B33: IVR(AGH) | C33: 1731061 | D33: PHW18R202P KR | E33: KR | F33: 2 | G33: 2 | H33: 2 | I33: 2 | J33: Guide wire circular type | K33: 50°C, 300 minutes Sterilization | L33: B | M33: B | N33: B | O33: ① | P33: N/A | Q33: 2350 | R33: 0.45 | S33: NA | T33: VAL2003002-2、VAL2008008-21 | U33: PENG1907017 | V33: AMC-C171513
A34: ASAHI Peripheral Guide Wire ASAHI Gaia PV18 Straight 300cm | B34: IVR(AGH) | C34: 1731062 | D34: PHW18R302S KR | E34: KR | F34: 2 | G34: 2 | H34: 2 | I34: 2 | J34: Guide wire circular type | K34: 50°C, 300 minutes Sterilization | L34: B | M34: B | N34: B | O34: ① | P34: N/A | Q34: 3000 | R34: 0.45 | S34: NA | T34: VAL2003002-2、VAL2008008-21 | U34: PENG1907017 | V34: AMC-C171513
A35: ASAHI Peripheral Guide Wire ASAHI Gaia PV18 Pre-shape 300cm | B35: IVR(AGH) | C35: 1731063 | D35: PHW18R302P KR | E35: KR | F35: 2 | G35: 2 | H35: 2 | I35: 2 | J35: Guide wire circular type | K35: 50°C, 300 minutes Sterilization | L35: B | M35: B | N35: B | O35: ① | P35: N/A | Q35: 3000 | R35: 0.45 | S35: NA | T35: VAL2003002-2、VAL2008008-21 | U35: PENG1907017 | V35: AMC-C171513
A36: ASAHI PTCA Guide Wire ASAHI Gaia First Pre-shape 190cm | B36: PTCA(AGH) | C36: 1731101 | D36: AHW14R007P US | E36: US | F36: 2 | G36: 2 | H36: 2 | I36: 2 | J36: Guide wire circular type | K36: 50°C, 300 minutes Sterilization | L36: B | M36: B | N36: B | O36: ① | P36: N/A | Q36: 1906 | R36: 0.36 | S36: NA | T36: VAL2003002-2、VAL2008008-21,AMD-Q220882 | U36: AMD-Q240340, AMD-Q240341, AMD-Q240342, AMD-Q240343, AMD-Q240344, AMD-Q240345, TMVAL2401001-2 | V36: AMC-C240292
A37: ASAHI PTCA Guide Wire ASAHI Gaia First Pre-shape 300cm | B37: PTCA(AGH) | C37: 1731102 | D37: AHW14R307P US | E37: US | F37: 2 | G37: 2 | H37: 2 | I37: 2 | J37: Guide wire circular type | K37: 50°C, 300 minutes Sterilization | L37: B | M37: B | N37: B | O37: ① | P37: N/A | Q37: 3026 | R37: 0.36 | S37: NA | T37: VAL2003002-2、VAL2008008-21,AMD-Q220882 | U37: AMD-Q240340, AMD-Q240341, AMD-Q240342, AMD-Q240343, AMD-Q240344, AMD-Q240345, TMVAL2401001-2 | V37: AMC-C240292
A38: ASAHI PTCA Guide Wire ASAHI Gaia First Straight 190cm | B38: PTCA(AGH) | C38: 1731103 | D38: AHW14R007S US | E38: US | F38: 2 | G38: 2 | H38: 2 | I38: 2 | J38: Guide wire circular type | K38: 50°C, 300 minutes Sterilization | L38: B | M38: B | N38: B | O38: ① | P38: N/A | Q38: 1906 | R38: 0.36 | S38: NA | T38: VAL2003002-2、VAL2008008-21,AMD-Q220882 | U38: AMD-Q240340, AMD-Q240341, AMD-Q240342, AMD-Q240343, AMD-Q240344, AMD-Q240345, TMVAL2401001-2 | V38: AMC-C240292
A39: ASAHI PTCA Guide Wire ASAHI Gaia First Straight 300cm | B39: PTCA(AGH) | C39: 1731104 | D39: AHW14R307S US | E39: US | F39: 2 | G39: 2 | H39: 2 | I39: 2 | J39: Guide wire circular type | K39: 50°C, 300 minutes Sterilization | L39: B | M39: B | N39: B | O39: ① | P39: N/A | Q39: 3026 | R39: 0.36 | S39: NA | T39: VAL2003002-2、VAL2008008-21,AMD-Q220882 | U39: AMD-Q240340, AMD-Q240341, AMD-Q240342, AMD-Q240343, AMD-Q240344, AMD-Q240345, TMVAL2401001-2 | V39: AMC-C240292
A40: ASAHI PTCA Guide Wire ASAHI Gaia Second Pre-shape 190cm | B40: PTCA(AGH) | C40: 1731107 | D40: AHW14R008P US | E40: US | F40: 2 | G40: 2 | H40: 2 | I40: 2 | J40: Guide wire circular type | K40: 50°C, 300 minutes Sterilization | L40: B | M40: B | N40: B | O40: ① | P40: N/A | Q40: 1900 | R40: 0.36 | S40: NA | T40: VAL2003002-2、VAL2008008-21,AMD-Q220882 | U40: AMD-Q240340, AMD-Q240341, AMD-Q240342, AMD-Q240343, AMD-Q240344, AMD-Q240345, TMVAL2401001-2 | V40: AMC-C240292
A41: ASAHI PTCA Guide Wire ASAHI Gaia Second Pre-shape 300cm | B41: PTCA(AGH) | C41: 1731108 | D41: AHW14R308P US | E41: US | F41: 2 | G41: 2 | H41: 2 | I41: 2 | J41: Guide wire circular type | K41: 50°C, 300 minutes Sterilization | L41: B | M41: B | N41: B | O41: ① | P41: N/A | Q41: 3020 | R41: 0.36 | S41: NA | T41: VAL2003002-2、VAL2008008-21,AMD-Q220882 | U41: AMD-Q240340, AMD-Q240341, AMD-Q240342, AMD-Q240343, AMD-Q240344, AMD-Q240345, TMVAL2401001-2 | V41: AMC-C240292
... A58: ASAHI Peripheral Guide Wire Gaia PV18 straight 235cm | B58: IVR(AGH) | C58: 1831266 | D58: PH18R202SR JP | E58: J-sales | F58: 2 | G58: 2 | H58: 2 | I58: 2 | J58: Guide wire circular type | K58: 50°C, 300 minutes Sterilization | L58: B | M58: B | N58: B | O58: ① | P58: N/A | Q58: 2350 | R58: 0.45 | S58: NA | T58: VAL2003002-2、VAL2008008-21 | U58: AMD-DA41561007 | V58: AMC-C181594
A59: ASAHI Peripheral Guide Wire Gaia PV18 straight 300cm | C59: 1831267 | D59: PH18R302SR JP | E59: J-sales | F59: 2 | G59: 2 | H59: 2 | I59: 2 | J59: Guide wire circular type | K59: 50°C, 300 minutes Sterilization | L59: B | M59: B | N59: B | O59: ① | P59: N/A | Q59: 3000 | R59: 0.45 | S59: NA | T59: VAL2003002-2、VAL2008008-21 | U59: AMD-DA41561007 | V59: AMC-C181594 | X59: ×
A60: ASAHI Peripheral Guide Wire ASAHI Gaia PV18 Straight 200cm | B60: IVR(AGH) | C60: 1931085 | D60: PHW18R102S CN | E60: CHINA | F60: 2 | G60: 2 | H60: 2 | I60: 2 | J60: Guide wire circular type | K60: 50°C, 300 minutes Sterilization | L60: B | M60: B | N60: B | O60: ① | P60: N/A | Q60: 2000 | R60: 0.45 | S60: NA | T60: AMD-Q190816 | U60: AMD-DG05019008/AMD-DA41561007 | V60: AMC-C191553
A61: ASAHI Peripheral Guide Wire ASAHI Gaia PV18 Pre-shape 200cm | B61: IVR(AGH) | C61: 1931086 | D61: PHW18R102P CN | E61: CHINA | F61: 2 | G61: 2 | H61: 2 | I61: 2 | J61: Guide wire circular type | K61: 50°C, 300 minutes Sterilization | L61: B | M61: B | N61: B | O61: ① | P61: N/A | Q61: 2000 | R61: 0.45 | S61: NA | T61: AMD-Q190816 | U61: AMD-DG05019008/AMD-DA41561008 | V61: AMC-C191553
A62: ASAHI Peripheral Guide Wire ASAHI Gaia PV18 Straight 235cm | B62: IVR(AGH) | C62: 1931087 | D62: PHW18R202S CN | E62: CHINA | F62: 2 | G62: 2 | H62: 2 | I62: 2 | J62: Guide wire circular type | K62: 50°C, 300 minutes Sterilization | L62: B | M62: B | N62: B | O62: ① | P62: N/A | Q62: 2350 | R62: 0.45 | S62: NA | T62: AMD-Q190816 | U62: AMD-DG05019008/AMD-DA41561009 | V62: AMC-C191553
A63: ASAHI Peripheral Guide Wire ASAHI Gaia PV18 Pre-shape 235cm | B63: IVR(AGH) | C63: 1931088 | D63: PHW18R202P CN | E63: CHINA | F63: 2 | G63: 2 | H63: 2 | I63: 2 | J63: Guide wire circular type | K63: 50°C, 300 minutes Sterilization | L63: B | M63: B | N63: B | O63: ① | P63: N/A | Q63: 2350 | R63: 0.45 | S63: NA | T63: AMD-Q190816 | U63: AMD-DG05019008/AMD-DA41561010 | V63: AMC-C191553
A64: ASAHI Peripheral Guide Wire ASAHI Gaia PV18 Straight 300cm | B64: IVR(AGH) | C64: 1931089 | D64: PHW18R302S CN | E64: CHINA | F64: 2 | G64: 2 | H64: 2 | I64: 2 | J64: Guide wire circular type | K64: 50°C, 300 minutes Sterilization | L64: B | M64: B | N64: B | O64: ① | P64: N/A | Q64: 3000 | R64: 0.45 | S64: NA | T64: AMD-Q190816 | U64: AMD-DG05019008/AMD-DA41561011 | V64: AMC-C191553
A65: ASAHI Peripheral Guide Wire ASAHI Gaia PV18 Pre-shape 300cm | B65: IVR(AGH) | C65: 1931090 | D65: PHW18R302P CN | E65: CHINA | F65: 2 | G65: 2 | H65: 2 | I65: 2 | J65: Guide wire circular type | K65: 50°C, 300 minutes Sterilization | L65: B | M65: B | N65: B | O65: ① | P65: N/A | Q65: 3000 | R65: 0.45 | S65: NA | T65: AMD-Q190816 | U65: AMD-DG05019008/AMD-DA41561012 | V65: AMC-C191553
A66: ASAHI PTCA Guide Wire ASAHI Gaia First Pre-shape 190 cm | B66: PTCA(AGH) | C66: 2031173 | D66: AH14R007PR CN | E66: CHINA | F66: 2 | G66: 2 | H66: 2 | I66: 2 | J66: Guide wire circular type | K66: 50°C, 300 minutes Sterilization | L66: B | M66: B | N66: B | O66: ① | P66: A | Q66: 1906 | R66: 0.36 | S66: NA | T66: AIH:AMD-Q200865, VAL2103011-21 AIT:AMO-Q201008, VA0199-1 | V66: AMC-C240088
A67: ASAHI PTCA Guide Wire ASAHI Gaia First Straight 190 cm | B67: PTCA(AGH) | C67: 2031174 | D67: AH14R007SR CN | E67: CHINA | F67: 2 | G67: 2 | H67: 2 | I67: 2 | J67: Guide wire circular type | K67: 50°C, 300 minutes Sterilization | L67: B | M67: B | N67: B | O67: ① | P67: A | Q67: 1906 | R67: 0.36 | S67: NA | T67: AIH:AMD-Q200865, VAL2103011-21 AIT:AMO-Q201008, VA0199-1 | V67: AMC-C240088
A68: ASAHI PTCA Guide Wire ASAHI Gaia First Pre-shape 300 cm | B68: PTCA(AGH) | C68: 2031175 | D68: AH14R307PR CN | E68: CHINA | F68: 2 | G68: 2 | H68: 2 | I68: 2 | J68: Guide wire circular type | K68: 50°C, 300 minutes Sterilization | L68: B | M68: B | N68: B | O68: ① | P68: A | Q68: 3026 | R68: 0.36 | S68: NA | T68: AIH:AMD-Q200865, VAL2103011-21 AIT:AMO-Q201008, VA0199-1 | V68: AMC-C240088
A69: ASAHI PTCA Guide Wire ASAHI Gaia First Straight 300 cm | B69: PTCA(AGH) | C69: 2031176 | D69: AH14R307SR CN | E69: CHINA | F69: 2 | G69: 2 | H69: 2 | I69: 2 | J69: Guide wire circular type | K69: 50°C, 300 minutes Sterilization | L69: B | M69: B | N69: B | O69: ① | P69: A | Q69: 3026 | R69: 0.36 | S69: NA | T69: AIH:AMD-Q200865, VAL2103011-21 AIT:AMO-Q201008, VA0199-1 | V69: AMC-C240088
...

Sheet H003
A1: =[3]表紙!A1 -> AMI-Q411-H003 Ver.1 | B1: 滅菌対象品一覧AIHM(Fielder series) | R1: 品質保証G
A4: 製品名 | B4: Product Information | C4: 図番 | D4: カタログコード | E4: 仕向け先 | F4: Chamber | J4: 滅菌ファミリー | K4: 滅菌条件 | L4: 無菌試験 ファミリー | M4: バイオバーデン ファミリー | N4: ｴﾝﾄﾞﾄｷｼﾝ試験 ファミリー | O4: エアレーション ファミリー | P4: 微粒汚染 ファミリー | Q4: Length [mm] | R4: O.D. [mm] (Shaft or core) | S4: I.D. [mm] (Shaft) | T4: 滅菌バリデーション | U4: 製品評価レポート | V4: 薬事承認書 | W4: 変更提案、品質関連連絡書
F5: A | G5: B | H5: C | I5: D
A6: ASAHI PTCA Guide Wire Fielder FC 300cm J | B6: PTCA(AGP) | C6: 2331154 | D6: AGP140301J CE4 | E6: CE | F6: 2 | G6: 2 | H6: 2 | I6: 2 | J6: Guide wire circular type | K6: 50°C, 300 minutes Sterilization | L6: C | M6: C | N6: C | O6: ① | P6: N/A | Q6: 3026 | R6: 0.35 | S6: NA
A7: ASAHI PTCA Guide Wire Fielder 180cm | B7: PTCA(AGP) | C7: 2331146 | D7: AGP140000 CE4 | E7: CE | F7: 2 | G7: 2 | H7: 2 | I7: 2 | J7: Guide wire circular type | K7: 50°C, 300 minutes Sterilization | L7: C | M7: C | N7: C | O7: ① | P7: N/A | Q7: 1812 | R7: 0.35 | S7: NA
A8: ASAHI PTCA Guide Wire Fielder FC 300cm | B8: PTCA(AGP) | C8: 2331153 | D8: AGP140301 CE4 | E8: CE | F8: 2 | G8: 2 | H8: 2 | I8: 2 | J8: Guide wire circular type | K8: 50°C, 300 minutes Sterilization | L8: C | M8: C | N8: C | O8: ① | P8: N/A | Q8: 3026 | R8: 0.35 | S8: NA
A9: ASAHI PTCA Guide Wire Fielder FC 180cm J | B9: PTCA(AGP) | C9: 2331152 | D9: AGP140001J CE4 | E9: CE | F9: 2 | G9: 2 | H9: 2 | I9: 2 | J9: Guide wire circular type | K9: 50°C, 300 minutes Sterilization | L9: C | M9: C | N9: C | O9: ① | P9: N/A | Q9: 1806 | R9: 0.35 | S9: NA
A10: ASAHI PTCA Guide Wire Fielder FC 180cm | B10: PTCA(AGP) | C10: 2331151 | D10: AGP140001 CE4 | E10: CE | F10: 2 | G10: 2 | H10: 2 | I10: 2 | J10: Guide wire circular type | K10: 50°C, 300 minutes Sterilization | L10: C | M10: C | N10: C | O10: ① | P10: N/A | Q10: 1806 | R10: 0.35 | S10: NA
A11: ASAHI PTCA Guide Wire Fielder XT 300cm | B11: PTCA(AGP) | C11: 2331150 | D11: AGP140302 CE4 | E11: CE | F11: 2 | G11: 2 | H11: 2 | I11: 2 | J11: Guide wire circular type | K11: 50°C, 300 minutes Sterilization | L11: C | M11: C | N11: C | O11: ① | P11: N/A | Q11: 3026 | R11: 0.35 | S11: NA
A12: ASAHI PTCA Guide Wire Fielder XT 190cm | B12: PTCA(AGP) | C12: 2331149 | D12: AGP140002 CE4 | E12: CE | F12: 2 | G12: 2 | H12: 2 | I12: 2 | J12: Guide wire circular type | K12: 50°C, 300 minutes Sterilization | L12: C | M12: C | N12: C | O12: ① | P12: N/A | Q12: 1906 | R12: 0.35 | S12: NA
A13: ASAHI PTCA Guide Wire Fielder 180cm J | B13: PTCA(AGP) | C13: 2331148 | D13: AGP140000J CE4 | E13: CE | F13: 2 | G13: 2 | H13: 2 | I13: 2 | J13: Guide wire circular type | K13: 50°C, 300 minutes Sterilization | L13: C | M13: C | N13: C | O13: ① | P13: N/A | Q13: 1812 | R13: 0.35 | S13: NA
A14: ASAHI PTCA Guide Wire Fielder 300cm | B14: PTCA(AGP) | C14: 2331147 | D14: AGP140300 CE4 | E14: CE | F14: 2 | G14: 2 | H14: 2 | I14: 2 | J14: Guide wire circular type | K14: 50°C, 300 minutes Sterilization | L14: C | M14: C | N14: C | O14: ① | P14: N/A | Q14: 3032 | R14: 0.35 | S14: NA
A15: ASAHI PTCA Guide Wire Fielder XT-R 300cm | B15: PTCA(AGP) | C15: 2331042 | D15: APW14R305S CE5 | E15: CE | F15: 2 | G15: 2 | H15: 2 | I15: 2 | J15: Guide wire circular type | K15: 50°C, 300 minutes Sterilization | L15: C | M15: C | N15: C | O15: ① | P15: N/A | Q15: 3027 | R15: 0.36 | S15: NA
A16: ASAHI PTCA Guide Wire Fielder XT-R 190cm | B16: PTCA(AGP) | C16: 2331041 | D16: APW14R005S CE5 | E16: CE | F16: 2 | G16: 2 | H16: 2 | I16: 2 | J16: Guide wire circular type | K16: 50°C, 300 minutes Sterilization | L16: C | M16: C | N16: C | O16: ① | P16: N/A | Q16: 1907 | R16: 0.36 | S16: NA
A17: ASAHI PTCA Guide Wire Fielder XT-R 300cm | B17: PTCA(AGP) | C17: 2131724 | D17: APW14R305S NOCE | E17: NO CE | F17: 2 | G17: 2 | H17: 2 | I17: 2 | J17: Guide wire circular type | K17: 50°C, 300 minutes Sterilization | L17: C | M17: C | N17: C | O17: ① | P17: N/A | Q17: 3027 | R17: 0.36 | S17: NA | T17: AMD-Q220819 | U17: AMD-DA41771056 | V17: AMC-C220059
A18: ASAHI PTCA Guide Wire Fielder XT-R 190cm | B18: PTCA(AGP) | C18: 2131723 | D18: APW14R005S NOCE | E18: NO CE | F18: 2 | G18: 2 | H18: 2 | I18: 2 | J18: Guide wire circular type | K18: 50°C, 300 minutes Sterilization | L18: C | M18: C | N18: C | O18: ① | P18: N/A | Q18: 1907 | R18: 0.36 | S18: NA | T18: AMD-Q220819 | U18: AMD-DA41771056 | V18: AMC-C220059
A19: ASAHI PTCA Guide Wire Fielder XT-A 300cm | B19: PTCA(AGP) | C19: 2131722 | D19: APW14R309S NOCE | E19: NO CE | F19: 2 | G19: 2 | H19: 2 | I19: 2 | J19: Guide wire circular type | K19: 50°C, 300 minutes Sterilization | L19: C | M19: C | N19: C | O19: ① | P19: N/A | Q19: 3027 | R19: 0.36 | S19: NA | T19: AMD-Q220819 | U19: AMD-DA41771056 | V19: AMC-C220059
A20: ASAHI PTCA Guide Wire Fielder XT-A 190cm | B20: PTCA(AGP) | C20: 2131721 | D20: APW14R009S NOCE | E20: NO CE | F20: 2 | G20: 2 | H20: 2 | I20: 2 | J20: Guide wire circular type | K20: 50°C, 300 minutes Sterilization | L20: C | M20: C | N20: C | O20: ① | P20: N/A | Q20: 1907 | R20: 0.36 | S20: NA | T20: AMD-Q220819 | U20: AMD-DA41771056 | V20: AMC-C220059
A21: ASAHI PTCA Guide Wire Fielder FC 300cm J | B21: PTCA(AGP) | C21: 2131661 | D21: AGP140301J NOCE | E21: NO CE | F21: 2 | G21: 2 | H21: 2 | I21: 2 | J21: Guide wire circular type | K21: 50°C, 300 minutes Sterilization | L21: C | M21: C | N21: C | O21: ① | P21: N/A | Q21: 3026 | R21: 0.35 | S21: NA | T21: AMD-Q220819 | U21: AMD-DA41771056 | V21: AMC-C220059
A22: ASAHI PTCA Guide Wire Fielder FC 300cm | B22: PTCA(AGP) | C22: 2131660 | D22: AGP140301 NOCE | E22: NO CE (インド) | F22: 2 | G22: 2 | H22: 2 | I22: 2 | J22: Guide wire circular type | K22: 50°C, 300 minutes Sterilization | L22: C | M22: C | N22: C | O22: ① | P22: N/A | Q22: 3026 | R22: 0.35 | S22: NA | T22: MAMD-Q240813 | U22: AMD-Q201411 | V22: AMC-C240322
A23: ASAHI PTCA Guide Wire Fielder FC 300cm | B23: PTCA(AGP) | C23: 2131660 | D23: AGP140301 NOCE | E23: NO CE | F23: 2 | G23: 2 | H23: 2 | I23: 2 | J23: Guide wire circular type | K23: 50°C, 300 minutes Sterilization | L23: C | M23: C | N23: C | O23: ① | P23: N/A | Q23: 3026 | R23: 0.35 | S23: NA | T23: MAMD-Q240813 | U23: AMD-Q201411 | V23: AMC-C240322
A24: ASAHI PTCA Guide Wire Fielder FC 180cm J | B24: PTCA(AGP) | C24: 2131659 | D24: AGP140001J NOCE | E24: NO CE (インド) | F24: 2 | G24: 2 | H24: 2 | I24: 2 | J24: Guide wire circular type | K24: 50°C, 300 minutes Sterilization | L24: C | M24: C | N24: C | O24: ① | P24: N/A | Q24: 1806 | R24: 0.35 | S24: NA | T24: MAMD-Q240813 | U24: AMD-Q201411 | V24: AMC-C240322
A25: ASAHI PTCA Guide Wire Fielder FC 180cm J | B25: PTCA(AGP) | C25: 2131659 | D25: AGP140001J NOCE | E25: NO CE | F25: 2 | G25: 2 | H25: 2 | I25: 2 | J25: Guide wire circular type | K25: 50°C, 300 minutes Sterilization | L25: C | M25: C | N25: C | O25: ① | P25: N/A | Q25: 1806 | R25: 0.35 | S25: NA | T25: MAMD-Q240813 | U25: AMD-Q201411 | V25: AMC-C240322
A26: ASAHI PTCA Guide Wire Fielder FC 180cm | B26: PTCA(AGP) | C26: 2131658 | D26: AGP140001 NOCE | E26: NO CE (インド) | F26: 2 | G26: 2 | H26: 2 | I26: 2 | J26: Guide wire circular type | K26: 50°C, 300 minutes Sterilization | L26: C | M26: C | N26: C | O26: ① | P26: N/A | Q26: 1806 | R26: 0.35 | S26: NA | T26: MAMD-Q240813 | U26: AMD-Q201411 | V26: AMC-C240322
A27: ASAHI PTCA Guide Wire Fielder FC 180cm | B27: PTCA(AGP) | C27: 2131658 | D27: AGP140001 NOCE | E27: NO CE | F27: 2 | G27: 2 | H27: 2 | I27: 2 | J27: Guide wire circular type | K27: 50°C, 300 minutes Sterilization | L27: C | M27: C | N27: C | O27: ① | P27: N/A | Q27: 1806 | R27: 0.35 | S27: NA | T27: MAMD-Q240813 | U27: AMD-Q201411 | V27: AMC-C240322
A28: ASAHI PTCA Guide Wire Fielder XT 300cm | B28: PTCA(AGP) | C28: 2131657 | D28: AGP140302 NOCE | E28: NO CE | F28: 2 | G28: 2 | H28: 2 | I28: 2 | J28: Guide wire circular type | K28: 50°C, 300 minutes Sterilization | L28: C | M28: C | N28: C | O28: ① | P28: N/A | Q28: 3026 | R28: 0.35 | S28: NA | T28: AMD-Q220819 | U28: AMD-DA41771056 | V28: AMC-C220059
... A34: ASAHI PTCA Guide Wire Fielder 180cm | B34: PTCA(AGP) | C34: 2131653 | D34: AGP140000 NOCE | E34: NO CE | F34: 2 | G34: 2 | H34: 2 | I34: 2 | J34: Guide wire circular type | K34: 50°C, 300 minutes Sterilization | L34: C | M34: C | N34: C | O34: ① | P34: N/A | Q34: 1812 | R34: 0.35 | S34: NA | T34: MAMD-Q240813 | U34: AMD-Q201411 | V34: AMC-C240322
A35: PCI Guide Wire Fielder FC 300cm J-shape | B35: PTCA(AGP) | C35: 2131083 | D35: AGP140301J MDR | E35: CE | F35: 2 | G35: 2 | H35: 2 | I35: 2 | J35: Guide wire circular type | K35: 50°C, 300 minutes Sterilization | L35: C | M35: C | N35: C | O35: ① | P35: N/A | Q35: 3026 | R35: 0.35 | S35: NA | T35: AMD-Q210803、AMD-Q210804
A36: PCI Guide Wire Fielder FC 180cm J-shape | B36: PTCA(AGP) | C36: 2131082 | D36: AGP140001J MDR | E36: CE | F36: 2 | G36: 2 | H36: 2 | I36: 2 | J36: Guide wire circular type | K36: 50°C, 300 minutes Sterilization | L36: C | M36: C | N36: C | O36: ① | P36: N/A | Q36: 1806 | R36: 0.35 | S36: NA | T36: AMD-Q210803、AMD-Q210804
A37: PCI Guide Wire Fielder 300cm J-shape | B37: PTCA(AGP) | C37: 2131081 | D37: AGP140300J MDR | E37: CE | F37: 2 | G37: 2 | H37: 2 | I37: 2 | J37: Guide wire circular type | K37: 50°C, 300 minutes Sterilization | L37: C | M37: C | N37: C | O37: ① | P37: N/A | Q37: 3032 | R37: 0.35 | S37: NA | T37: AMD-Q210803、AMD-Q210804
A38: PCI Guide Wire Fielder 180cm J-shape | B38: PTCA(AGP) | C38: 2131080 | D38: AGP140000J MDR | E38: CE | F38: 2 | G38: 2 | H38: 2 | I38: 2 | J38: Guide wire circular type | K38: 50°C, 300 minutes Sterilization | L38: C | M38: C | N38: C | O38: ① | P38: N/A | Q38: 1812 | R38: 0.35 | S38: NA | T38: AMD-Q210803、AMD-Q210804
A39: PCI Guide Wire Fielder XT 300cm Straight | B39: PTCA(AGP) | C39: 2131029 | D39: AGP140302 MDR | E39: CE | F39: 2 | G39: 2 | H39: 2 | I39: 2 | J39: Guide wire circular type | K39: 50°C, 300 minutes Sterilization | L39: C | M39: C | N39: C | O39: ① | P39: N/A | Q39: 3026 | R39: 0.35 | S39: NA | T39: AMD-Q210803、AMD-Q210804
A40: PCI Guide Wire Fielder XT 190cm Straight | B40: PTCA(AGP) | C40: 2131027 | D40: AGP140002 MDR | E40: CE | F40: 2 | G40: 2 | H40: 2 | I40: 2 | J40: Guide wire circular type | K40: 50°C, 300 minutes Sterilization | L40: C | M40: C | N40: C | O40: ① | P40: N/A | Q40: 1906 | R40: 0.35 | S40: NA | T40: AMD-Q210803、AMD-Q210804
A41: PCI Guide Wire Fielder FC 300cm Straight | B41: PTCA(AGP) | C41: 2131026 | D41: AGP140301 MDR | E41: CE | F41: 2 | G41: 2 | H41: 2 | I41: 2 | J41: Guide wire circular type | K41: 50°C, 300 minutes Sterilization | L41: C | M41: C | N41: C | O41: ① | P41: N/A | Q41: 3026 | R41: 0.35 | S41: NA | T41: AMD-Q210803、AMD-Q210804
A42: PCI Guide Wire Fielder FC 180cm Straight | B42: PTCA(AGP) | C42: 2131024 | D42: AGP140001 MDR | E42: CE | F42: 2 | G42: 2 | H42: 2 | I42: 2 | J42: Guide wire circular type | K42: 50°C, 300 minutes Sterilization | L42: C | M42: C | N42: C | O42: ① | P42: N/A | Q42: 1806 | R42: 0.35 | S42: NA | T42: AMD-Q210803、AMD-Q210804
A43: PCI Guide Wire Fielder 300cm Straight | B43: PTCA(AGP) | C43: 2131023 | D43: AGP140300 MDR | E43: CE | F43: 2 | G43: 2 | H43: 2 | I43: 2 | J43: Guide wire circular type | K43: 50°C, 300 minutes Sterilization | L43: C | M43: C | N43: C | O43: ① | P43: N/A | Q43: 3032 | R43: 0.35 | S43: NA | T43: AMD-Q210803、AMD-Q210804
