Workbook
Name eratet: '[1]PLAN PTCA'!#REF!
Name eratet: #REF!
Name eratet: '[1]PLAN PTCA'!#REF!
Name eratet: '[1]PLAN PTCA'!#REF!

Sheet PLAN
B1: PLAN STER - CAG | G1: =SUBTOTAL(9,G3:G97002) -> 65738 | K1: =SUBTOTAL(9,K3:K97002) -> 66879 | AD1: =SUBTOTAL(9,AD3:AD97002) -> 24776
A2: PO No. | B2: TT | C2: PldOrd | D2: Material No | E2: Item code | F2: Item name | G2: Q'ty | H2: Complete Date | I2: Internal Lot | J2: External Lot Ster | K2: Q'ty Input | L2: Material No Type C | M2: Item Code Type C | N2: QA test | O2: KEEP | P2: Destination | Q2: Bioburden | R2: Label | S2: Test Endotoxin ( pcs) | T2: Test Particle ( pcs) | U2: Seal | V2: Ster | W2: MẺ | X2: BOXING | Y2: Label | Z2: Seal | AA2: Boxing | AB2: ETD | AC2: Family | AD2: WH | AE2: PROCESS | AF2: ngày lưu kho | AG2: Cột ƯỚc | AH2: Tổng test | AI2: 0 | AJ2: MẺ | AK2: 1 | AL2: Địa Chỉ Label QR code | AM2: 1 | AN2: ＡＩＨ B | AO2: ＡＩＨ B | AP2: ＡＩＨ C | AQ2: ＡＩＨ D
A3: HF | B3: Aug15-01 | C3: 1001897397 | D3: 12129248 | E3: PR2145021-0-A | F3: 2009051 Masters HF CN | G3: 3300 | H3: 46249 | I3: 0103516476 | J3: 260625K01A | K3: 3306 | L3: 12003986 | M3: PR19SR002-0-D | N3: 0 | O3: 0 | P3: CHINA | Q3: 3 | R3: 46205 | S3: 3 | T3: 0 | U3: 46206 | V3: 46206 | W3: M8 | X3: 46247 | Y3: =VLOOKUP(F3,[2]New!$B:$G,3,0)*K3/60 -> 1212.2 | Z3: =VLOOKUP(F3,[2]New!$B:$G,4,0)*K3/60 -> 6496.29 | AA3: =VLOOKUP(F3,[2]New!$B:$G,6,0)*K3/60 -> 6336.5 | AB3: 46269 | AC3: =IFERROR(VLOOKUP(F3,[3]Sheet1!$E:$H,4,0),) -> K | AD3: 3300 | AE3: FINISH | AF3: 36 | AI3: 6 | AJ3: M8-1 | AN3: 1 | AO3: 1 | AP3: × | AQ3: ×
A4: Đăng | B4: QC-5 | C4: 2000126703 | D4: 11125142 | E4: 1941011-D-A | F4: Masters PARKWAY SOFT 150cm Straight | G4: 3 | H4: 46234 | I4: 0103539406 | J4: 260707Y17A | K4: 3 | L4: 12120564 | M4: 1942042-A-C | N4: 0 | O4: 0 | P4: TEST | Q4: 0 | R4: 46221 | S4: 0 | T4: 0 | U4: 46230 | V4: N/A | W4: TEST | Y4: 0 | Z4: 0 | AA4: 0 | AB4: TEST | AE4: TEST
A5: Đăng | B5: QC-6 | C5: 2000126704 | D5: 11125142 | E5: 1941011-D-A | F5: Masters PARKWAY SOFT 150cm Straight | G5: 9 | H5: 46234 | I5: 0103539408 | J5: 260707Y17D | K5: 9 | L5: 12120564 | M5: 1942042-A-C | N5: 0 | O5: 0 | P5: TEST | Q5: 0 | R5: 46221 | S5: 0 | T5: 0 | U5: 46230 | V5: 46230 | W5: TEST | Y5: 0 | Z5: 0 | AA5: 0 | AB5: TEST | AE5: TEST
A6: Đăng | B6: QC-7 | C6: 2000126705 | D6: 11112488 | E6: PSC35170S-E-A | F6: CROSSWALK 035 170cm Straight | G6: 3 | H6: 46234 | I6: 0103539409 | J6: 260707Y18A | K6: 3 | L6: 12115911 | M6: PSC35170S-E-C | N6: 0 | O6: 0 | P6: TEST | Q6: 0 | R6: 46221 | S6: 0 | T6: 0 | U6: 46230 | V6: N/A | W6: TEST | Y6: 0 | Z6: 0 | AA6: 0 | AB6: TEST | AE6: TEST
A7: Đăng | B7: QC-8 | C7: 2000126706 | D7: 11112488 | E7: PSC35170S-E-A | F7: CROSSWALK 035 170cm Straight | G7: 9 | H7: 46234 | I7: 0103539410 | J7: 260707Y18D | K7: 9 | L7: 12115911 | M7: PSC35170S-E-C | N7: 0 | O7: 0 | P7: TEST | Q7: 0 | R7: 46221 | S7: 0 | T7: 0 | U7: 46230 | V7: 46230 | W7: TEST | Y7: 0 | Z7: 0 | AA7: 0 | AB7: TEST | AE7: TEST
A8: Đăng | B8: QC-9 | C8: 2000126709 | D8: 12012480 | E8: PR1944001-0-A | F8: Accessories for Masters Parkway HF | G8: 3 | H8: 46234 | I8: 0103539413 | J8: 260707Y20A | K8: 3 | L8: 12003986 | M8: PR19SR002-0-D | N8: 0 | O8: 0 | P8: TEST | Q8: 0 | R8: 46221 | S8: 0 | T8: 0 | U8: 46230 | V8: N/A | W8: TEST | Y8: 0 | Z8: 0 | AA8: 0 | AB8: TEST | AE8: TEST
A9: Đăng | B9: QC-10 | C9: 2000126710 | D9: 12012480 | E9: PR1944001-0-A | F9: Accessories for Masters Parkway HF | G9: 9 | H9: 46234 | I9: 0103539414 | J9: 260707Y20D | K9: 9 | L9: 12003986 | M9: PR19SR002-0-D | N9: 0 | O9: 0 | P9: TEST | Q9: 0 | R9: 46221 | S9: 0 | T9: 0 | U9: 46230 | V9: 46230 | W9: TEST | Y9: 0 | Z9: 0 | AA9: 0 | AB9: TEST | AE9: TEST
A10: Đăng | B10: QC-11 | C10: 2000127274 | D10: 12143523 | E10: PR2545028-0-A | F10: 2009009 Veloute | G10: 3 | H10: 46234 | I10: 0103553325 | J10: 260707Y21A | K10: 3 | L10: 12001113 | M10: PR19SR003-0-D | N10: 0 | O10: 0 | P10: TEST | Q10: 0 | R10: 46221 | S10: 0 | T10: 0 | U10: 46230 | V10: N/A | W10: TEST | Y10: 0 | Z10: 0 | AA10: 0 | AB10: TEST | AE10: TEST
A11: Đăng | B11: QC-12 | C11: 2000127275 | D11: 12143523 | E11: PR2545028-0-A | F11: 2009009 Veloute | G11: 9 | H11: 46234 | I11: 0103553326 | J11: 260707Y21D | K11: 9 | L11: 12001113 | M11: PR19SR003-0-D | N11: 0 | O11: 0 | P11: TEST | Q11: 0 | R11: 46221 | S11: 0 | T11: 0 | U11: 46230 | V11: 46230 | W11: TEST | Y11: 0 | Z11: 0 | AA11: 0 | AB11: TEST | AE11: TEST
A12: Đăng | B12: QC-13 | C12: 2000126731 | D12: 11134563 | E12: 2041304-C-A | F12: ASAHI Masters PARKWAY HF 150cm Straight | G12: 3 | H12: 46234 | I12: 0103539435 | J12: 260707Y30A | K12: 3 | L12: 12131598 | M12: 2042141-B-C | N12: 0 | O12: 0 | P12: TEST | Q12: 0 | R12: 46221 | S12: 0 | T12: 0 | U12: 46230 | V12: N/A | W12: TEST | Y12: 0 | Z12: 0 | AA12: 0 | AB12: TEST | AE12: TEST
A13: Đăng | B13: QC-14 | C13: 2000126732 | D13: 11134563 | E13: 2041304-C-A | F13: ASAHI Masters PARKWAY HF 150cm Straight | G13: 9 | H13: 46234 | I13: 0103539437 | J13: 260707Y30B | K13: 9 | L13: 12131598 | M13: 2042141-B-C | N13: 0 | O13: 0 | P13: TEST | Q13: 0 | R13: 46221 | S13: 0 | T13: 0 | U13: 46230 | V13: 46230 | W13: TEST | Y13: 0 | Z13: 0 | AA13: 0 | AB13: TEST | AE13: TEST
A14: Đăng | B14: QC-15 | C14: 2000126733 | D14: 11134563 | E14: 2041304-C-A | F14: ASAHI Masters PARKWAY HF 150cm Straight | G14: 9 | H14: 46234 | I14: 0103539438 | J14: 260707Y30D | K14: 9 | L14: 12131598 | M14: 2042141-B-C | N14: 0 | O14: 0 | P14: TEST | Q14: 0 | R14: 46221 | S14: 0 | T14: 0 | U14: 46230 | V14: 46230 | W14: TEST | Y14: 0 | Z14: 0 | AA14: 0 | AB14: TEST | AE14: TEST
A15: Đăng | B15: QC-16 | C15: 2000126734 | D15: 11134247 | E15: 2141050-D-A | F15: ASAHI Caravel 150cm | G15: 3 | H15: 46234 | I15: 0103539439 | J15: 260707Y31A | K15: 3 | L15: 12129253 | M15: 1842015-B-C | N15: 0 | O15: 0 | P15: TEST | Q15: 0 | R15: 46221 | S15: 0 | T15: 0 | U15: 46230 | V15: N/A | W15: TEST | Y15: 0 | Z15: 0 | AA15: 0 | AB15: TEST | AE15: TEST
A16: Đăng | B16: QC-17 | C16: 2000126735 | D16: 11134247 | E16: 2141050-D-A | F16: ASAHI Caravel 150cm | G16: 9 | H16: 46234 | I16: 0103539440 | J16: 260707Y31B | K16: 9 | L16: 12129253 | M16: 1842015-B-C | N16: 0 | O16: 0 | P16: TEST | Q16: 0 | R16: 46221 | S16: 0 | T16: 0 | U16: 46230 | V16: 46230 | W16: TEST | Y16: 0 | Z16: 0 | AA16: 0 | AB16: TEST | AE16: TEST
A17: Đăng | B17: QC-18 | C17: 2000126736 | D17: 11134247 | E17: 2141050-D-A | F17: ASAHI Caravel 150cm | G17: 9 | H17: 46234 | I17: 0103539441 | J17: 260707Y31D | K17: 9 | L17: 12129253 | M17: 1842015-B-C | N17: 0 | O17: 0 | P17: TEST | Q17: 0 | R17: 46221 | S17: 0 | T17: 0 | U17: 46230 | V17: 46230 | W17: TEST | Y17: 0 | Z17: 0 | AA17: 0 | AB17: TEST | AE17: TEST
A18: Đăng | B18: QC-19 | C18: 2000126737 | D18: 11134249 | E18: 2041190-D-A | F18: ASAHI Corsair Pro 150㎝ | G18: 3 | H18: 46234 | I18: 0103539442 | J18: 260707Y32A | K18: 3 | L18: 12139932 | M18: 2342020-A-C-CN | N18: 0 | O18: 0 | P18: TEST | Q18: 0 | R18: 46221 | S18: 0 | T18: 0 | U18: 46230 | V18: N/A | W18: TEST | Y18: 0 | Z18: 0 | AA18: 0 | AB18: TEST | AE18: TEST
A19: Đăng | B19: QC-20 | C19: 2000126738 | D19: 11134249 | E19: 2041190-D-A | F19: ASAHI Corsair Pro 150㎝ | G19: 9 | H19: 46234 | I19: 0103539443 | J19: 260707Y32D | K19: 9 | L19: 12139932 | M19: 2342020-A-C-CN | N19: 0 | O19: 0 | P19: TEST | Q19: 0 | R19: 46221 | S19: 0 | T19: 0 | U19: 46230 | V19: 46230 | W19: TEST | Y19: 0 | Z19: 0 | AA19: 0 | AB19: TEST | AE19: TEST
A20: Đăng | B20: QC-21 | C20: 2000126739 | D20: 11119663 | E20: 1911329-D-A | F20: HJ80AL102P10002 JP | G20: 3 | H20: 46234 | I20: 0103539445 | J20: 260707Y33A | K20: 3 | L20: 12116298 | M20: 2112331-0-C | N20: 0 | O20: 0 | P20: TEST | Q20: 0 | R20: 46221 | S20: 0 | T20: 0 | U20: 46230 | V20: N/A | W20: TEST | Y20: 0 | Z20: 0 | AA20: 0 | AB20: TEST | AE20: TEST
A21: Đăng | B21: QC-22 | C21: 2000126740 | D21: 11119663 | E21: 1911329-D-A | F21: HJ80AL102P10002 JP | G21: 6 | H21: 46234 | I21: 0103539446 | J21: 260707Y33B | K21: 6 | L21: 12116298 | M21: 2112331-0-C | N21: 0 | O21: 0 | P21: TEST | Q21: 0 | R21: 46221 | S21: 0 | T21: 0 | U21: 46230 | V21: 46230 | W21: TEST | Y21: 0 | Z21: 0 | AA21: 0 | AB21: TEST | AE21: TEST
A22: Đăng | B22: QC-23 | C22: 2000127121 | D22: 11134203 | E22: 2211671-D-A | F22: HW80AL102P10000 CN | G22: 3 | H22: 46234 | I22: 0103548965 | J22: 260713Y01A | K22: 3 | L22: 12130255 | M22: 2112244-0-C-CN | N22: 0 | O22: 0 | P22: TEST | Q22: 0 | R22: 46221 | S22: 0 | T22: 0 | U22: 46230 | V22: N/A | W22: TEST | Y22: 0 | Z22: 0 | AA22: 0 | AB22: TEST | AE22: TEST
A23: Đăng | B23: QC-26 | C23: 2000127122 | D23: 11134203 | E23: 2211671-D-A | F23: HW80AL102P10000 CN | G23: 9 | H23: 46234 | I23: 0103548970 | J23: 260713Y01D | K23: 9 | L23: 12130255 | M23: 2112244-0-C-CN | N23: 0 | O23: 0 | P23: TEST | Q23: 0 | R23: 46221 | S23: 0 | T23: 0 | U23: 46230 | V23: 46230 | W23: TEST | Y23: 0 | Z23: 0 | AA23: 0 | AB23: TEST | AE23: TEST
A24: Đăng | B24: QC-24 | C24: 2000126742 | D24: 12129248 | E24: PR2145021-0-A | F24: Accessories for Masters Parkway HF | G24: 3 | H24: 46234 | I24: 0103539448 | J24: 260707Y34A | K24: 3 | L24: 12003986 | M24: PR19SR002-0-D | N24: 0 | O24: 0 | P24: TEST | Q24: 0 | R24: 46221 | S24: 0 | T24: 0 | U24: 46230 | V24: N/A | W24: TEST | Y24: 0 | Z24: 0 | AA24: 0 | AB24: TEST | AE24: TEST
A25: Đăng | B25: QC-25 | C25: 2000126743 | D25: 12129248 | E25: PR2145021-0-A | F25: Accessories for Masters Parkway HF | G25: 9 | H25: 46234 | I25: 0103539449 | J25: 260707Y34D | K25: 9 | L25: 12003986 | M25: PR19SR002-0-D | N25: 0 | O25: 0 | P25: TEST | Q25: 0 | R25: 46221 | S25: 0 | T25: 0 | U25: 46230 | V25: 46230 | W25: TEST | Y25: 0 | Z25: 0 | AA25: 0 | AB25: TEST | AE25: TEST
A26: CA-H2607-PD-003 | B26: Jul29-02 | C26: 1001910173 | D26: 11134248 | E26: 2041189-D-A | F26: CSR135-26P CN | G26: 620 | H26: 46232 | I26: 0103541259 | J26: 260709K24A | K26: 626 | L26: 12139931 | M26: 2342019-A-C-CN | N26: 0 | O26: 0 | P26: CHINA | Q26: 0 | R26: 46217 | S26: 3 | T26: 3 | U26: 46218 | V26: 46218 | W26: M8 | Y26: =VLOOKUP(F26,[2]New!$B:$G,3,0)*K26/60 -> 350.56 | Z26: =VLOOKUP(F26,[2]New!$B:$G,4,0)*K26/60 -> 672.95 | AA26: =VLOOKUP(F26,[2]New!$B:$G,6,0)*K26/60 -> 1390.7633 | AB26: =VLOOKUP(A26,'[4]PO CAG (2)'!$A:$L,12,0) -> 46268 | AC26: =IFERROR(VLOOKUP(F26,[3]Sheet1!$E:$H,4,0),) -> H | AD26: 620 | AE26: FINISH | AF26: 10 | AI26: 6 | AJ26: M8-3 | AN26: 2 | AO26: 2 | AP26: 2 | AQ26: 2
A27: CA-H2606-PD-223 | B27: Jul30-01 | C27: 1001910722 | D27: 11134249 | E27: 2041190-D-A | F27: CSR150-26P CN | G27: 30 | H27: 46233 | I27: 0103542125 | J27: 260709K25A | K27: 36 | L27: 12139932 | M27: 2342020-A-C-CN | N27: 0 | O27: 0 | P27: CHINA | Q27: 0 | R27: 46218 | S27: 3 | T27: 3 | U27: 46219 | V27: 46219 | W27: M8 | Y27: =VLOOKUP(F27,[2]New!$B:$G,3,0)*K27/60 -> 20.16 | Z27: =VLOOKUP(F27,[2]New!$B:$G,4,0)*K27/60 -> 38.7 | AA27: =VLOOKUP(F27,[2]New!$B:$G,6,0)*K27/60 -> 79.98 | AB27: =VLOOKUP(A27,'[4]PO CAG (2)'!$A:$L,12,0) -> 46268 | AC27: =IFERROR(VLOOKUP(F27,[3]Sheet1!$E:$H,4,0),) -> H | AD27: 30 | AE27: FINISH | AF27: 10 | AI27: 6 | AJ27: M8-1 | AN27: 2 | AO27: 2 | AP27: 2 | AQ27: 2
A28: CA-H2606-PD-222 | B28: Jul30-02 | C28: 1001910723 | D28: 11134248 | E28: 2041189-D-A | F28: CSR135-26P CN | G28: 270 | H28: 46233 | I28: 0103542126 | J28: 260709K26A | K28: 270 | L28: 12139931 | M28: 2342019-A-C-CN | N28: 0 | O28: 0 | P28: CHINA | Q28: 0 | R28: 46218 | S28: 0 | T28: 0 | U28: 46219 | V28: 46219 | W28: M8 | Y28: =VLOOKUP(F28,[2]New!$B:$G,3,0)*K28/60 -> 151.2 | Z28: =VLOOKUP(F28,[2]New!$B:$G,4,0)*K28/60 -> 290.25 | AA28: =VLOOKUP(F28,[2]New!$B:$G,6,0)*K28/60 -> 599.85 | AB28: =VLOOKUP(A28,'[4]PO CAG (2)'!$A:$L,12,0) -> 46268 | AC28: =IFERROR(VLOOKUP(F28,[3]Sheet1!$E:$H,4,0),) -> H | AD28: 270 | AE28: FINISH | AF28: 10 | AI28: 0 | AJ28: M8-1 | AN28: 2 | AO28: 2 | AP28: 2 | AQ28: 2
A29: CA-H2607-PD-003 | B29: Jul30-03 | C29: 1001910724 | D29: 11134248 | E29: 2041189-D-A | F29: CSR135-26P CN | G29: 2050 | H29: 46233 | I29: 0103542127 | J29: 260709K27A | K29: 2050 | L29: 12139931 | M29: 2342019-A-C-CN | N29: 0 | O29: 0 | P29: CHINA | Q29: 0 | R29: 46218 | S29: 0 | T29: 0 | U29: 46219 | V29: 46219 | W29: M8 | Y29: =VLOOKUP(F29,[2]New!$B:$G,3,0)*K29/60 -> 1148 | Z29: =VLOOKUP(F29,[2]New!$B:$G,4,0)*K29/60 -> 2203.75 | AA29: =VLOOKUP(F29,[2]New!$B:$G,6,0)*K29/60 -> 4554.4167 | AB29: =VLOOKUP(A29,'[4]PO CAG (2)'!$A:$L,12,0) -> 46268 | AC29: =IFERROR(VLOOKUP(F29,[3]Sheet1!$E:$H,4,0),) -> H | AD29: 2050 | AE29: FINISH | AF29: 10 | AI29: 0 | AJ29: M8-1 | AN29: 2 | AO29: 2 | AP29: 2 | AQ29: 2
A30: Liên PE | B30: TER-PE-260447-01 | C30: 2000126878 | D30: 11132932 | E30: Z376-1001-0-A | F30: Z376-1001-0-A_MS3552H26-PIG110J | G30: 9 | H30: 46238 | I30: 0103542343 | J30: 260706X01A | K30: 9 | L30: 12145263 | M30: Z376-2001-0-C | N30: 0 | O30: 0 | P30: TEST | Q30: 0 | R30: 46223 | S30: 0 | T30: 0 | U30: 46227 | V30: 46230 | W30: M9 | Y30: 0 | Z30: 0 | AA30: 0 | AB30: TEST | AC30: =IFERROR(VLOOKUP(F30,[3]Sheet1!$E:$H,4,0),) -> 0 | AE30: TEST
A31: Liên PE | B31: TER-PE-260447-02 | C31: 2000126879 | D31: 11132933 | E31: Z376-1002-0-A | F31: Z376-1002-0-A_MS3552H26-PIG110J | G31: 9 | H31: 46238 | I31: 0103542344 | J31: 260706X02A | K31: 9 | L31: 12145264 | M31: Z376-2002-0-C | N31: 0 | O31: 0 | P31: TEST | Q31: 0 | R31: 46223 | S31: 0 | T31: 0 | U31: 46227 | V31: 46230 | W31: M9 | Y31: 0 | Z31: 0 | AA31: 0 | AB31: TEST | AC31: =IFERROR(VLOOKUP(F31,[3]Sheet1!$E:$H,4,0),) -> 0 | AE31: TEST
A32: Liên PE | B32: TER-PE-260447-03 | C32: 2000126880 | D32: 11132934 | E32: Z376-1003-0-A | F32: Z376-1003-0-A_MS3552H26-PIG110J | G32: 9 | H32: 46238 | I32: 0103542345 | J32: 260706X03A | K32: 9 | L32: 12145265 | M32: Z376-2003-0-C | N32: 0 | O32: 0 | P32: TEST | Q32: 0 | R32: 46223 | S32: 0 | T32: 0 | U32: 46227 | V32: 46230 | W32: M9 | Y32: 0 | Z32: 0 | AA32: 0 | AB32: TEST | AC32: =IFERROR(VLOOKUP(F32,[3]Sheet1!$E:$H,4,0),) -> 0 | AE32: TEST
A33: CA-H2607-PD-018 | B33: Jul30-04 | C33: 1001913378 | D33: 11134152 | E33: 1811913-L-A | F33: HW60SP400P10000 CN | G33: 3 | H33: 46233 | I33: 0103547088 | J33: 260713C01A | K33: 3 | L33: 12130016 | M33: 2112103-0-C-CN | N33: 0 | O33: 0 | P33: CHINA | Q33: 0 | R33: 46219 | S33: 0 | T33: 0 | U33: 46220 | V33: 46220 | W33: M9 | Y33: =VLOOKUP(F33,[2]New!$B:$G,3,0)*K33/60 -> 2.8 | Z33: =VLOOKUP(F33,[2]New!$B:$G,4,0)*K33/60 -> 11.7 | AA33: =VLOOKUP(F33,[2]New!$B:$G,6,0)*K33/60 -> 14.45 | AB33: =VLOOKUP(A33,'[4]PO CAG (2)'!$A:$L,12,0) -> 46268 | AC33: =IFERROR(VLOOKUP(F33,[3]Sheet1!$E:$H,4,0),) -> G | AD33: 3 | AE33: FINISH | AF33: 10 | AI33: 0 | AJ33: M9-1 | AN33: 3 | AO33: 3 | AP33: 3 | AQ33: 3
A34: CA-H2607-PD-016 | B34: Jul30-05 | C34: 1001913379 | D34: 11134149 | E34: 1811910-L-A | F34: HW60SP352P10000 CN | G34: 10 | H34: 46233 | I34: 0103547089 | J34: 260713C02A | K34: 10 | L34: 12129996 | M34: 2112100-0-C-CN | N34: 0 | O34: 0 | P34: CHINA | Q34: 0 | R34: 46219 | S34: 0 | T34: 0 | U34: 46220 | V34: 46220 | W34: M9 | Y34: =VLOOKUP(F34,[2]New!$B:$G,3,0)*K34/60 -> 9.3333333 | Z34: =VLOOKUP(F34,[2]New!$B:$G,4,0)*K34/60 -> 39 | AA34: =VLOOKUP(F34,[2]New!$B:$G,6,0)*K34/60 -> 48.166667 | AB34: =VLOOKUP(A34,'[4]PO CAG (2)'!$A:$L,12,0) -> 46268 | AC34: =IFERROR(VLOOKUP(F34,[3]Sheet1!$E:$H,4,0),) -> G | AD34: 10 | AE34: FINISH | AF34: 10 | AI34: 0 | AJ34: M9-1 | AN34: 3 | AO34: 3 | AP34: 3 | AQ34: 3
A35: CA-H2607-PD-014 | B35: Jul30-06 | C35: 1001913380 | D35: 11134146 | E35: 1811907-L-A | F35: HW60SP300P10000 CN | G35: 15 | H35: 46233 | I35: 0103547090 | J35: 260713C03A | K35: 21 | L35: 12129994 | M35: 2112095-0-C-CN | N35: 0 | O35: 0 | P35: CHINA | Q35: 0 | R35: 46219 | S35: 3 | T35: 3 | U35: 46220 | V35: 46220 | W35: M9 | Y35: =VLOOKUP(F35,[2]New!$B:$G,3,0)*K35/60 -> 19.6 | Z35: =VLOOKUP(F35,[2]New!$B:$G,4,0)*K35/60 -> 81.9 | AA35: =VLOOKUP(F35,[2]New!$B:$G,6,0)*K35/60 -> 101.15 | AB35: =VLOOKUP(A35,'[4]PO CAG (2)'!$A:$L,12,0) -> 46268 | AC35: =IFERROR(VLOOKUP(F35,[3]Sheet1!$E:$H,4,0),) -> G | AD35: 15 | AE35: FINISH | AF35: 10 | AI35: 0 | AJ35: M9-1 | AN35: 3 | AO35: 3 | AP35: 3 | AQ35: 3
A36: CA-H2607-PD-017 | B36: Jul30-07 | C36: 1001913381 | D36: 11134150 | E36: 1811911-L-A | F36: HW60SP370P10000 CN | G36: 290 | H36: 46233 | I36: 0103547091 | J36: 260713C04A | K36: 290 | L36: 12129997 | M36: 2112101-0-C-CN | N36: 0 | O36: 0 | P36: CHINA | Q36: 0 | R36: 46219 | S36: 0 | T36: 0 | U36: 46220 | V36: 46220 | W36: M9 | Y36: =VLOOKUP(F36,[2]New!$B:$G,3,0)*K36/60 -> 270.66667 | Z36: =VLOOKUP(F36,[2]New!$B:$G,4,0)*K36/60 -> 1131 | AA36: =VLOOKUP(F36,[2]New!$B:$G,6,0)*K36/60 -> 1396.8333 | AB36: =VLOOKUP(A36,'[4]PO CAG (2)'!$A:$L,12,0) -> 46268 | AC36: =IFERROR(VLOOKUP(F36,[3]Sheet1!$E:$H,4,0),) -> G | AD36: 290 | AE36: FINISH | AF36: 10 | AI36: 6 | AJ36: M9-1 | AN36: 3 | AO36: 3 | AP36: 3 | AQ36: 3
A37: CA-H2606-PD-226 | B37: Jul30-08 | C37: 1001913382 | D37: 11134148 | E37: 1811909-L-A | F37: HW60SP350P10000 CN | G37: 400 | H37: 46233 | I37: 0103547092 | J37: 260713C05A | K37: 400 | L37: 12129995 | M37: 2112099-0-C-CN | N37: 0 | O37: 0 | P37: CHINA | Q37: 0 | R37: 46219 | S37: 0 | T37: 0 | U37: 46220 | V37: 46220 | W37: M9 | Y37: =VLOOKUP(F37,[2]New!$B:$G,3,0)*K37/60 -> 373.33333 | Z37: =VLOOKUP(F37,[2]New!$B:$G,4,0)*K37/60 -> 1560 | AA37: =VLOOKUP(F37,[2]New!$B:$G,6,0)*K37/60 -> 1926.6667 | AB37: =VLOOKUP(A37,'[4]PO CAG (2)'!$A:$L,12,0) -> 46268 | AC37: =IFERROR(VLOOKUP(F37,[3]Sheet1!$E:$H,4,0),) -> G | AD37: 400 | AE37: FINISH | AF37: 10 | AI37: 0 | AJ37: M9-1 | AN37: 3 | AO37: 3 | AP37: 3 | AQ37: 3
A38: CA-H2607-PD-005 | B38: Jul30-09 | C38: 1001913383 | D38: 11134129 | E38: 1811861-J-A | F38: HW60AL070P10000 CN | G38: 40 | H38: 46233 | I38: 0103547093 | J38: 260713C06A | K38: 40 | L38: 12129985 | M38: 2112003-0-C-CN | N38: 0 | O38: 0 | P38: CHINA | Q38: 0 | R38: 46219 | S38: 0 | T38: 0 | U38: 46220 | V38: 46220 | W38: M10 | Y38: =VLOOKUP(F38,[2]New!$B:$G,3,0)*K38/60 -> 37.333333 | Z38: =VLOOKUP(F38,[2]New!$B:$G,4,0)*K38/60 -> 156 | AA38: =VLOOKUP(F38,[2]New!$B:$G,6,0)*K38/60 -> 192.66667 | AB38: =VLOOKUP(A38,'[4]PO CAG (2)'!$A:$L,12,0) -> 46268 | AC38: =IFERROR(VLOOKUP(F38,[3]Sheet1!$E:$H,4,0),) -> G | AD38: 40 | AE38: FINISH | AF38: 10 | AI38: 0 | AJ38: M10-1 | AN38: 3 | AO38: 3 | AP38: 3 | AQ38: 3
A39: CA-H2607-PD-008 | B39: Jul30-10 | C39: 1001913384 | D39: 11134131 | E39: 1811863-J-A | F39: HW60AL100P10000 CN | G39: 96 | H39: 46233 | I39: 0103547094 | J39: 260713C07A | K39: 96 | L39: 12129987 | M39: 2112007-0-C-CN | N39: 0 | O39: 0 | P39: CHINA | Q39: 0 | R39: 46219 | S39: 0 | T39: 0 | U39: 46220 | V39: 46220 | W39: M10 | Y39: =VLOOKUP(F39,[2]New!$B:$G,3,0)*K39/60 -> 89.6 | Z39: =VLOOKUP(F39,[2]New!$B:$G,4,0)*K39/60 -> 374.4 | AA39: =VLOOKUP(F39,[2]New!$B:$G,6,0)*K39/60 -> 462.4 | AB39: =VLOOKUP(A39,'[4]PO CAG (2)'!$A:$L,12,0) -> 46268 | AC39: =IFERROR(VLOOKUP(F39,[3]Sheet1!$E:$H,4,0),) -> G | AD39: 96 | AE39: FINISH | AF39: 10 | AI39: 0 | AJ39: M10-1 | AN39: 3 | AO39: 3 | AP39: 3 | AQ39: 3
A40: CA-H2607-PD-011 | B40: Jul30-11 | C40: 1001913385 | D40: 11134120 | E40: 1811831-J-A | F40: HW60JL400P10000 CN | G40: 380 | H40: 46233 | I40: 0103547095 | J40: 260713C08A | K40: 380 | L40: 12129990 | M40: 2112045-0-C-CN | N40: 0 | O40: 0 | P40: CHINA | Q40: 0 | R40: 46219 | S40: 0 | T40: 0 | U40: 46220 | V40: 46220 | W40: M10 | Y40: =VLOOKUP(F40,[2]New!$B:$G,3,0)*K40/60 -> 354.66667 | Z40: =VLOOKUP(F40,[2]New!$B:$G,4,0)*K40/60 -> 1482 | AA40: =VLOOKUP(F40,[2]New!$B:$G,6,0)*K40/60 -> 1830.3333 | AB40: =VLOOKUP(A40,'[4]PO CAG (2)'!$A:$L,12,0) -> 46268 | AC40: =IFERROR(VLOOKUP(F40,[3]Sheet1!$E:$H,4,0),) -> G | AD40: 380 | AE40: FINISH | AF40: 10 | AI40: 0 | AJ40: M10-1 | AN40: 3 | AO40: 3 | AP40: 3 | AQ40: 3
...

Sheet Sheet2
I5: ETD
D6: CA-H2608-PD-153 | E6: 11122087 | F6: 2341003-B-A | G6: CRV135-19P CE3 | H6: 799 | I6: 46268
D7: CA-H2608-PD-154 | E7: 11122088 | F7: 2341004-B-A | G7: CRV150-19P CE3 | H7: 160 | I7: 46268
D8: CA-H2608-PD-154 | E8: 11122088 | F8: 2341004-B-A | G8: CRV150-19P CE3 | H8: 108 | I8: 46268
D9: CA-H2608-PD-047 | E9: 11122087 | F9: 2341003-B-A | G9: CRV135-19P CE3 | H9: 40 | I9: 46282
D10: CA-H2608-PD-048 | E10: 11122088 | F10: 2341004-B-A | G10: CRV150-19P CE3 | H10: 15 | I10: 46282
M16: Test EN dotoxin
D17: 1001938869 | E17: 11131256 | F17: 1841033-E-A | G17: CRV135-19M JP | H17: 1202 | I17: 46259 | J17: 0103596402 | K17: 260805K03A | L17: 1202 | M17: 0
D18: 1001938871 | E18: 11131258 | F18: 1941001-D-A | G18: CSR135-26PR JP | H18: 1100 | I18: 46259 | J18: 0103596404 | K18: 260805K05A | L18: 1100 | M18: 0
D19: 1001942483 | E19: 11127226 | F19: 2351005-0-A | G19: TES0018S US | H19: 20 | I19: 46260 | J19: 0103602697 | K19: 260807G02A | L19: 22 | M19: 2
D24: CA-H2608-PD-449 | E24: Masters parkway | F24: 11126311 | G24: 1941011-E-A | H24: MST150-18PWSFR JP | I24: JAPAN | J24: 5
D25: CA-H2608-PD-449 | F25: 11124123 | G25: 1941011-F-A | H25: MST150-18PWSFR JP | I25: JAPAN | J25: 1

Sheet Sheet3
A1: PldOrd | B1: Material No | C1: Item code | D1: Item name | E1: Q'ty | F1: Complete Date | G1: Internal Lot | H1: External Lot Ster | I1: Q'ty Input | J1: Material No Type C | K1: Item Code Type C | L1: Label | M1: Seal | N1: STR 1 | O1: STR 2 | P1: MẺ | Q1: Family | R1: WH | S1: PROCESS | T1: ngày lưu kho | U1: Cột ƯỚc
A2: 2000119895 | B2: 11134343 | C2: 1941029-F-A | D2: VEL105-16SR_JP | E2: 92 | F2: 46107 | G2: 0103341900 | H2: 260402X13B | I2: 92 | J2: 12120504 | K2: 1942060-A-C | L2: 46146 | M2: 46147 | N2: 46147 | O2: 46149 | P2: M8 | S2: TEST | U2: Lân2 N7
A3: 2000119880 | B3: 11134343 | C3: 1941029-F-A | D3: VEL105-16SR_JP | E3: 92 | F3: 46140 | G3: 0103341597 | H3: 260402X02B | I3: 92 | J3: 12120504 | K3: 1942060-A-C | L3: 46146 | M3: 46147 | N3: 46147 | O3: 46149 | P3: M8 | S3: TEST | U3: Lân2 N7
A4: 2000119881 | B4: 11134343 | C4: 1941029-F-A | D4: VEL105-16SR_JP | E4: 92 | F4: 46140 | G4: 0103341601 | H4: 260402X03B | I4: 92 | J4: 12120504 | K4: 1942060-A-C | L4: 46146 | M4: 46147 | N4: 46147 | O4: 46149 | P4: M8 | S4: TEST | U4: Lân2 N7
A5: 2000119885 | B5: 11134345 | C5: 1941031-F-A | D5: VEL150-16SR_JP | E5: 57 | F5: 46134 | G5: 0103341645 | H5: 260402X07B | I5: 57 | J5: 12120506 | K5: 1942062-A-C | L5: 46146 | M5: 46147 | N5: 46147 | O5: 46149 | P5: M8 | S5: TEST | U5: Lân2 N7
A6: 2000119886 | B6: 11134345 | C6: 1941031-F-A | D6: VEL150-16SR_JP | E6: 57 | F6: 46134 | G6: 0103341651 | H6: 260402X08B | I6: 57 | J6: 12120506 | K6: 1942062-A-C | L6: 46146 | M6: 46147 | N6: 46147 | O6: 46149 | P6: M8 | S6: TEST | U6: Lân2 N7
A7: 2000119887 | B7: 11134345 | C7: 1941031-F-A | D7: VEL150-16SR_JP | E7: 57 | F7: 46134 | G7: 0103341654 | H7: 260402X09B | I7: 57 | J7: 12120506 | K7: 1942062-A-C | L7: 46146 | M7: 46147 | N7: 46147 | O7: 46149 | P7: M8 | S7: TEST | U7: Lân2 N7
A8: 2000119888 | B8: 11134345 | C8: 1941031-F-A | D8: VEL150-16SR_JP | E8: 56 | F8: 46156 | G8: 0103341656 | H8: 260402X10B | I8: 56 | J8: 12120506 | K8: 1942062-A-C | L8: 46160 | M8: 46161 | N8: 46161 | O8: 46164 | P8: M8 | S8: TEST | U8: Lân2 N22
A9: 2000119889 | B9: 11134345 | C9: 1941031-F-A | D9: VEL150-16SR_JP | E9: 56 | F9: 46156 | G9: 0103341659 | H9: 260402X11B | I9: 56 | J9: 12120506 | K9: 1942062-A-C | L9: 46160 | M9: 46161 | N9: 46161 | O9: 46164 | P9: M8 | S9: TEST | U9: Lân2 N22
A10: 2000119890 | B10: 11134345 | C10: 1941031-F-A | D10: VEL150-16SR_JP | E10: 56 | F10: 46156 | G10: 0103341660 | H10: 260402X12B | I10: 56 | J10: 12120506 | K10: 1942062-A-C | L10: 46160 | M10: 46161 | N10: 46161 | O10: 46164 | P10: M8 | S10: TEST | U10: Lân2 N22
A11: 2000120213 | B11: 11125153 | C11: 1941022-F-A | D11: MST105-27HFR_JP | E11: 250 | F11: 21.Apr,.26 | G11: 0103348715 | H11: 260406X03B | I11: 250 | J11: 12120612 | K11: 2042139-B-C | L11: 46128 | M11: 46147 | N11: 46147 | O11: 46149 | P11: M8 | S11: TEST | U11: Lân2 N7
A12: 2000120120 | B12: 11125140 | C12: 1941009-D-A | D12: MST105-18PWSFR_JP | E12: 129 | F12: 18.May.26 | G12: 0103345627 | H12: 260404X13B | I12: 129 | J12: 12120562 | K12: 1942040-A-C | L12: 46160 | M12: 46161 | N12: 46161 | O12: 46164 | P12: M8 | S12: TEST | U12: Lân2 N22
A13: 2000120122 | B13: 11125140 | C13: 1941009-D-A | D13: MST105-18PWSFR_JP | E13: 129 | F13: 18.May.26 | G13: 0103345628 | H13: 260404X14B | I13: 129 | J13: 12120562 | K13: 1942040-A-C | L13: 46160 | M13: 46161 | N13: 46161 | O13: 46164 | P13: M8 | S13: TEST | U13: Lân2 N22
A14: 2000120124 | B14: 11125140 | C14: 1941009-D-A | D14: MST105-18PWSFR_JP | E14: 129 | F14: 18.May.26 | G14: 0103345629 | H14: 260404X15B | I14: 129 | J14: 12120562 | K14: 1942040-A-C | L14: 46160 | M14: 46161 | N14: 46161 | O14: 46164 | P14: M8 | S14: TEST | U14: Lân2 N22
A15: 2000120132 | B15: 11125142 | C15: 1941011-D-A | D15: MST150-18PWSFR_JP | E15: 66 | F15: 18.May.26 | G15: 0103345643 | H15: 260404X22B | I15: 66 | J15: 12120564 | K15: 1942042-A-C | L15: 46160 | M15: 46161 | N15: 46161 | O15: 46164 | P15: M8 | S15: TEST | U15: Lân2 N22
A16: 2000120133 | B16: 11125142 | C16: 1941011-D-A | D16: MST150-18PWSFR_JP | E16: 66 | F16: 18.May.26 | G16: 0103345649 | H16: 260404X23B | I16: 66 | J16: 12120564 | K16: 1942042-A-C | L16: 46160 | M16: 46161 | N16: 46161 | O16: 46164 | P16: M8 | S16: TEST | U16: Lân2 N22
A17: 2000120134 | B17: 11125142 | C17: 1941011-D-A | D17: MST150-18PWSFR_JP | E17: 66 | F17: 18.May.26 | G17: 0103345655 | H17: 260404X24B | I17: 66 | J17: 12120564 | K17: 1942042-A-C | L17: 46160 | M17: 46161 | N17: 46161 | O17: 46164 | P17: M8 | S17: TEST | U17: Lân2 N22
A18: 2000120138 | B18: 11132001 | C18: 1941063-D-A | D18: TLS105-16YR_JP | E18: 129 | F18: 16.Apr.26 | G18: 0103345839 | H18: 260404X25B | I18: 129 | J18: 12120522 | K18: 1942078-A-C | L18: 46149 | M18: 46150 | N18: 46150 | O18: 46153 | P18: M8 | S18: TEST | U18: Lân2 N11
A19: 2000120139 | B19: 11132001 | C19: 1941063-D-A | D19: TLS105-16YR_JP | E19: 129 | F19: 16.Apr.26 | G19: 0103345841 | H19: 260404X26B | I19: 129 | J19: 12120522 | K19: 1942078-A-C | L19: 46149 | M19: 46150 | N19: 46150 | O19: 46153 | P19: M8 | S19: TEST | U19: Lân2 N11
A20: 2000120140 | B20: 11132001 | C20: 1941063-D-A | D20: TLS105-16YR_JP | E20: 129 | F20: 16.Apr.26 | G20: 0103345844 | H20: 260404X27B | I20: 129 | J20: 12120522 | K20: 1942078-A-C | L20: 46149 | M20: 46150 | N20: 46150 | O20: 46153 | P20: M8 | S20: TEST | U20: Lân2 N11
A21: 2000120141 | B21: 11132001 | C21: 1941063-D-A | D21: TLS105-16YR_JP | E21: 129 | F21: 18.May.26 | G21: 0103345846 | H21: 260404X28B | I21: 129 | J21: 12120522 | K21: 1942078-A-C | L21: 46160 | M21: 46161 | N21: 46161 | O21: 46164 | P21: M8 | S21: TEST | U21: Lân2 N22
A22: 2000120142 | B22: 11132001 | C22: 1941063-D-A | D22: TLS105-16YR_JP | E22: 129 | F22: 18.May.26 | G22: 0103345848 | H22: 260404X29B | I22: 129 | J22: 12120522 | K22: 1942078-A-C | L22: 46160 | M22: 46161 | N22: 46161 | O22: 46164 | P22: M8 | S22: TEST | U22: Lân2 N22
... A32: 2000120152 | B32: 11132003 | C32: 1941065-D-A | D32: TLS150-16YR_JP | E32: 69 | F32: 18.May.26 | G32: 0103345862 | H32: 260404X39B | I32: 69 | J32: 12120524 | K32: 1942080-A-C | L32: 46160 | M32: 46161 | N32: 46161 | O32: 46164 | P32: M8 | S32: TEST | U32: Lân2 N22
A41: TT | B41: PldOrd | C41: Material No | D41: Item code | E41: Item name | F41: Q'ty | G41: Complete Date | H41: Internal Lot | I41: External Lot Ster | J41: Q'ty Input | K41: Material No Type C | L41: Item Code Type C | M41: QA test | O41: KEEP | P41: KEEP | Q41: Bioburden | R41: Label | S41: Test Endotoxin ( pcs) | T41: Test Particle ( pcs) | U41: Seal | V41: Ster | W41: MẺ | X41: BOXING | Y41: Label | Z41: Seal | AA41: Boxing | AB41: ETD | AC41: Family | AD41: WH | AE41: PROCESS | AF41: ngày lưu kho | AG41: Cột ƯỚc
A42: TER-PE-260232-01 | B42: 2000119895 | C42: 11134343 | D42: 1941029-F-A | E42: VEL105-16SR_JP | F42: 92 | G42: 46107 | H42: 0103341900 | I42: 260402X13B | J42: 92 | K42: 12120504 | L42: 1942060-A-C | M42: 0 | O42: 0 | P42: 0 | Q42: 0 | R42: 46146 | S42: 0 | T42: 0 | U42: 46147 | V42: 46147 | W42: M8 | Y42: 0 | Z42: 0 | AA42: 0 | AB42: 46161 | AC42: 0 | AE42: TEST | AG42: Lân2 N7
A43: TER-PE-260232-02 | B43: 2000119880 | C43: 11134343 | D43: 1941029-F-A | E43: VEL105-16SR_JP | F43: 92 | G43: 46140 | H43: 0103341597 | I43: 260402X02B | J43: 92 | K43: 12120504 | L43: 1942060-A-C | M43: 0 | O43: 0 | P43: 0 | Q43: 0 | R43: 46146 | S43: 0 | T43: 0 | U43: 46147 | V43: 46147 | W43: M8 | Y43: 0 | Z43: 0 | AA43: 0 | AB43: 46161 | AC43: 0 | AE43: TEST | AG43: Lân2 N7
A44: TER-PE-260232-03 | B44: 2000119881 | C44: 11134343 | D44: 1941029-F-A | E44: VEL105-16SR_JP | F44: 92 | G44: 46140 | H44: 0103341601 | I44: 260402X03B | J44: 92 | K44: 12120504 | L44: 1942060-A-C | M44: 0 | O44: 0 | P44: 0 | Q44: 0 | R44: 46146 | S44: 0 | T44: 0 | U44: 46147 | V44: 46147 | W44: M8 | Y44: 0 | Z44: 0 | AA44: 0 | AB44: 46161 | AC44: 0 | AE44: TEST | AG44: Lân2 N7
A45: TER-PE-260232-07 | B45: 2000119885 | C45: 11134345 | D45: 1941031-F-A | E45: VEL150-16SR_JP | F45: 57 | G45: 46134 | H45: 0103341645 | I45: 260402X07B | J45: 57 | K45: 12120506 | L45: 1942062-A-C | M45: 0 | O45: 0 | P45: 0 | Q45: 0 | R45: 46146 | S45: 0 | T45: 0 | U45: 46147 | V45: 46147 | W45: M8 | Y45: 0 | Z45: 0 | AA45: 0 | AB45: 46157 | AC45: 0 | AE45: TEST | AG45: Lân2 N7
A46: TER-PE-260232-08 | B46: 2000119886 | C46: 11134345 | D46: 1941031-F-A | E46: VEL150-16SR_JP | F46: 57 | G46: 46134 | H46: 0103341651 | I46: 260402X08B | J46: 57 | K46: 12120506 | L46: 1942062-A-C | M46: 0 | O46: 0 | P46: 0 | Q46: 0 | R46: 46146 | S46: 0 | T46: 0 | U46: 46147 | V46: 46147 | W46: M8 | Y46: 0 | Z46: 0 | AA46: 0 | AB46: 46157 | AC46: 0 | AE46: TEST | AG46: Lân2 N7
A47: TER-PE-260232-09 | B47: 2000119887 | C47: 11134345 | D47: 1941031-F-A | E47: VEL150-16SR_JP | F47: 57 | G47: 46134 | H47: 0103341654 | I47: 260402X09B | J47: 57 | K47: 12120506 | L47: 1942062-A-C | M47: 0 | O47: 0 | P47: 0 | Q47: 0 | R47: 46146 | S47: 0 | T47: 0 | U47: 46147 | V47: 46147 | W47: M8 | Y47: 0 | Z47: 0 | AA47: 0 | AB47: 46157 | AC47: 0 | AE47: TEST | AG47: Lân2 N7
A48: TER-PE-260232-10 | B48: 2000119888 | C48: 11134345 | D48: 1941031-F-A | E48: VEL150-16SR_JP | F48: 56 | G48: 46156 | H48: 0103341656 | I48: 260402X10B | J48: 56 | K48: 12120506 | L48: 1942062-A-C | M48: 0 | O48: 0 | P48: 0 | Q48: 0 | R48: 46160 | S48: 0 | T48: 0 | U48: 46161 | V48: 46161 | W48: M8 | Y48: 0 | Z48: 0 | AA48: 0 | AB48: 46175 | AC48: 0 | AE48: TEST | AG48: Lân2 N22
A49: TER-PE-260232-11 | B49: 2000119889 | C49: 11134345 | D49: 1941031-F-A | E49: VEL150-16SR_JP | F49: 56 | G49: 46156 | H49: 0103341659 | I49: 260402X11B | J49: 56 | K49: 12120506 | L49: 1942062-A-C | M49: 0 | O49: 0 | P49: 0 | Q49: 0 | R49: 46160 | S49: 0 | T49: 0 | U49: 46161 | V49: 46161 | W49: M8 | Y49: 0 | Z49: 0 | AA49: 0 | AB49: 46175 | AC49: 0 | AE49: TEST | AG49: Lân2 N22
A50: TER-PE-260232-12 | B50: 2000119890 | C50: 11134345 | D50: 1941031-F-A | E50: VEL150-16SR_JP | F50: 56 | G50: 46156 | H50: 0103341660 | I50: 260402X12B | J50: 56 | K50: 12120506 | L50: 1942062-A-C | M50: 0 | O50: 0 | P50: 0 | Q50: 0 | R50: 46160 | S50: 0 | T50: 0 | U50: 46161 | V50: 46161 | W50: M8 | Y50: 0 | Z50: 0 | AA50: 0 | AB50: 46175 | AC50: 0 | AE50: TEST | AG50: Lân2 N22
A51: TER-PE-260235-03 | B51: 2000120213 | C51: 11125153 | D51: 1941022-F-A | E51: MST105-27HFR_JP | F51: 250 | G51: 21.Apr,.26 | H51: 0103348715 | I51: 260406X03B | J51: 250 | K51: 12120612 | L51: 2042139-B-C | M51: 0 | O51: 0 | P51: 0 | Q51: 0 | R51: 46128 | S51: 0 | T51: 0 | U51: 46147 | V51: 46147 | W51: M8 | X51: 46134 | Y51: 0 | Z51: 0 | AA51: 0 | AB51: 46154 | AE51: TEST | AG51: Lân2 N7
A52: TER-PE-260234-04 | B52: 2000120120 | C52: 11125140 | D52: 1941009-D-A | E52: MST105-18PWSFR_JP | F52: 129 | G52: 18.May.26 | H52: 0103345627 | I52: 260404X13B | J52: 129 | K52: 12120562 | L52: 1942040-A-C | M52: 0 | O52: 0 | P52: 0 | Q52: 0 | R52: 46160 | S52: 0 | T52: 0 | U52: 46161 | V52: 46161 | W52: M8 | AB52: 46175 | AE52: TEST | AG52: Lân2 N22
A53: TER-PE-260234-05 | B53: 2000120122 | C53: 11125140 | D53: 1941009-D-A | E53: MST105-18PWSFR_JP | F53: 129 | G53: 18.May.26 | H53: 0103345628 | I53: 260404X14B | J53: 129 | K53: 12120562 | L53: 1942040-A-C | M53: 0 | O53: 0 | P53: 0 | Q53: 0 | R53: 46160 | S53: 0 | T53: 0 | U53: 46161 | V53: 46161 | W53: M8 | AB53: 46175 | AE53: TEST | AG53: Lân2 N22
A54: TER-PE-260234-06 | B54: 2000120124 | C54: 11125140 | D54: 1941009-D-A | E54: MST105-18PWSFR_JP | F54: 129 | G54: 18.May.26 | H54: 0103345629 | I54: 260404X15B | J54: 129 | K54: 12120562 | L54: 1942040-A-C | M54: 0 | O54: 0 | P54: 0 | Q54: 0 | R54: 46160 | S54: 0 | T54: 0 | U54: 46161 | V54: 46161 | W54: M8 | AB54: 46175 | AE54: TEST | AG54: Lân2 N22
A55: TER-PE-260234-13 | B55: 2000120132 | C55: 11125142 | D55: 1941011-D-A | E55: MST150-18PWSFR_JP | F55: 66 | G55: 18.May.26 | H55: 0103345643 | I55: 260404X22B | J55: 66 | K55: 12120564 | L55: 1942042-A-C | M55: 0 | O55: 0 | P55: 0 | Q55: 0 | R55: 46160 | S55: 0 | T55: 0 | U55: 46161 | V55: 46161 | W55: M8 | AB55: 46175 | AE55: TEST | AG55: Lân2 N22
A56: TER-PE-260234-14 | B56: 2000120133 | C56: 11125142 | D56: 1941011-D-A | E56: MST150-18PWSFR_JP | F56: 66 | G56: 18.May.26 | H56: 0103345649 | I56: 260404X23B | J56: 66 | K56: 12120564 | L56: 1942042-A-C | M56: 0 | O56: 0 | P56: 0 | Q56: 0 | R56: 46160 | S56: 0 | T56: 0 | U56: 46161 | V56: 46161 | W56: M8 | AB56: 46175 | AE56: TEST | AG56: Lân2 N22
A57: TER-PE-260234-15 | B57: 2000120134 | C57: 11125142 | D57: 1941011-D-A | E57: MST150-18PWSFR_JP | F57: 66 | G57: 18.May.26 | H57: 0103345655 | I57: 260404X24B | J57: 66 | K57: 12120564 | L57: 1942042-A-C | M57: 0 | O57: 0 | P57: 0 | Q57: 0 | R57: 46160 | S57: 0 | T57: 0 | U57: 46161 | V57: 46161 | W57: M8 | AB57: 46175 | AE57: TEST | AG57: Lân2 N22
...

Sheet Label
A1: DIV/ SECTION | C1: DAILY PLAN AND IN-OUT LABEL CONTROL LIST ( Kế hoạch sản xuất hàng ngày và quản lý việc In-Out Label) | N1: F-1469 Ver 1.07
A2: GPC/ Order control | N2: Page : / 1
A4: PLAN DATE : | C4: 46259
A5: No | B5: Material | C5: Drawing List No | D5: Item name/Description | E5: Plnd order / PO | F5: Schuled Finish Date | G5: Internal Lot (SAP Lot) | H5: External Lot (Hanoi Lot) | I5: Q'ty | J5: Sterilize | L5: Finish | M5: Out label control | O5: Remark
J6: Date | K6: Batch | M6: Bag | N6: Box
A7: Aug15-01 | B7: =VLOOKUP($A7,PLAN!$B:$AC,3,0) -> 12129248 | C7: =VLOOKUP($A7,PLAN!$B:$AC,4,0) -> PR2145021-0-A | D7: =VLOOKUP($A7,PLAN!$B:$AC,5,0) -> 2009051 Masters HF CN | E7: =VLOOKUP($A7,PLAN!$B:$AC,2,0) -> 1001897397 | F7: =VLOOKUP($A7,PLAN!$B:$AC,7,0) -> 46249 | G7: =VLOOKUP($A7,PLAN!$B:$AC,8,0) -> 0103516476 | H7: =VLOOKUP($A7,PLAN!$B:$AC,9,0) -> 260625K01A | I7: =VLOOKUP($A7,PLAN!$B:$AC,10,0) -> 3306 | J7: =VLOOKUP($A7,PLAN!$B:$AC,21,0) -> 46206 | K7: =VLOOKUP($A7,PLAN!$B:$AC,22,0) -> M8 | O7: CAG | Q7: =VLOOKUP(A7,PLAN!B:R,17,0) -> 46205
A8: Jul29-02 | B8: =VLOOKUP($A8,PLAN!$B:$AC,3,0) -> 11134248 | C8: =VLOOKUP($A8,PLAN!$B:$AC,4,0) -> 2041189-D-A | D8: =VLOOKUP($A8,PLAN!$B:$AC,5,0) -> CSR135-26P CN | E8: =VLOOKUP($A8,PLAN!$B:$AC,2,0) -> 1001910173 | F8: =VLOOKUP($A8,PLAN!$B:$AC,7,0) -> 46232 | G8: =VLOOKUP($A8,PLAN!$B:$AC,8,0) -> 0103541259 | H8: =VLOOKUP($A8,PLAN!$B:$AC,9,0) -> 260709K24A | I8: =VLOOKUP($A8,PLAN!$B:$AC,10,0) -> 626 | J8: =VLOOKUP($A8,PLAN!$B:$AC,21,0) -> 46218 | K8: =VLOOKUP($A8,PLAN!$B:$AC,22,0) -> M8 | O8: CAG | Q8: =VLOOKUP(A8,PLAN!B:R,17,0) -> 46217
A9: Jul30-01 | B9: =VLOOKUP($A9,PLAN!$B:$AC,3,0) -> 11134249 | C9: =VLOOKUP($A9,PLAN!$B:$AC,4,0) -> 2041190-D-A | D9: =VLOOKUP($A9,PLAN!$B:$AC,5,0) -> CSR150-26P CN | E9: =VLOOKUP($A9,PLAN!$B:$AC,2,0) -> 1001910722 | F9: =VLOOKUP($A9,PLAN!$B:$AC,7,0) -> 46233 | G9: =VLOOKUP($A9,PLAN!$B:$AC,8,0) -> 0103542125 | H9: =VLOOKUP($A9,PLAN!$B:$AC,9,0) -> 260709K25A | I9: =VLOOKUP($A9,PLAN!$B:$AC,10,0) -> 36 | J9: =VLOOKUP($A9,PLAN!$B:$AC,21,0) -> 46219 | K9: =VLOOKUP($A9,PLAN!$B:$AC,22,0) -> M8 | O9: CAG | Q9: =VLOOKUP(A9,PLAN!B:R,17,0) -> 46218
A10: Jul30-02 | B10: =VLOOKUP($A10,PLAN!$B:$AC,3,0) -> 11134248 | C10: =VLOOKUP($A10,PLAN!$B:$AC,4,0) -> 2041189-D-A | D10: =VLOOKUP($A10,PLAN!$B:$AC,5,0) -> CSR135-26P CN | E10: =VLOOKUP($A10,PLAN!$B:$AC,2,0) -> 1001910723 | F10: =VLOOKUP($A10,PLAN!$B:$AC,7,0) -> 46233 | G10: =VLOOKUP($A10,PLAN!$B:$AC,8,0) -> 0103542126 | H10: =VLOOKUP($A10,PLAN!$B:$AC,9,0) -> 260709K26A | I10: =VLOOKUP($A10,PLAN!$B:$AC,10,0) -> 270 | J10: =VLOOKUP($A10,PLAN!$B:$AC,21,0) -> 46219 | K10: =VLOOKUP($A10,PLAN!$B:$AC,22,0) -> M8 | O10: CAG | Q10: =VLOOKUP(A10,PLAN!B:R,17,0) -> 46218
A11: Jul30-03 | B11: =VLOOKUP($A11,PLAN!$B:$AC,3,0) -> 11134248 | C11: =VLOOKUP($A11,PLAN!$B:$AC,4,0) -> 2041189-D-A | D11: =VLOOKUP($A11,PLAN!$B:$AC,5,0) -> CSR135-26P CN | E11: =VLOOKUP($A11,PLAN!$B:$AC,2,0) -> 1001910724 | F11: =VLOOKUP($A11,PLAN!$B:$AC,7,0) -> 46233 | G11: =VLOOKUP($A11,PLAN!$B:$AC,8,0) -> 0103542127 | H11: =VLOOKUP($A11,PLAN!$B:$AC,9,0) -> 260709K27A | I11: =VLOOKUP($A11,PLAN!$B:$AC,10,0) -> 2050 | J11: =VLOOKUP($A11,PLAN!$B:$AC,21,0) -> 46219 | K11: =VLOOKUP($A11,PLAN!$B:$AC,22,0) -> M8 | O11: CAG | Q11: =VLOOKUP(A11,PLAN!B:R,17,0) -> 46218
A12: QC-5 | B12: =VLOOKUP($A12,PLAN!$B:$AC,3,0) -> 11125142 | C12: =VLOOKUP($A12,PLAN!$B:$AC,4,0) -> 1941011-D-A | D12: =VLOOKUP($A12,PLAN!$B:$AC,5,0) -> Masters PARKWAY SOFT 150cm Straight | E12: =VLOOKUP($A12,PLAN!$B:$AC,2,0) -> 2000126703 | F12: =VLOOKUP($A12,PLAN!$B:$AC,7,0) -> 46234 | G12: =VLOOKUP($A12,PLAN!$B:$AC,8,0) -> 0103539406 | H12: =VLOOKUP($A12,PLAN!$B:$AC,9,0) -> 260707Y17A | I12: =VLOOKUP($A12,PLAN!$B:$AC,10,0) -> 3 | J12: =VLOOKUP($A12,PLAN!$B:$AC,21,0) -> N/A | K12: =VLOOKUP($A12,PLAN!$B:$AC,22,0) -> TEST | O12: CAG | Q12: Bio
A13: QC-6 | B13: =VLOOKUP($A13,PLAN!$B:$AC,3,0) -> 11125142 | C13: =VLOOKUP($A13,PLAN!$B:$AC,4,0) -> 1941011-D-A | D13: =VLOOKUP($A13,PLAN!$B:$AC,5,0) -> Masters PARKWAY SOFT 150cm Straight | E13: =VLOOKUP($A13,PLAN!$B:$AC,2,0) -> 2000126704 | F13: =VLOOKUP($A13,PLAN!$B:$AC,7,0) -> 46234 | G13: =VLOOKUP($A13,PLAN!$B:$AC,8,0) -> 0103539408 | H13: =VLOOKUP($A13,PLAN!$B:$AC,9,0) -> 260707Y17D | I13: =VLOOKUP($A13,PLAN!$B:$AC,10,0) -> 9 | J13: =VLOOKUP($A13,PLAN!$B:$AC,21,0) -> 46230 | K13: =VLOOKUP($A13,PLAN!$B:$AC,22,0) -> TEST | O13: CAG | Q13: Bio
A14: QC-7 | B14: =VLOOKUP($A14,PLAN!$B:$AC,3,0) -> 11112488 | C14: =VLOOKUP($A14,PLAN!$B:$AC,4,0) -> PSC35170S-E-A | D14: =VLOOKUP($A14,PLAN!$B:$AC,5,0) -> CROSSWALK 035 170cm Straight | E14: =VLOOKUP($A14,PLAN!$B:$AC,2,0) -> 2000126705 | F14: =VLOOKUP($A14,PLAN!$B:$AC,7,0) -> 46234 | G14: =VLOOKUP($A14,PLAN!$B:$AC,8,0) -> 0103539409 | H14: =VLOOKUP($A14,PLAN!$B:$AC,9,0) -> 260707Y18A | I14: =VLOOKUP($A14,PLAN!$B:$AC,10,0) -> 3 | J14: =VLOOKUP($A14,PLAN!$B:$AC,21,0) -> N/A | K14: =VLOOKUP($A14,PLAN!$B:$AC,22,0) -> TEST | O14: CAG | Q14: Bio
A15: QC-8 | B15: =VLOOKUP($A15,PLAN!$B:$AC,3,0) -> 11112488 | C15: =VLOOKUP($A15,PLAN!$B:$AC,4,0) -> PSC35170S-E-A | D15: =VLOOKUP($A15,PLAN!$B:$AC,5,0) -> CROSSWALK 035 170cm Straight | E15: =VLOOKUP($A15,PLAN!$B:$AC,2,0) -> 2000126706 | F15: =VLOOKUP($A15,PLAN!$B:$AC,7,0) -> 46234 | G15: =VLOOKUP($A15,PLAN!$B:$AC,8,0) -> 0103539410 | H15: =VLOOKUP($A15,PLAN!$B:$AC,9,0) -> 260707Y18D | I15: =VLOOKUP($A15,PLAN!$B:$AC,10,0) -> 9 | J15: =VLOOKUP($A15,PLAN!$B:$AC,21,0) -> 46230 | K15: =VLOOKUP($A15,PLAN!$B:$AC,22,0) -> TEST | O15: CAG | Q15: Bio
A16: QC-9 | B16: =VLOOKUP($A16,PLAN!$B:$AC,3,0) -> 12012480 | C16: =VLOOKUP($A16,PLAN!$B:$AC,4,0) -> PR1944001-0-A | D16: =VLOOKUP($A16,PLAN!$B:$AC,5,0) -> Accessories for Masters Parkway HF | E16: =VLOOKUP($A16,PLAN!$B:$AC,2,0) -> 2000126709 | F16: =VLOOKUP($A16,PLAN!$B:$AC,7,0) -> 46234 | G16: =VLOOKUP($A16,PLAN!$B:$AC,8,0) -> 0103539413 | H16: =VLOOKUP($A16,PLAN!$B:$AC,9,0) -> 260707Y20A | I16: =VLOOKUP($A16,PLAN!$B:$AC,10,0) -> 3 | J16: =VLOOKUP($A16,PLAN!$B:$AC,21,0) -> N/A | K16: =VLOOKUP($A16,PLAN!$B:$AC,22,0) -> TEST | O16: CAG | Q16: Bio
A17: QC-10 | B17: =VLOOKUP($A17,PLAN!$B:$AC,3,0) -> 12012480 | C17: =VLOOKUP($A17,PLAN!$B:$AC,4,0) -> PR1944001-0-A | D17: =VLOOKUP($A17,PLAN!$B:$AC,5,0) -> Accessories for Masters Parkway HF | E17: =VLOOKUP($A17,PLAN!$B:$AC,2,0) -> 2000126710 | F17: =VLOOKUP($A17,PLAN!$B:$AC,7,0) -> 46234 | G17: =VLOOKUP($A17,PLAN!$B:$AC,8,0) -> 0103539414 | H17: =VLOOKUP($A17,PLAN!$B:$AC,9,0) -> 260707Y20D | I17: =VLOOKUP($A17,PLAN!$B:$AC,10,0) -> 9 | J17: =VLOOKUP($A17,PLAN!$B:$AC,21,0) -> 46230 | K17: =VLOOKUP($A17,PLAN!$B:$AC,22,0) -> TEST | O17: CAG | Q17: Bio
A18: QC-11 | B18: =VLOOKUP($A18,PLAN!$B:$AC,3,0) -> 12143523 | C18: =VLOOKUP($A18,PLAN!$B:$AC,4,0) -> PR2545028-0-A | D18: =VLOOKUP($A18,PLAN!$B:$AC,5,0) -> 2009009 Veloute | E18: =VLOOKUP($A18,PLAN!$B:$AC,2,0) -> 2000127274 | F18: =VLOOKUP($A18,PLAN!$B:$AC,7,0) -> 46234 | G18: =VLOOKUP($A18,PLAN!$B:$AC,8,0) -> 0103553325 | H18: =VLOOKUP($A18,PLAN!$B:$AC,9,0) -> 260707Y21A | I18: =VLOOKUP($A18,PLAN!$B:$AC,10,0) -> 3 | J18: =VLOOKUP($A18,PLAN!$B:$AC,21,0) -> N/A | K18: =VLOOKUP($A18,PLAN!$B:$AC,22,0) -> TEST | O18: CAG | Q18: Bio
A19: QC-12 | B19: =VLOOKUP($A19,PLAN!$B:$AC,3,0) -> 12143523 | C19: =VLOOKUP($A19,PLAN!$B:$AC,4,0) -> PR2545028-0-A | D19: =VLOOKUP($A19,PLAN!$B:$AC,5,0) -> 2009009 Veloute | E19: =VLOOKUP($A19,PLAN!$B:$AC,2,0) -> 2000127275 | F19: =VLOOKUP($A19,PLAN!$B:$AC,7,0) -> 46234 | G19: =VLOOKUP($A19,PLAN!$B:$AC,8,0) -> 0103553326 | H19: =VLOOKUP($A19,PLAN!$B:$AC,9,0) -> 260707Y21D | I19: =VLOOKUP($A19,PLAN!$B:$AC,10,0) -> 9 | J19: =VLOOKUP($A19,PLAN!$B:$AC,21,0) -> 46230 | K19: =VLOOKUP($A19,PLAN!$B:$AC,22,0) -> TEST | O19: CAG | Q19: Bio
A20: QC-13 | B20: =VLOOKUP($A20,PLAN!$B:$AC,3,0) -> 11134563 | C20: =VLOOKUP($A20,PLAN!$B:$AC,4,0) -> 2041304-C-A | D20: =VLOOKUP($A20,PLAN!$B:$AC,5,0) -> ASAHI Masters PARKWAY HF 150cm Straight | E20: =VLOOKUP($A20,PLAN!$B:$AC,2,0) -> 2000126731 | F20: =VLOOKUP($A20,PLAN!$B:$AC,7,0) -> 46234 | G20: =VLOOKUP($A20,PLAN!$B:$AC,8,0) -> 0103539435 | H20: =VLOOKUP($A20,PLAN!$B:$AC,9,0) -> 260707Y30A | I20: =VLOOKUP($A20,PLAN!$B:$AC,10,0) -> 3 | J20: =VLOOKUP($A20,PLAN!$B:$AC,21,0) -> N/A | K20: =VLOOKUP($A20,PLAN!$B:$AC,22,0) -> TEST | O20: CAG | Q20: Bio
A21: QC-14 | B21: =VLOOKUP($A21,PLAN!$B:$AC,3,0) -> 11134563 | C21: =VLOOKUP($A21,PLAN!$B:$AC,4,0) -> 2041304-C-A | D21: =VLOOKUP($A21,PLAN!$B:$AC,5,0) -> ASAHI Masters PARKWAY HF 150cm Straight | E21: =VLOOKUP($A21,PLAN!$B:$AC,2,0) -> 2000126732 | F21: =VLOOKUP($A21,PLAN!$B:$AC,7,0) -> 46234 | G21: =VLOOKUP($A21,PLAN!$B:$AC,8,0) -> 0103539437 | H21: =VLOOKUP($A21,PLAN!$B:$AC,9,0) -> 260707Y30B | I21: =VLOOKUP($A21,PLAN!$B:$AC,10,0) -> 9 | J21: =VLOOKUP($A21,PLAN!$B:$AC,21,0) -> 46230 | K21: =VLOOKUP($A21,PLAN!$B:$AC,22,0) -> TEST | O21: CAG | Q21: Bio
A22: QC-15 | B22: =VLOOKUP($A22,PLAN!$B:$AC,3,0) -> 11134563 | C22: =VLOOKUP($A22,PLAN!$B:$AC,4,0) -> 2041304-C-A | D22: =VLOOKUP($A22,PLAN!$B:$AC,5,0) -> ASAHI Masters PARKWAY HF 150cm Straight | E22: =VLOOKUP($A22,PLAN!$B:$AC,2,0) -> 2000126733 | F22: =VLOOKUP($A22,PLAN!$B:$AC,7,0) -> 46234 | G22: =VLOOKUP($A22,PLAN!$B:$AC,8,0) -> 0103539438 | H22: =VLOOKUP($A22,PLAN!$B:$AC,9,0) -> 260707Y30D | I22: =VLOOKUP($A22,PLAN!$B:$AC,10,0) -> 9 | J22: =VLOOKUP($A22,PLAN!$B:$AC,21,0) -> 46230 | K22: =VLOOKUP($A22,PLAN!$B:$AC,22,0) -> TEST | O22: CAG | Q22: Bio
A23: QC-16 | B23: =VLOOKUP($A23,PLAN!$B:$AC,3,0) -> 11134247 | C23: =VLOOKUP($A23,PLAN!$B:$AC,4,0) -> 2141050-D-A | D23: =VLOOKUP($A23,PLAN!$B:$AC,5,0) -> ASAHI Caravel 150cm | E23: =VLOOKUP($A23,PLAN!$B:$AC,2,0) -> 2000126734 | F23: =VLOOKUP($A23,PLAN!$B:$AC,7,0) -> 46234 | G23: =VLOOKUP($A23,PLAN!$B:$AC,8,0) -> 0103539439 | H23: =VLOOKUP($A23,PLAN!$B:$AC,9,0) -> 260707Y31A | I23: =VLOOKUP($A23,PLAN!$B:$AC,10,0) -> 3 | J23: =VLOOKUP($A23,PLAN!$B:$AC,21,0) -> N/A | K23: =VLOOKUP($A23,PLAN!$B:$AC,22,0) -> TEST | O23: CAG | Q23: Bio
... A33: QC-25 | B33: =VLOOKUP($A33,PLAN!$B:$AC,3,0) -> 12129248 | C33: =VLOOKUP($A33,PLAN!$B:$AC,4,0) -> PR2145021-0-A | D33: =VLOOKUP($A33,PLAN!$B:$AC,5,0) -> Accessories for Masters Parkway HF | E33: =VLOOKUP($A33,PLAN!$B:$AC,2,0) -> 2000126743 | F33: =VLOOKUP($A33,PLAN!$B:$AC,7,0) -> 46234 | G33: =VLOOKUP($A33,PLAN!$B:$AC,8,0) -> 0103539449 | H33: =VLOOKUP($A33,PLAN!$B:$AC,9,0) -> 260707Y34D | I33: =VLOOKUP($A33,PLAN!$B:$AC,10,0) -> 9 | J33: =VLOOKUP($A33,PLAN!$B:$AC,21,0) -> 46230 | K33: =VLOOKUP($A33,PLAN!$B:$AC,22,0) -> TEST | O33: CAG | Q33: Bio
A34: Jul30-04 | B34: =VLOOKUP($A34,PLAN!$B:$AC,3,0) -> 11134152 | C34: =VLOOKUP($A34,PLAN!$B:$AC,4,0) -> 1811913-L-A | D34: =VLOOKUP($A34,PLAN!$B:$AC,5,0) -> HW60SP400P10000 CN | E34: =VLOOKUP($A34,PLAN!$B:$AC,2,0) -> 1001913378 | F34: =VLOOKUP($A34,PLAN!$B:$AC,7,0) -> 46233 | G34: =VLOOKUP($A34,PLAN!$B:$AC,8,0) -> 0103547088 | H34: =VLOOKUP($A34,PLAN!$B:$AC,9,0) -> 260713C01A | I34: =VLOOKUP($A34,PLAN!$B:$AC,10,0) -> 3 | J34: =VLOOKUP($A34,PLAN!$B:$AC,21,0) -> 46220 | K34: =VLOOKUP($A34,PLAN!$B:$AC,22,0) -> M9 | O34: CAG | Q34: =VLOOKUP(A34,PLAN!B:R,17,0) -> 46219
A35: Jul30-05 | B35: =VLOOKUP($A35,PLAN!$B:$AC,3,0) -> 11134149 | C35: =VLOOKUP($A35,PLAN!$B:$AC,4,0) -> 1811910-L-A | D35: =VLOOKUP($A35,PLAN!$B:$AC,5,0) -> HW60SP352P10000 CN | E35: =VLOOKUP($A35,PLAN!$B:$AC,2,0) -> 1001913379 | F35: =VLOOKUP($A35,PLAN!$B:$AC,7,0) -> 46233 | G35: =VLOOKUP($A35,PLAN!$B:$AC,8,0) -> 0103547089 | H35: =VLOOKUP($A35,PLAN!$B:$AC,9,0) -> 260713C02A | I35: =VLOOKUP($A35,PLAN!$B:$AC,10,0) -> 10 | J35: =VLOOKUP($A35,PLAN!$B:$AC,21,0) -> 46220 | K35: =VLOOKUP($A35,PLAN!$B:$AC,22,0) -> M9 | O35: CAG | Q35: =VLOOKUP(A35,PLAN!B:R,17,0) -> 46219
A36: Jul30-06 | B36: =VLOOKUP($A36,PLAN!$B:$AC,3,0) -> 11134146 | C36: =VLOOKUP($A36,PLAN!$B:$AC,4,0) -> 1811907-L-A | D36: =VLOOKUP($A36,PLAN!$B:$AC,5,0) -> HW60SP300P10000 CN | E36: =VLOOKUP($A36,PLAN!$B:$AC,2,0) -> 1001913380 | F36: =VLOOKUP($A36,PLAN!$B:$AC,7,0) -> 46233 | G36: =VLOOKUP($A36,PLAN!$B:$AC,8,0) -> 0103547090 | H36: =VLOOKUP($A36,PLAN!$B:$AC,9,0) -> 260713C03A | I36: =VLOOKUP($A36,PLAN!$B:$AC,10,0) -> 21 | J36: =VLOOKUP($A36,PLAN!$B:$AC,21,0) -> 46220 | K36: =VLOOKUP($A36,PLAN!$B:$AC,22,0) -> M9 | O36: CAG | Q36: =VLOOKUP(A36,PLAN!B:R,17,0) -> 46219
A37: Jul30-07 | B37: =VLOOKUP($A37,PLAN!$B:$AC,3,0) -> 11134150 | C37: =VLOOKUP($A37,PLAN!$B:$AC,4,0) -> 1811911-L-A | D37: =VLOOKUP($A37,PLAN!$B:$AC,5,0) -> HW60SP370P10000 CN | E37: =VLOOKUP($A37,PLAN!$B:$AC,2,0) -> 1001913381 | F37: =VLOOKUP($A37,PLAN!$B:$AC,7,0) -> 46233 | G37: =VLOOKUP($A37,PLAN!$B:$AC,8,0) -> 0103547091 | H37: =VLOOKUP($A37,PLAN!$B:$AC,9,0) -> 260713C04A | I37: =VLOOKUP($A37,PLAN!$B:$AC,10,0) -> 290 | J37: =VLOOKUP($A37,PLAN!$B:$AC,21,0) -> 46220 | K37: =VLOOKUP($A37,PLAN!$B:$AC,22,0) -> M9 | O37: CAG | Q37: =VLOOKUP(A37,PLAN!B:R,17,0) -> 46219
A38: Jul30-08 | B38: =VLOOKUP($A38,PLAN!$B:$AC,3,0) -> 11134148 | C38: =VLOOKUP($A38,PLAN!$B:$AC,4,0) -> 1811909-L-A | D38: =VLOOKUP($A38,PLAN!$B:$AC,5,0) -> HW60SP350P10000 CN | E38: =VLOOKUP($A38,PLAN!$B:$AC,2,0) -> 1001913382 | F38: =VLOOKUP($A38,PLAN!$B:$AC,7,0) -> 46233 | G38: =VLOOKUP($A38,PLAN!$B:$AC,8,0) -> 0103547092 | H38: =VLOOKUP($A38,PLAN!$B:$AC,9,0) -> 260713C05A | I38: =VLOOKUP($A38,PLAN!$B:$AC,10,0) -> 400 | J38: =VLOOKUP($A38,PLAN!$B:$AC,21,0) -> 46220 | K38: =VLOOKUP($A38,PLAN!$B:$AC,22,0) -> M9 | O38: CAG | Q38: =VLOOKUP(A38,PLAN!B:R,17,0) -> 46219
A39: Jul30-09 | B39: =VLOOKUP($A39,PLAN!$B:$AC,3,0) -> 11134129 | C39: =VLOOKUP($A39,PLAN!$B:$AC,4,0) -> 1811861-J-A | D39: =VLOOKUP($A39,PLAN!$B:$AC,5,0) -> HW60AL070P10000 CN | E39: =VLOOKUP($A39,PLAN!$B:$AC,2,0) -> 1001913383 | F39: =VLOOKUP($A39,PLAN!$B:$AC,7,0) -> 46233 | G39: =VLOOKUP($A39,PLAN!$B:$AC,8,0) -> 0103547093 | H39: =VLOOKUP($A39,PLAN!$B:$AC,9,0) -> 260713C06A | I39: =VLOOKUP($A39,PLAN!$B:$AC,10,0) -> 40 | J39: =VLOOKUP($A39,PLAN!$B:$AC,21,0) -> 46220 | K39: =VLOOKUP($A39,PLAN!$B:$AC,22,0) -> M10 | O39: CAG | Q39: =VLOOKUP(A39,PLAN!B:R,17,0) -> 46219
A40: Jul30-10 | B40: =VLOOKUP($A40,PLAN!$B:$AC,3,0) -> 11134131 | C40: =VLOOKUP($A40,PLAN!$B:$AC,4,0) -> 1811863-J-A | D40: =VLOOKUP($A40,PLAN!$B:$AC,5,0) -> HW60AL100P10000 CN | E40: =VLOOKUP($A40,PLAN!$B:$AC,2,0) -> 1001913384 | F40: =VLOOKUP($A40,PLAN!$B:$AC,7,0) -> 46233 | G40: =VLOOKUP($A40,PLAN!$B:$AC,8,0) -> 0103547094 | H40: =VLOOKUP($A40,PLAN!$B:$AC,9,0) -> 260713C07A | I40: =VLOOKUP($A40,PLAN!$B:$AC,10,0) -> 96 | J40: =VLOOKUP($A40,PLAN!$B:$AC,21,0) -> 46220 | K40: =VLOOKUP($A40,PLAN!$B:$AC,22,0) -> M10 | O40: CAG | Q40: =VLOOKUP(A40,PLAN!B:R,17,0) -> 46219
A41: Jul30-11 | B41: =VLOOKUP($A41,PLAN!$B:$AC,3,0) -> 11134120 | C41: =VLOOKUP($A41,PLAN!$B:$AC,4,0) -> 1811831-J-A | D41: =VLOOKUP($A41,PLAN!$B:$AC,5,0) -> HW60JL400P10000 CN | E41: =VLOOKUP($A41,PLAN!$B:$AC,2,0) -> 1001913385 | F41: =VLOOKUP($A41,PLAN!$B:$AC,7,0) -> 46233 | G41: =VLOOKUP($A41,PLAN!$B:$AC,8,0) -> 0103547095 | H41: =VLOOKUP($A41,PLAN!$B:$AC,9,0) -> 260713C08A | I41: =VLOOKUP($A41,PLAN!$B:$AC,10,0) -> 380 | J41: =VLOOKUP($A41,PLAN!$B:$AC,21,0) -> 46220 | K41: =VLOOKUP($A41,PLAN!$B:$AC,22,0) -> M10 | O41: CAG | Q41: =VLOOKUP(A41,PLAN!B:R,17,0) -> 46219
A42: Jul30-12 | B42: =VLOOKUP($A42,PLAN!$B:$AC,3,0) -> 11134117 | C42: =VLOOKUP($A42,PLAN!$B:$AC,4,0) -> 1811827-J-A | D42: =VLOOKUP($A42,PLAN!$B:$AC,5,0) -> HW60JL350P10000 CN | E42: =VLOOKUP($A42,PLAN!$B:$AC,2,0) -> 1001913386 | F42: =VLOOKUP($A42,PLAN!$B:$AC,7,0) -> 46233 | G42: =VLOOKUP($A42,PLAN!$B:$AC,8,0) -> 0103547096 | H42: =VLOOKUP($A42,PLAN!$B:$AC,9,0) -> 260713C09A | I42: =VLOOKUP($A42,PLAN!$B:$AC,10,0) -> 324 | J42: =VLOOKUP($A42,PLAN!$B:$AC,21,0) -> 46220 | K42: =VLOOKUP($A42,PLAN!$B:$AC,22,0) -> M10 | O42: CAG | Q42: =VLOOKUP(A42,PLAN!B:R,17,0) -> 46219
A43: Jul31-01 | B43: =VLOOKUP($A43,PLAN!$B:$AC,3,0) -> 11134148 | C43: =VLOOKUP($A43,PLAN!$B:$AC,4,0) -> 1811909-L-A | D43: =VLOOKUP($A43,PLAN!$B:$AC,5,0) -> HW60SP350P10000 CN | E43: =VLOOKUP($A43,PLAN!$B:$AC,2,0) -> 1001913433 | F43: =VLOOKUP($A43,PLAN!$B:$AC,7,0) -> 46234 | G43: =VLOOKUP($A43,PLAN!$B:$AC,8,0) -> 0103547143 | H43: =VLOOKUP($A43,PLAN!$B:$AC,9,0) -> 260713C56A | I43: =VLOOKUP($A43,PLAN!$B:$AC,10,0) -> 486 | J43: =VLOOKUP($A43,PLAN!$B:$AC,21,0) -> 46221 | K43: =VLOOKUP($A43,PLAN!$B:$AC,22,0) -> M10 | O43: CAG | Q43: =VLOOKUP(A43,PLAN!B:R,17,0) -> 46220
A44: Jul31-02 | B44: =VLOOKUP($A44,PLAN!$B:$AC,3,0) -> 11134148 | C44: =VLOOKUP($A44,PLAN!$B:$AC,4,0) -> 1811909-L-A | D44: =VLOOKUP($A44,PLAN!$B:$AC,5,0) -> HW60SP350P10000 CN | E44: =VLOOKUP($A44,PLAN!$B:$AC,2,0) -> 1001914294 | F44: =VLOOKUP($A44,PLAN!$B:$AC,7,0) -> 46234 | G44: =VLOOKUP($A44,PLAN!$B:$AC,8,0) -> 0103548549 | H44: =VLOOKUP($A44,PLAN!$B:$AC,9,0) -> 260616C17B | I44: =VLOOKUP($A44,PLAN!$B:$AC,10,0) -> 1 | J44: =VLOOKUP($A44,PLAN!$B:$AC,21,0) -> 46221 | K44: =VLOOKUP($A44,PLAN!$B:$AC,22,0) -> M10 | O44: CAG | Q44: =VLOOKUP(A44,PLAN!B:R,17,0) -> 46220
A45: Aug03-01 | B45: =VLOOKUP($A45,PLAN!$B:$AC,3,0) -> 11134146 | C45: =VLOOKUP($A45,PLAN!$B:$AC,4,0) -> 1811907-L-A | D45: =VLOOKUP($A45,PLAN!$B:$AC,5,0) -> HW60SP300P10000 CN | E45: =VLOOKUP($A45,PLAN!$B:$AC,2,0) -> 1001916295 | F45: =VLOOKUP($A45,PLAN!$B:$AC,7,0) -> 46237 | G45: =VLOOKUP($A45,PLAN!$B:$AC,8,0) -> 0103552270 | H45: =VLOOKUP($A45,PLAN!$B:$AC,9,0) -> 260715C44A | I45: =VLOOKUP($A45,PLAN!$B:$AC,10,0) -> 720 | J45: =VLOOKUP($A45,PLAN!$B:$AC,21,0) -> 46223 | K45: =VLOOKUP($A45,PLAN!$B:$AC,22,0) -> M10 | O45: CAG | Q45: =VLOOKUP(A45,PLAN!B:R,17,0) -> 46221
... A80: Aug13-04 | B80: =VLOOKUP($A80,PLAN!$B:$AC,3,0) -> 11134146 | C80: =VLOOKUP($A80,PLAN!$B:$AC,4,0) -> 1811907-L-A | D80: =VLOOKUP($A80,PLAN!$B:$AC,5,0) -> HW60SP300P10000 CN | E80: =VLOOKUP($A80,PLAN!$B:$AC,2,0) -> 1001921248 | F80: =VLOOKUP($A80,PLAN!$B:$AC,7,0) -> 46247 | G80: =VLOOKUP($A80,PLAN!$B:$AC,8,0) -> 0103562352 | H80: =VLOOKUP($A80,PLAN!$B:$AC,9,0) -> 260720C64A | I80: =VLOOKUP($A80,PLAN!$B:$AC,10,0) -> 720 | J80: =VLOOKUP($A80,PLAN!$B:$AC,21,0) -> 46230 | K80: =VLOOKUP($A80,PLAN!$B:$AC,22,0) -> M10 | O80: CAG | Q80: =VLOOKUP(A80,PLAN!B:R,17,0) -> 46227
A81: Bio-1 | B81: =VLOOKUP($A81,PLAN!$B:$AC,3,0) -> 11107911 | C81: =VLOOKUP($A81,PLAN!$B:$AC,4,0) -> 2511509-001 | D81: =VLOOKUP($A81,PLAN!$B:$AC,5,0) -> CROSSRIDGE 6Fr 100cm_Kit | E81: =VLOOKUP($A81,PLAN!$B:$AC,2,0) -> 2000127633 | F81: =VLOOKUP($A81,PLAN!$B:$AC,7,0) -> 46234 | G81: =VLOOKUP($A81,PLAN!$B:$AC,8,0) -> 0103565388 | H81: =VLOOKUP($A81,PLAN!$B:$AC,9,0) -> 260720Y01A | I81: =VLOOKUP($A81,PLAN!$B:$AC,10,0) -> 20 | J81: =VLOOKUP($A81,PLAN!$B:$AC,21,0) -> 46228 | K81: =VLOOKUP($A81,PLAN!$B:$AC,22,0) -> TEST | O81: CAG | Q81: Bio-1
A82: Bio-2 | B82: =VLOOKUP($A82,PLAN!$B:$AC,3,0) -> 11107911 | C82: =VLOOKUP($A82,PLAN!$B:$AC,4,0) -> 2511509-001 | D82: =VLOOKUP($A82,PLAN!$B:$AC,5,0) -> CROSSRIDGE 6Fr 100cm_Kit | E82: =VLOOKUP($A82,PLAN!$B:$AC,2,0) -> 2000127634 | F82: =VLOOKUP($A82,PLAN!$B:$AC,7,0) -> 46234 | G82: =VLOOKUP($A82,PLAN!$B:$AC,8,0) -> 0103565391 | H82: =VLOOKUP($A82,PLAN!$B:$AC,9,0) -> 260720Y02A | I82: =VLOOKUP($A82,PLAN!$B:$AC,10,0) -> 3 | J82: =VLOOKUP($A82,PLAN!$B:$AC,21,0) -> N/A | K82: =VLOOKUP($A82,PLAN!$B:$AC,22,0) -> TEST | O82: CAG | Q82: Bio-1
A83: Bio-3 | B83: =VLOOKUP($A83,PLAN!$B:$AC,3,0) -> 11107911 | C83: =VLOOKUP($A83,PLAN!$B:$AC,4,0) -> 2511509-001 | D83: =VLOOKUP($A83,PLAN!$B:$AC,5,0) -> CROSSRIDGE 6Fr 100cm_Kit | E83: =VLOOKUP($A83,PLAN!$B:$AC,2,0) -> 2000127635 | F83: =VLOOKUP($A83,PLAN!$B:$AC,7,0) -> 46234 | G83: =VLOOKUP($A83,PLAN!$B:$AC,8,0) -> 0103565392 | H83: =VLOOKUP($A83,PLAN!$B:$AC,9,0) -> 260720Y03A | I83: =VLOOKUP($A83,PLAN!$B:$AC,10,0) -> 5 | J83: =VLOOKUP($A83,PLAN!$B:$AC,21,0) -> 46228 | K83: =VLOOKUP($A83,PLAN!$B:$AC,22,0) -> TEST | O83: CAG | Q83: Bio-1
A84: Bio-4 | B84: =VLOOKUP($A84,PLAN!$B:$AC,3,0) -> 11107911 | C84: =VLOOKUP($A84,PLAN!$B:$AC,4,0) -> 2511509-001 | D84: =VLOOKUP($A84,PLAN!$B:$AC,5,0) -> CROSSRIDGE 6Fr 100cm_Kit | E84: =VLOOKUP($A84,PLAN!$B:$AC,2,0) -> 2000127636 | F84: =VLOOKUP($A84,PLAN!$B:$AC,7,0) -> 46234 | G84: =VLOOKUP($A84,PLAN!$B:$AC,8,0) -> 0103565394 | H84: =VLOOKUP($A84,PLAN!$B:$AC,9,0) -> 260720Y04A | I84: =VLOOKUP($A84,PLAN!$B:$AC,10,0) -> 5 | J84: =VLOOKUP($A84,PLAN!$B:$AC,21,0) -> 46228 | K84: =VLOOKUP($A84,PLAN!$B:$AC,22,0) -> TEST | O84: CAG | Q84: Bio-1
...

Sheet seal (2)
C1: DIV/ SECTION | E1: PRODUCTION PLAN FOR STERILIZE (KẾ HOẠCH SẢN XUẤT CỦA PHÒNG STERILIZE) | W1: F- 5740 Ver:2
C2: GPC/ Order control | W2: Page: / 3
C4: Plan date: | E4: 46258
C5: No | D5: Material | E5: Drawing list No | F5: Item name/ Description | G5: Plnd order / PO | H5: Scheduled Finish Date | I5: Internal Lot (SAP Lot) | J5: External Lot (Hanoi Lot) | K5: Q`ty | L5: Destination | M5: Test Endotoxin ( pcs) | N5: Test Particle ( pcs) | O5: Wip request infomation | U5: Sterilize | W5: Start date (Sealing) | Y5: Remark
O6: Item code Type C | P6: Material Type C | Q6: Internal Lot (SAP Lot) | R6: External Lot | S6: Q`ty | T6: Sheft | U6: Date | V6: No | W6: Date | X6: Time
C7: =AA7 -> Aug15-01 | D7: =IFERROR(VLOOKUP($AA7,PLAN!$B:$AA,3,0),"") -> 12129248 | E7: =IFERROR(VLOOKUP($AA7,PLAN!$B:$AA,4,0),"") -> PR2145021-0-A | F7: =IFERROR(VLOOKUP($AA7,PLAN!$B:$AA,5,0),"") -> 2009051 Masters HF CN | G7: =IFERROR(VLOOKUP($AA7,PLAN!$B:$AA,2,0),"") -> 1001897397 | H7: =IFERROR(VLOOKUP($AA7,PLAN!$B:$AA,7,0),"") -> 46249 | I7: =IFERROR(VLOOKUP($AA7,PLAN!$B:$AA,8,0),"") -> 0103516476 | J7: =IFERROR(VLOOKUP($AA7,PLAN!$B:$AA,9,0),"") -> 260625K01A | K7: =IFERROR(VLOOKUP($AA7,PLAN!$B:$AA,10,0),"") -> 3306 | L7: =IFERROR(VLOOKUP($AA7,PLAN!$B:$AA,15,0),"") -> CHINA | M7: =IFERROR(VLOOKUP($AA7,PLAN!$B:$AA,18,0),"") -> 3 | N7: =IFERROR(VLOOKUP($AA7,PLAN!$B:$AA,19,0),"") -> 0 | O7: =IFERROR(VLOOKUP($AA7,PLAN!$B:$AA,12,0),"") -> PR19SR002-0-D | P7: =IFERROR(VLOOKUP($AA7,PLAN!$B:$AA,11,0),"") -> 12003986 | Q7: 0103383152 | R7: JP26424A3 | S7: 318 | U7: =IFERROR(VLOOKUP($AA7,PLAN!$B:$AA,21,0),"") -> 46206 | V7: =IFERROR(VLOOKUP($AA7,PLAN!$B:$AA,22,0),"") -> M8 | AA7: Aug15-01 | AB7: =VLOOKUP(AA7,PLAN!B:V,20,0) -> 46206
C8: =AA8 -> 0 | D8: =IFERROR(VLOOKUP($AA8,PLAN!$B:$AA,3,0),"") | E8: =IFERROR(VLOOKUP($AA8,PLAN!$B:$AA,4,0),"") | F8: =IFERROR(VLOOKUP($AA8,PLAN!$B:$AA,5,0),"") | G8: =IFERROR(VLOOKUP($AA8,PLAN!$B:$AA,2,0),"") | H8: =IFERROR(VLOOKUP($AA8,PLAN!$B:$AA,7,0),"") | I8: =IFERROR(VLOOKUP($AA8,PLAN!$B:$AA,8,0),"") | J8: =IFERROR(VLOOKUP($AA8,PLAN!$B:$AA,9,0),"") | K8: =IFERROR(VLOOKUP($AA8,PLAN!$B:$AA,10,0),"") | L8: =IFERROR(VLOOKUP($AA8,PLAN!$B:$AA,15,0),"") | M8: =IFERROR(VLOOKUP($AA8,PLAN!$B:$AA,18,0),"") | N8: =IFERROR(VLOOKUP($AA8,PLAN!$B:$AA,19,0),"") | O8: =IFERROR(VLOOKUP($AA8,PLAN!$B:$AA,12,0),"") | P8: =IFERROR(VLOOKUP($AA8,PLAN!$B:$AA,11,0),"") | Q8: 0103383153 | R8: JP26424A4 | S8: 1000 | U8: =IFERROR(VLOOKUP($AA8,PLAN!$B:$AA,21,0),"") | V8: =IFERROR(VLOOKUP($AA8,PLAN!$B:$AA,22,0),"") | AB8: 46206
C9: =AA9 -> 0 | D9: =IFERROR(VLOOKUP($AA9,PLAN!$B:$AA,3,0),"") | E9: =IFERROR(VLOOKUP($AA9,PLAN!$B:$AA,4,0),"") | F9: =IFERROR(VLOOKUP($AA9,PLAN!$B:$AA,5,0),"") | G9: =IFERROR(VLOOKUP($AA9,PLAN!$B:$AA,2,0),"") | H9: =IFERROR(VLOOKUP($AA9,PLAN!$B:$AA,7,0),"") | I9: =IFERROR(VLOOKUP($AA9,PLAN!$B:$AA,8,0),"") | J9: =IFERROR(VLOOKUP($AA9,PLAN!$B:$AA,9,0),"") | K9: =IFERROR(VLOOKUP($AA9,PLAN!$B:$AA,10,0),"") | L9: =IFERROR(VLOOKUP($AA9,PLAN!$B:$AA,15,0),"") | M9: =IFERROR(VLOOKUP($AA9,PLAN!$B:$AA,18,0),"") | N9: =IFERROR(VLOOKUP($AA9,PLAN!$B:$AA,19,0),"") | O9: =IFERROR(VLOOKUP($AA9,PLAN!$B:$AA,12,0),"") | P9: =IFERROR(VLOOKUP($AA9,PLAN!$B:$AA,11,0),"") | Q9: 0103457714 | R9: JP26528E4 | S9: 1000 | U9: =IFERROR(VLOOKUP($AA9,PLAN!$B:$AA,21,0),"") | V9: =IFERROR(VLOOKUP($AA9,PLAN!$B:$AA,22,0),"") | AB9: 46206
C10: =AA10 -> 0 | D10: =IFERROR(VLOOKUP($AA10,PLAN!$B:$AA,3,0),"") | E10: =IFERROR(VLOOKUP($AA10,PLAN!$B:$AA,4,0),"") | F10: =IFERROR(VLOOKUP($AA10,PLAN!$B:$AA,5,0),"") | G10: =IFERROR(VLOOKUP($AA10,PLAN!$B:$AA,2,0),"") | H10: =IFERROR(VLOOKUP($AA10,PLAN!$B:$AA,7,0),"") | I10: =IFERROR(VLOOKUP($AA10,PLAN!$B:$AA,8,0),"") | J10: =IFERROR(VLOOKUP($AA10,PLAN!$B:$AA,9,0),"") | K10: =IFERROR(VLOOKUP($AA10,PLAN!$B:$AA,10,0),"") | L10: =IFERROR(VLOOKUP($AA10,PLAN!$B:$AA,15,0),"") | M10: =IFERROR(VLOOKUP($AA10,PLAN!$B:$AA,18,0),"") | N10: =IFERROR(VLOOKUP($AA10,PLAN!$B:$AA,19,0),"") | O10: =IFERROR(VLOOKUP($AA10,PLAN!$B:$AA,12,0),"") | P10: =IFERROR(VLOOKUP($AA10,PLAN!$B:$AA,11,0),"") | Q10: 0103457715 | R10: JP26528E5 | S10: =K7-S7-S8-S9 -> 988 | U10: =IFERROR(VLOOKUP($AA10,PLAN!$B:$AA,21,0),"") | V10: =IFERROR(VLOOKUP($AA10,PLAN!$B:$AA,22,0),"") | AB10: 46206
C11: =AA11 -> Jul29-02 | D11: =IFERROR(VLOOKUP($AA11,PLAN!$B:$AA,3,0),"") -> 11134248 | E11: =IFERROR(VLOOKUP($AA11,PLAN!$B:$AA,4,0),"") -> 2041189-D-A | F11: =IFERROR(VLOOKUP($AA11,PLAN!$B:$AA,5,0),"") -> CSR135-26P CN | G11: =IFERROR(VLOOKUP($AA11,PLAN!$B:$AA,2,0),"") -> 1001910173 | H11: =IFERROR(VLOOKUP($AA11,PLAN!$B:$AA,7,0),"") -> 46232 | I11: =IFERROR(VLOOKUP($AA11,PLAN!$B:$AA,8,0),"") -> 0103541259 | J11: =IFERROR(VLOOKUP($AA11,PLAN!$B:$AA,9,0),"") -> 260709K24A | K11: =IFERROR(VLOOKUP($AA11,PLAN!$B:$AA,10,0),"") -> 626 | L11: =IFERROR(VLOOKUP($AA11,PLAN!$B:$AA,15,0),"") -> CHINA | M11: =IFERROR(VLOOKUP($AA11,PLAN!$B:$AA,18,0),"") -> 3 | N11: =IFERROR(VLOOKUP($AA11,PLAN!$B:$AA,19,0),"") -> 3 | O11: =IFERROR(VLOOKUP($AA11,PLAN!$B:$AA,12,0),"") -> 2342019-A-C-CN | P11: =IFERROR(VLOOKUP($AA11,PLAN!$B:$AA,11,0),"") -> 12139931 | Q11: 0103502481 | R11: JF26618A7 | S11: 90 | U11: =IFERROR(VLOOKUP($AA11,PLAN!$B:$AA,21,0),"") -> 46218 | V11: =IFERROR(VLOOKUP($AA11,PLAN!$B:$AA,22,0),"") -> M8 | AA11: Jul29-02 | AB11: =VLOOKUP(AA11,PLAN!B:V,20,0) -> 46218
Q12: 0103502482 | R12: JF26618A8 | S12: 306 | AB12: 46218
Q13: 0103502483 | R13: JF26618A9 | S13: =K11-S11-S12 -> 230 | AB13: 46218
