Workbook
Name eratet: '[1]PLAN PTCA'!#REF!
Name eratet: #REF!
Name eratet: #REF!

Sheet PLAN
B1: PLAN STER - PTCA | I1: =SUBTOTAL(9,I3:I2249) -> 624591 | M1: =SUBTOTAL(9,M3:M2249) -> 627733 | AE1: =SUBTOTAL(9,AE3:AE2249) -> 280022
A2: PO No. | B2: TT | C2: Material No Type C | D2: Item Code Type C | E2: PldOrd | F2: Material No | G2: Item code | H2: Item name | I2: Q'ty | J2: Complete Date | K2: Internal Lot | L2: External Lot Ster | M2: Q'ty Input | N2: QA test | O2: KEEP | P2: Destination | Q2: Label | R2: Bioburden | S2: Seal | T2: Ster | U2: MẺ | V2: Phase | W2: BOXING | X2: Test Endotoxin ( pcs) | Y2: Test Particle ( pcs) | Z2: Label | AA2: Seal | AB2: Boxing | AC2: ETD | AD2: Family | AE2: WH | AF2: PROCESS | AG2: ngày lưu kho | AI2: MẺ | AJ2: 1 | AK2: Địa Chỉ Label QR code | AM2: 1 | AN2: ＡＩＨ A | AO2: ＡＩＨ A | AP2: ＡＩＨ C | AQ2: ＡＩＨ D
A3: PT-H2607-PT-029 | B3: Jul22-11 | C3: 12111088 | D3: 1932090-A-C | E3: 1001907448 | F3: 11111223 | G3: 1631042-F-A | H3: AMS-180-1445 JP | I3: 380 | J3: 46236 | K3: 0103536427 | L3: 260707A14A | M3: 380 | N3: 0 | O3: 0 | P3: Japan | Q3: 46217 | R3: 0 | S3: 46238 | T3: 46238 | U3: M7 | V3: CAG | X3: 0 | Y3: 0 | Z3: =IFERROR(VLOOKUP(H3,[2]New!$B:$G,3,0),)*I3/60 -> 266 | AA3: =IFERROR(VLOOKUP(H3,[2]New!$B:$G,4,0),)*I3/60 -> 1038.6667 | AB3: =IFERROR(VLOOKUP(H3,[2]New!$B:$G,6,0),)*I3/60 -> 931 | AC3: 46251 | AD3: =IFERROR(VLOOKUP(H3,[3]Sheet1!$E:$H,4,0),) -> 0 | AE3: 380 | AF3: FINISH | AG3: 0 | AH3: 0 | AI3: M7 | AL3: AVPE-7634 | AM3: AVPE-7634 | AN3: 3 | AO3: 3 | AP3: 2 | AQ3: 2 | AR3: 06.Aug.26
A4: PT-H2605-PC-002-2 | B4: Jul23-04 | C4: 12125012 | D4: 2332200-0-C-CN | E4: 1001907463 | F4: 11134237 | G4: 1436196-Q-A | H4: AHW14R004S CN | I4: 2370 | J4: 46226 | K4: 0103536442 | L4: 260707A29A | M4: 2389 | N4: 16 | O4: 0 | P4: China | Q4: 46216 | R4: 0 | S4: 46217 | T4: 46217 | U4: M3 | V4: F3 | X4: 3 | Y4: 0 | Z4: =IFERROR(VLOOKUP(H4,[2]New!$B:$G,3,0),)*I4/60 -> 1674.8 | AA4: =IFERROR(VLOOKUP(H4,[2]New!$B:$G,4,0),)*I4/60 -> 4657.05 | AB4: =IFERROR(VLOOKUP(H4,[2]New!$B:$G,6,0),)*I4/60 -> 2291 | AC4: =VLOOKUP(A4,'[4]PO PTCA (2)'!$A:$L,12,0) -> 46238 | AD4: =IFERROR(VLOOKUP(H4,[3]Sheet1!$E:$H,4,0),) -> B | AE4: 2370 | AF4: FINISH | AG4: 3 | AH4: 19 | AI4: M3-1 | AL4: AVPE-8631 | AM4: #N/A | AN4: 3 | AO4: 3 | AP4: 2 | AQ4: 2
A5: PT-H2606-PD-194 | B5: Jul24-21 | C5: 12111412 | D5: 1832240-B-CK | E5: 1001912027 | F5: 11126730 | G5: 1436075-J-AK | H5: AGH143092 Q NOCE | I5: 25 | J5: 46227 | K5: 0103544281 | L5: 260709A17A | M5: 25 | N5: 0 | O5: 0 | P5: Oversea | Q5: 46227 | R5: 0 | S5: 46230 | T5: 46230 | U5: M7 | V5: F2 | X5: 0 | Y5: 0 | Z5: =IFERROR(VLOOKUP(H5,[2]New!$B:$G,3,0),)*I5/60 -> 0 | AA5: =IFERROR(VLOOKUP(H5,[2]New!$B:$G,4,0),)*I5/60 -> 0 | AB5: =IFERROR(VLOOKUP(H5,[2]New!$B:$G,6,0),)*I5/60 -> 0 | AC5: =VLOOKUP(A5,'[4]PO PTCA (2)'!$A:$L,12,0) -> 46238 | AD5: =IFERROR(VLOOKUP(H5,[3]Sheet1!$E:$H,4,0),) -> 0 | AE5: 25 | AF5: FINISH | AG5: 0 | AH5: 0 | AI5: M7-1 | AL5: AVPE-9952 | AM5: AVPE-9952 | AN5: 2 | AO5: 2 | AP5: 2 | AQ5: ×
A6: PT-H2606-PD-194 | B6: Jul24-22 | C6: 12111412 | D6: 1832240-B-CK | E6: 1001912028 | F6: 11126730 | G6: 1436075-J-AK | H6: AGH143092 Q NO CE | I6: 25 | J6: 46227 | K6: 0103544282 | L6: 260709A18A | M6: 25 | N6: 0 | O6: 0 | P6: Oversea | Q6: 46227 | R6: 0 | S6: 46230 | T6: 46230 | U6: M7 | V6: F2 | X6: 0 | Y6: 0 | Z6: =IFERROR(VLOOKUP(H6,[2]New!$B:$G,3,0),)*I6/60 -> 0 | AA6: =IFERROR(VLOOKUP(H6,[2]New!$B:$G,4,0),)*I6/60 -> 0 | AB6: =IFERROR(VLOOKUP(H6,[2]New!$B:$G,6,0),)*I6/60 -> 0 | AC6: =VLOOKUP(A6,'[4]PO PTCA (2)'!$A:$L,12,0) -> 46238 | AD6: =IFERROR(VLOOKUP(H6,[3]Sheet1!$E:$H,4,0),) -> 0 | AE6: 25 | AF6: FINISH | AG6: 0 | AH6: 0 | AI6: M7-1 | AL6: AVPE-9952 | AM6: AVPE-9952 | AN6: 2 | AO6: 2 | AP6: 2 | AQ6: ×
A7: IPC-2605004 | B7: Jul24-40 | C7: 12125021 | D7: 2332447-0-C-CN | E7: 1001912046 | F7: 11133759 | G7: 1456045-Q-A | H7: STM180-14S CN | I7: 5 | J7: 46227 | K7: 0103544302 | L7: 260709A36A | M7: 5 | N7: 5 | O7: 0 | P7: China | Q7: 46217 | R7: 0 | S7: 46218 | T7: 46218 | U7: M5 | V7: F3 | X7: 0 | Y7: 0 | Z7: =IFERROR(VLOOKUP(H7,[2]New!$B:$G,3,0),)*I7/60 -> 4.5583333 | AA7: =IFERROR(VLOOKUP(H7,[2]New!$B:$G,4,0),)*I7/60 -> 13.908333 | AB7: =IFERROR(VLOOKUP(H7,[2]New!$B:$G,6,0),)*I7/60 -> 12.791667 | AC7: TEST | AD7: =IFERROR(VLOOKUP(H7,[3]Sheet1!$E:$H,4,0),) -> D | AE7: 5 | AF7: FINISH | AG7: 12 | AH7: 0 | AI7: M5-2 | AK7: IPC-2605004 | AL7: AVPE-6724 | AM7: #N/A | AN7: 3 | AO7: 3 | AP7: 2 | AQ7: 2
A8: IPC-2605004 | B8: Jul24-41 | C8: 12125021 | D8: 2332447-0-C-CN | E8: 1001912047 | F8: 11133759 | G8: 1456045-Q-A | H8: STM180-14S CN | I8: 5 | J8: 46227 | K8: 0103544305 | L8: 260709A37A | M8: 5 | N8: 5 | O8: 0 | P8: China | Q8: 46217 | R8: 0 | S8: 46218 | T8: 46218 | U8: M5 | V8: F3 | X8: 0 | Y8: 0 | Z8: =IFERROR(VLOOKUP(H8,[2]New!$B:$G,3,0),)*I8/60 -> 4.5583333 | AA8: =IFERROR(VLOOKUP(H8,[2]New!$B:$G,4,0),)*I8/60 -> 13.908333 | AB8: =IFERROR(VLOOKUP(H8,[2]New!$B:$G,6,0),)*I8/60 -> 12.791667 | AC8: TEST | AD8: =IFERROR(VLOOKUP(H8,[3]Sheet1!$E:$H,4,0),) -> D | AE8: 5 | AF8: FINISH | AG8: 12 | AH8: 0 | AI8: M5-2 | AK8: IPC-2605004 | AL8: AVPE-6724 | AM8: #N/A | AN8: 3 | AO8: 3 | AP8: 2 | AQ8: 2
A9: IPC-2605004 | B9: Jul24-42 | C9: 12125021 | D9: 2332447-0-C-CN | E9: 1001912048 | F9: 11133759 | G9: 1456045-Q-A | H9: STM180-14S CN | I9: 5 | J9: 46227 | K9: 0103544306 | L9: 260709A38A | M9: 5 | N9: 5 | O9: 0 | P9: China | Q9: 46217 | R9: 0 | S9: 46218 | T9: 46218 | U9: M5 | V9: F3 | X9: 0 | Y9: 0 | Z9: =IFERROR(VLOOKUP(H9,[2]New!$B:$G,3,0),)*I9/60 -> 4.5583333 | AA9: =IFERROR(VLOOKUP(H9,[2]New!$B:$G,4,0),)*I9/60 -> 13.908333 | AB9: =IFERROR(VLOOKUP(H9,[2]New!$B:$G,6,0),)*I9/60 -> 12.791667 | AC9: TEST | AD9: =IFERROR(VLOOKUP(H9,[3]Sheet1!$E:$H,4,0),) -> D | AE9: 5 | AF9: FINISH | AG9: 12 | AH9: 0 | AI9: M5-2 | AK9: IPC-2605004 | AL9: AVPE-6724 | AM9: #N/A | AN9: 3 | AO9: 3 | AP9: 2 | AQ9: 2
A10: IPC-2605004 | B10: Jul24-43 | C10: 12125021 | D10: 2332447-0-C-CN | E10: 1001912049 | F10: 11133759 | G10: 1456045-Q-A | H10: STM180-14S CN | I10: 5 | J10: 46227 | K10: 0103544307 | L10: 260709A39A | M10: 5 | N10: 5 | O10: 0 | P10: China | Q10: 46217 | R10: 0 | S10: 46218 | T10: 46218 | U10: M5 | V10: F3 | X10: 0 | Y10: 0 | Z10: =IFERROR(VLOOKUP(H10,[2]New!$B:$G,3,0),)*I10/60 -> 4.5583333 | AA10: =IFERROR(VLOOKUP(H10,[2]New!$B:$G,4,0),)*I10/60 -> 13.908333 | AB10: =IFERROR(VLOOKUP(H10,[2]New!$B:$G,6,0),)*I10/60 -> 12.791667 | AC10: TEST | AD10: =IFERROR(VLOOKUP(H10,[3]Sheet1!$E:$H,4,0),) -> D | AE10: 5 | AF10: FINISH | AG10: 12 | AH10: 0 | AI10: M5-2 | AK10: IPC-2605004 | AL10: AVPE-6724 | AM10: #N/A | AN10: 3 | AO10: 3 | AP10: 2 | AQ10: 2
A11: IPC-2605004 | B11: Jul24-44 | C11: 12125021 | D11: 2332447-0-C-CN | E11: 1001912051 | F11: 11133759 | G11: 1456045-Q-A | H11: STM180-14S CN | I11: 5 | J11: 46227 | K11: 0103544308 | L11: 260709A40A | M11: 5 | N11: 5 | O11: 0 | P11: China | Q11: 46217 | R11: 0 | S11: 46218 | T11: 46218 | U11: M5 | V11: F3 | X11: 0 | Y11: 0 | Z11: =IFERROR(VLOOKUP(H11,[2]New!$B:$G,3,0),)*I11/60 -> 4.5583333 | AA11: =IFERROR(VLOOKUP(H11,[2]New!$B:$G,4,0),)*I11/60 -> 13.908333 | AB11: =IFERROR(VLOOKUP(H11,[2]New!$B:$G,6,0),)*I11/60 -> 12.791667 | AC11: TEST | AD11: =IFERROR(VLOOKUP(H11,[3]Sheet1!$E:$H,4,0),) -> D | AE11: 5 | AF11: FINISH | AG11: 12 | AH11: 0 | AI11: M5-2 | AK11: IPC-2605004 | AL11: AVPE-6724 | AM11: #N/A | AN11: 3 | AO11: 3 | AP11: 2 | AQ11: 2
A12: IPC-2605004 | B12: Jul24-45 | C12: 12125021 | D12: 2332447-0-C-CN | E12: 1001912052 | F12: 11133759 | G12: 1456045-Q-A | H12: STM180-14S CN | I12: 5 | J12: 46227 | K12: 0103544309 | L12: 260709A41A | M12: 5 | N12: 5 | O12: 0 | P12: China | Q12: 46217 | R12: 0 | S12: 46218 | T12: 46218 | U12: M5 | V12: F3 | X12: 0 | Y12: 0 | Z12: =IFERROR(VLOOKUP(H12,[2]New!$B:$G,3,0),)*I12/60 -> 4.5583333 | AA12: =IFERROR(VLOOKUP(H12,[2]New!$B:$G,4,0),)*I12/60 -> 13.908333 | AB12: =IFERROR(VLOOKUP(H12,[2]New!$B:$G,6,0),)*I12/60 -> 12.791667 | AC12: TEST | AD12: =IFERROR(VLOOKUP(H12,[3]Sheet1!$E:$H,4,0),) -> D | AE12: 5 | AF12: FINISH | AG12: 12 | AH12: 0 | AI12: M5-2 | AK12: IPC-2605004 | AL12: AVPE-6724 | AM12: #N/A | AN12: 3 | AO12: 3 | AP12: 2 | AQ12: 2
A13: IPC-2605004 | B13: Jul24-46 | C13: 12125021 | D13: 2332447-0-C-CN | E13: 1001912053 | F13: 11133759 | G13: 1456045-Q-A | H13: STM180-14S CN | I13: 5 | J13: 46227 | K13: 0103544311 | L13: 260709A42A | M13: 5 | N13: 5 | O13: 0 | P13: China | Q13: 46217 | R13: 0 | S13: 46218 | T13: 46218 | U13: M5 | V13: F3 | X13: 0 | Y13: 0 | Z13: =IFERROR(VLOOKUP(H13,[2]New!$B:$G,3,0),)*I13/60 -> 4.5583333 | AA13: =IFERROR(VLOOKUP(H13,[2]New!$B:$G,4,0),)*I13/60 -> 13.908333 | AB13: =IFERROR(VLOOKUP(H13,[2]New!$B:$G,6,0),)*I13/60 -> 12.791667 | AC13: TEST | AD13: =IFERROR(VLOOKUP(H13,[3]Sheet1!$E:$H,4,0),) -> D | AE13: 5 | AF13: FINISH | AG13: 12 | AH13: 0 | AI13: M5-2 | AK13: IPC-2605004 | AL13: AVPE-6724 | AM13: #N/A | AN13: 3 | AO13: 3 | AP13: 2 | AQ13: 2
A14: IPC-2605004 | B14: Jul24-47 | C14: 12125021 | D14: 2332447-0-C-CN | E14: 1001912054 | F14: 11133759 | G14: 1456045-Q-A | H14: STM180-14S CN | I14: 5 | J14: 46227 | K14: 0103544312 | L14: 260709A43A | M14: 5 | N14: 5 | O14: 0 | P14: China | Q14: 46217 | R14: 0 | S14: 46218 | T14: 46218 | U14: M5 | V14: F3 | X14: 0 | Y14: 0 | Z14: =IFERROR(VLOOKUP(H14,[2]New!$B:$G,3,0),)*I14/60 -> 4.5583333 | AA14: =IFERROR(VLOOKUP(H14,[2]New!$B:$G,4,0),)*I14/60 -> 13.908333 | AB14: =IFERROR(VLOOKUP(H14,[2]New!$B:$G,6,0),)*I14/60 -> 12.791667 | AC14: TEST | AD14: =IFERROR(VLOOKUP(H14,[3]Sheet1!$E:$H,4,0),) -> D | AE14: 5 | AF14: FINISH | AG14: 12 | AH14: 0 | AI14: M5-2 | AK14: IPC-2605004 | AL14: AVPE-6724 | AM14: #N/A | AN14: 3 | AO14: 3 | AP14: 2 | AQ14: 2
A15: IPC-2605004 | B15: Jul24-48 | C15: 12125021 | D15: 2332447-0-C-CN | E15: 1001912055 | F15: 11133759 | G15: 1456045-Q-A | H15: STM180-14S CN | I15: 5 | J15: 46227 | K15: 0103544313 | L15: 260709A44A | M15: 5 | N15: 5 | O15: 0 | P15: China | Q15: 46217 | R15: 0 | S15: 46218 | T15: 46218 | U15: M5 | V15: F3 | X15: 0 | Y15: 0 | Z15: =IFERROR(VLOOKUP(H15,[2]New!$B:$G,3,0),)*I15/60 -> 4.5583333 | AA15: =IFERROR(VLOOKUP(H15,[2]New!$B:$G,4,0),)*I15/60 -> 13.908333 | AB15: =IFERROR(VLOOKUP(H15,[2]New!$B:$G,6,0),)*I15/60 -> 12.791667 | AC15: TEST | AD15: =IFERROR(VLOOKUP(H15,[3]Sheet1!$E:$H,4,0),) -> D | AE15: 5 | AF15: FINISH | AG15: 12 | AH15: 0 | AI15: M5-2 | AK15: IPC-2605004 | AL15: AVPE-6724 | AM15: #N/A | AN15: 3 | AO15: 3 | AP15: 2 | AQ15: 2
A16: IPC-2605004 | B16: Jul24-49 | C16: 12125021 | D16: 2332447-0-C-CN | E16: 1001912056 | F16: 11133759 | G16: 1456045-Q-A | H16: STM180-14S CN | I16: 5 | J16: 46227 | K16: 0103544314 | L16: 260709A45A | M16: 5 | N16: 5 | O16: 0 | P16: China | Q16: 46217 | R16: 0 | S16: 46218 | T16: 46218 | U16: M5 | V16: F3 | X16: 0 | Y16: 0 | Z16: =IFERROR(VLOOKUP(H16,[2]New!$B:$G,3,0),)*I16/60 -> 4.5583333 | AA16: =IFERROR(VLOOKUP(H16,[2]New!$B:$G,4,0),)*I16/60 -> 13.908333 | AB16: =IFERROR(VLOOKUP(H16,[2]New!$B:$G,6,0),)*I16/60 -> 12.791667 | AC16: TEST | AD16: =IFERROR(VLOOKUP(H16,[3]Sheet1!$E:$H,4,0),) -> D | AE16: 5 | AF16: FINISH | AG16: 12 | AH16: 0 | AI16: M5-2 | AK16: IPC-2605004 | AL16: AVPE-6724 | AM16: #N/A | AN16: 3 | AO16: 3 | AP16: 2 | AQ16: 2
A17: PT-H2606-PC-019 | B17: Jul28-24 | C17: 12120774 | D17: 2332192-0-C-CN | E17: 1001913437 | F17: 11134235 | G17: 1036068-S-AK | H17: AHW14R001S CN | I17: 2370 | J17: 46231 | K17: 0103547147 | L17: 260713A04A | M17: 2386 | N17: 16 | O17: 0 | P17: China | Q17: 46219 | R17: 0 | S17: 46220 | T17: 46220 | U17: M3 | V17: F3 | X17: 0 | Y17: 0 | Z17: =IFERROR(VLOOKUP(H17,[2]New!$B:$G,3,0),)*I17/60 -> 1674.8 | AA17: =IFERROR(VLOOKUP(H17,[2]New!$B:$G,4,0),)*I17/60 -> 4657.05 | AB17: =IFERROR(VLOOKUP(H17,[2]New!$B:$G,6,0),)*I17/60 -> 2291 | AC17: =VLOOKUP(A17,'[4]PO PTCA (2)'!$A:$L,12,0) -> 46255 | AD17: =IFERROR(VLOOKUP(H17,[3]Sheet1!$E:$H,4,0),) -> B | AE17: 2370 | AF17: FINISH | AG17: 3 | AH17: 16 | AI17: M3-1 | AL17: AVPE-8633 | AM17: #N/A | AN17: 2 | AO17: 2 | AP17: 2 | AQ17: 2
A18: PT-H2605-PC-001-1 | B18: Jul28-46 | C18: 12120774 | D18: 2332192-0-C-CN | E18: 1001914292 | F18: 11134235 | G18: 1036068-S-AK | H18: AHW14R001S CN | I18: 5 | J18: 46231 | K18: 0103548546 | L18: 260625A40B | M18: 5 | N18: 0 | O18: 0 | P18: China | Q18: 46219 | R18: 0 | S18: 46220 | T18: 46220 | U18: M3 | V18: F3 | X18: 0 | Y18: 0 | Z18: =IFERROR(VLOOKUP(H18,[2]New!$B:$G,3,0),)*I18/60 -> 3.5333333 | AA18: =IFERROR(VLOOKUP(H18,[2]New!$B:$G,4,0),)*I18/60 -> 9.825 | AB18: =IFERROR(VLOOKUP(H18,[2]New!$B:$G,6,0),)*I18/60 -> 4.8333333 | AC18: 46255 | AD18: =IFERROR(VLOOKUP(H18,[3]Sheet1!$E:$H,4,0),) -> B | AE18: 5 | AF18: FINISH | AG18: 3 | AH18: 0 | AI18: M3-1 | AL18: AVPE-8633 | AM18: #N/A | AN18: 2 | AO18: 2 | AP18: 2 | AQ18: 2
A19: PT-H2606-PC-021 | B19: Jul29-02 | C19: 12125012 | D19: 2332200-0-C-CN | E19: 1001914917 | F19: 11134237 | G19: 1436196-Q-A | H19: AHW14R004S CN | I19: 3570 | J19: 46232 | K19: 0103549428 | L19: 260713A46A | M19: 3586 | N19: 16 | O19: 0 | P19: China | Q19: 46220 | R19: 0 | S19: 46221 | T19: 46221 | U19: M2 | V19: F3 | X19: 0 | Y19: 0 | Z19: =IFERROR(VLOOKUP(H19,[2]New!$B:$G,3,0),)*I19/60 -> 2522.8 | AA19: =IFERROR(VLOOKUP(H19,[2]New!$B:$G,4,0),)*I19/60 -> 7015.05 | AB19: =IFERROR(VLOOKUP(H19,[2]New!$B:$G,6,0),)*I19/60 -> 3451 | AC19: =VLOOKUP(A19,'[4]PO PTCA (2)'!$A:$L,12,0) -> 46255 | AD19: =IFERROR(VLOOKUP(H19,[3]Sheet1!$E:$H,4,0),) -> B | AE19: 3570 | AF19: FINISH | AG19: 3 | AH19: 16 | AI19: M2-1 | AL19: AVPE-8631 | AM19: #N/A | AN19: 3 | AO19: 3 | AP19: 2 | AQ19: 2
A20: PT-H2606-PC-019 | B20: Jul29-19 | C20: 12120774 | D20: 2332192-0-C-CN | E20: 1001915236 | F20: 11134235 | G20: 1036068-S-AK | H20: AHW14R001S CN | I20: 3570 | J20: 46232 | K20: 0103550231 | L20: 260713A63A | M20: 3586 | N20: 16 | O20: 0 | P20: China | Q20: 46220 | R20: 0 | S20: 46221 | T20: 46221 | U20: M8 | V20: CAG | X20: 0 | Y20: 0 | Z20: =IFERROR(VLOOKUP(H20,[2]New!$B:$G,3,0),)*I20/60 -> 2522.8 | AA20: =IFERROR(VLOOKUP(H20,[2]New!$B:$G,4,0),)*I20/60 -> 7015.05 | AB20: =IFERROR(VLOOKUP(H20,[2]New!$B:$G,6,0),)*I20/60 -> 3451 | AC20: =VLOOKUP(A20,'[4]PO PTCA (2)'!$A:$L,12,0) -> 46255 | AD20: =IFERROR(VLOOKUP(H20,[3]Sheet1!$E:$H,4,0),) -> B | AE20: 3570 | AF20: FINISH | AG20: 3 | AH20: 16 | AI20: M8-1 | AL20: AVPE-8633 | AM20: #N/A | AN20: 2 | AO20: 2 | AP20: 2 | AQ20: 2
A21: Tuyến | B21: Test07-13-04 | C21: 12142310 | D21: 2432027-0-CB | E21: 2000127118 | F21: 11134959 | G21: 2431008-0-A | H21: 2431008-0-A_AIN-CNX-14-300A_US | I21: 34 | J21: 46248 | K21: 0103548931 | L21: 260713X04D | M21: 34 | N21: 0 | O21: 0 | P21: TEST | Q21: 46219 | R21: 0 | S21: 46227 | T21: 46227 | U21: TEST | V21: F2 | W21: 46232 | X21: 0 | Y21: 0 | Z21: 0 | AA21: 0 | AB21: 0 | AC21: TEST | AF21: TEST | AI21: TEST | AL21: AVPE-11193 | AM21: AVPE-11193
A22: Tuyến | B22: Test07-13-05 | C22: 12142310 | D22: 2432027-0-CB | E22: 2000127119 | F22: 11134959 | G22: 2431008-0-A | H22: 2431008-0-A_AIN-CNX-14-300A_US | I22: 33 | J22: 46248 | K22: 0103548932 | L22: 260713X05D | M22: 33 | N22: 0 | O22: 0 | P22: TEST | Q22: 46219 | R22: 0 | S22: 46227 | T22: 46227 | U22: TEST | V22: F2 | W22: 46232 | X22: 0 | Y22: 0 | Z22: 0 | AA22: 0 | AB22: 0 | AC22: TEST | AF22: TEST | AL22: AVPE-11193 | AM22: AVPE-11193
A23: Tuyến | B23: Test07-13-06 | C23: 12142310 | D23: 2432027-0-CB | E23: 2000127120 | F23: 11134959 | G23: 2431008-0-A | H23: 2431008-0-A_AIN-CNX-14-300A_US | I23: 33 | J23: 46248 | K23: 0103548933 | L23: 260713X06D | M23: 33 | N23: 0 | O23: 0 | P23: TEST | Q23: 46219 | R23: 0 | S23: 46227 | T23: 46227 | U23: TEST | V23: F2 | W23: 46232 | X23: 0 | Y23: 0 | Z23: 0 | AA23: 0 | AB23: 0 | AC23: TEST | AF23: TEST | AL23: AVPE-11193 | AM23: AVPE-11193
A24: Tuyến | B24: Test07-13-01 | C24: 12144294 | D24: AJ2401211-01-C | E24: 2000127115 | F24: 11121123 | G24: AJ2401256-03-A | H24: AJ2401256-03-A_WAMS-180-16WAC CN | I24: 40 | J24: 46227 | K24: 0103548928 | L24: 260713X01D | M24: 40 | N24: 0 | O24: 0 | P24: TEST | Q24: 46219 | R24: 0 | S24: 46226 | T24: 46226 | U24: M5 | V24: F2 | W24: 46241 | X24: 0 | Y24: 0 | Z24: 0 | AA24: 0 | AB24: 0 | AC24: TEST | AF24: TEST | AK24: M6-23 | AL24: #N/A | AM24: #N/A
A25: Tuyến | B25: Test07-13-02 | C25: 12144294 | D25: AJ2401211-01-C | E25: 2000127116 | F25: 11121123 | G25: AJ2401256-03-A | H25: AJ2401256-03-A_WAMS-180-16WAC CN | I25: 40 | J25: 46227 | K25: 0103548929 | L25: 260713X02D | M25: 40 | N25: 0 | O25: 0 | P25: TEST | Q25: 46219 | R25: 0 | S25: 46226 | T25: 46226 | U25: M5 | V25: F2 | W25: 46241 | X25: 0 | Y25: 0 | Z25: 0 | AA25: 0 | AB25: 0 | AC25: TEST | AF25: TEST | AK25: M6-23 | AL25: #N/A | AM25: #N/A
A26: Tuyến | B26: Test07-13-03 | C26: 12144294 | D26: AJ2401211-01-C | E26: 2000127117 | F26: 11121123 | G26: AJ2401256-03-A | H26: AJ2401256-03-A_WAMS-180-16WAC CN | I26: 45 | J26: 46227 | K26: 0103548930 | L26: 260713X03D | M26: 45 | N26: 0 | O26: 0 | P26: TEST | Q26: 46219 | R26: 0 | S26: 46226 | T26: 46226 | U26: M5 | V26: F2 | W26: 46241 | X26: 0 | Y26: 0 | Z26: 0 | AA26: 0 | AB26: 0 | AC26: TEST | AF26: TEST | AK26: M6-23 | AL26: #N/A | AM26: #N/A
A27: PT-H2606-PC-021 | B27: Jul29-21 | C27: 12125012 | D27: 2332200-0-C-CN | E27: 1001916972 | F27: 11134237 | G27: 1436196-Q-A | H27: AHW14R004S CN | I27: 3570 | J27: 46232 | K27: 0103553784 | L27: 260715A01A | M27: 3586 | N27: 16 | O27: 0 | P27: China | Q27: 46221 | R27: 0 | S27: 46223 | T27: 46223 | U27: M1 | V27: F3 | X27: 0 | Y27: 0 | Z27: =IFERROR(VLOOKUP(H27,[2]New!$B:$G,3,0),)*I27/60 -> 2522.8 | AA27: =IFERROR(VLOOKUP(H27,[2]New!$B:$G,4,0),)*I27/60 -> 7015.05 | AB27: =IFERROR(VLOOKUP(H27,[2]New!$B:$G,6,0),)*I27/60 -> 3451 | AC27: =VLOOKUP(A27,'[4]PO PTCA (2)'!$A:$L,12,0) -> 46255 | AD27: =IFERROR(VLOOKUP(H27,[3]Sheet1!$E:$H,4,0),) -> B | AE27: 3570 | AF27: FINISH | AG27: 3 | AH27: 16 | AI27: M1-1 | AL27: AVPE-8631 | AM27: #N/A | AN27: 3 | AO27: 3 | AP27: 2 | AQ27: 2
A28: PT-H2606-PC-021 | B28: Jul29-22 | C28: 12125012 | D28: 2332200-0-C-CN | E28: 1001916973 | F28: 11134237 | G28: 1436196-Q-A | H28: AHW14R004S CN | I28: 3570 | J28: 46232 | K28: 0103553785 | L28: 260715A02A | M28: 3586 | N28: 16 | O28: 0 | P28: China | Q28: 46221 | R28: 0 | S28: 46223 | T28: 46223 | U28: M2 | V28: F3 | X28: 0 | Y28: 0 | Z28: =IFERROR(VLOOKUP(H28,[2]New!$B:$G,3,0),)*I28/60 -> 2522.8 | AA28: =IFERROR(VLOOKUP(H28,[2]New!$B:$G,4,0),)*I28/60 -> 7015.05 | AB28: =IFERROR(VLOOKUP(H28,[2]New!$B:$G,6,0),)*I28/60 -> 3451 | AC28: =VLOOKUP(A28,'[4]PO PTCA (2)'!$A:$L,12,0) -> 46255 | AD28: =IFERROR(VLOOKUP(H28,[3]Sheet1!$E:$H,4,0),) -> B | AE28: 3570 | AF28: FINISH | AG28: 3 | AH28: 16 | AI28: M2-1 | AL28: AVPE-8631 | AM28: #N/A | AN28: 3 | AO28: 3 | AP28: 2 | AQ28: 2
A29: PT-H2606-PC-021 | B29: Jul29-23 | C29: 12125012 | D29: 2332200-0-C-CN | E29: 1001916974 | F29: 11134237 | G29: 1436196-Q-A | H29: AHW14R004S CN | I29: 2365 | J29: 46232 | K29: 0103553786 | L29: 260715A03A | M29: 2384 | N29: 16 | O29: 0 | P29: China | Q29: 46221 | R29: 0 | S29: 46223 | T29: 46223 | U29: M3 | V29: F3 | X29: 3 | Y29: 0 | Z29: =IFERROR(VLOOKUP(H29,[2]New!$B:$G,3,0),)*I29/60 -> 1671.2667 | AA29: =IFERROR(VLOOKUP(H29,[2]New!$B:$G,4,0),)*I29/60 -> 4647.225 | AB29: =IFERROR(VLOOKUP(H29,[2]New!$B:$G,6,0),)*I29/60 -> 2286.1667 | AC29: =VLOOKUP(A29,'[4]PO PTCA (2)'!$A:$L,12,0) -> 46255 | AD29: =IFERROR(VLOOKUP(H29,[3]Sheet1!$E:$H,4,0),) -> B | AE29: 2365 | AF29: FINISH | AG29: 3 | AH29: 19 | AI29: M3-1 | AL29: AVPE-8631 | AM29: #N/A | AN29: 3 | AO29: 3 | AP29: 2 | AQ29: 2
A30: PT-H2606-PC-019 | B30: Jul29-24 | C30: 12120774 | D30: 2332192-0-C-CN | E30: 1001916975 | F30: 11134235 | G30: 1036068-S-AK | H30: AHW14R001S CN | I30: 2370 | J30: 46232 | K30: 0103553787 | L30: 260715A04A | M30: 2386 | N30: 16 | O30: 0 | P30: China | Q30: 46221 | R30: 0 | S30: 46223 | T30: 46223 | U30: M4 | V30: F3 | X30: 0 | Y30: 0 | Z30: =IFERROR(VLOOKUP(H30,[2]New!$B:$G,3,0),)*I30/60 -> 1674.8 | AA30: =IFERROR(VLOOKUP(H30,[2]New!$B:$G,4,0),)*I30/60 -> 4657.05 | AB30: =IFERROR(VLOOKUP(H30,[2]New!$B:$G,6,0),)*I30/60 -> 2291 | AC30: =VLOOKUP(A30,'[4]PO PTCA (2)'!$A:$L,12,0) -> 46255 | AD30: =IFERROR(VLOOKUP(H30,[3]Sheet1!$E:$H,4,0),) -> B | AE30: 2370 | AF30: FINISH | AG30: 3 | AH30: 16 | AI30: M4-1 | AL30: AVPE-8633 | AM30: #N/A | AN30: 2 | AO30: 2 | AP30: 2 | AQ30: 2
A31: PT-H2606-PC-019 | B31: Jul29-25 | C31: 12120774 | D31: 2332192-0-C-CN | E31: 1001916976 | F31: 11134235 | G31: 1036068-S-AK | H31: AHW14R001S CN | I31: 2370 | J31: 46232 | K31: 0103553788 | L31: 260715A05A | M31: 2386 | N31: 16 | O31: 0 | P31: China | Q31: 46221 | R31: 0 | S31: 46223 | T31: 46223 | U31: M5 | V31: F3 | X31: 0 | Y31: 0 | Z31: =IFERROR(VLOOKUP(H31,[2]New!$B:$G,3,0),)*I31/60 -> 1674.8 | AA31: =IFERROR(VLOOKUP(H31,[2]New!$B:$G,4,0),)*I31/60 -> 4657.05 | AB31: =IFERROR(VLOOKUP(H31,[2]New!$B:$G,6,0),)*I31/60 -> 2291 | AC31: =VLOOKUP(A31,'[4]PO PTCA (2)'!$A:$L,12,0) -> 46255 | AD31: =IFERROR(VLOOKUP(H31,[3]Sheet1!$E:$H,4,0),) -> B | AE31: 2370 | AF31: FINISH | AG31: 3 | AH31: 16 | AI31: M5-1 | AL31: AVPE-8633 | AM31: #N/A | AN31: 2 | AO31: 2 | AP31: 2 | AQ31: 2
A32: PT-H2607-PT-035 | B32: Jul29-30 | C32: 12111488 | D32: 1832283-A-CK | E32: 1001916981 | F32: 11125017 | G32: 1831234-C-AK | H32: PAGH18M071R JP | I32: 155 | J32: 46232 | K32: 0103553793 | L32: 260715A10A | M32: 155 | N32: 0 | O32: 0 | P32: Japan | Q32: 46221 | R32: 0 | S32: 46230 | T32: 46230 | U32: M7 | V32: F2 | X32: 0 | Y32: 0 | Z32: =IFERROR(VLOOKUP(H32,[2]New!$B:$G,3,0),)*I32/60 -> 71.041667 | AA32: =IFERROR(VLOOKUP(H32,[2]New!$B:$G,4,0),)*I32/60 -> 304.575 | AB32: =IFERROR(VLOOKUP(H32,[2]New!$B:$G,6,0),)*I32/60 -> 180.83333 | AC32: =VLOOKUP(A32,'[4]PO PTCA (2)'!$A:$L,12,0) -> 46238 | AD32: =IFERROR(VLOOKUP(H32,[3]Sheet1!$E:$H,4,0),) -> 0 | AE32: 155 | AF32: FINISH | AG32: 0 | AH32: 0 | AI32: M7-1 | AL32: AVPE-7534 | AM32: AVPE-7534 | AN32: 2 | AO32: 2 | AP32: 2 | AQ32: 2
A33: PT-H2606-PC-019 | B33: Jul29-44 | C33: 12120774 | D33: 2332192-0-C-CN | E33: 1001916995 | F33: 11134235 | G33: 1036068-S-AK | H33: AHW14R001S CN | I33: 3570 | J33: 46232 | K33: 0103553807 | L33: 260715A24A | M33: 3586 | N33: 16 | O33: 0 | P33: China | Q33: 46221 | R33: 0 | S33: 46223 | T33: 46223 | U33: M8 | V33: CAG | X33: 0 | Y33: 0 | Z33: =IFERROR(VLOOKUP(H33,[2]New!$B:$G,3,0),)*I33/60 -> 2522.8 | AA33: =IFERROR(VLOOKUP(H33,[2]New!$B:$G,4,0),)*I33/60 -> 7015.05 | AB33: =IFERROR(VLOOKUP(H33,[2]New!$B:$G,6,0),)*I33/60 -> 3451 | AC33: =VLOOKUP(A33,'[4]PO PTCA (2)'!$A:$L,12,0) -> 46255 | AD33: =IFERROR(VLOOKUP(H33,[3]Sheet1!$E:$H,4,0),) -> B | AE33: 3570 | AF33: FINISH | AG33: 3 | AH33: 16 | AI33: M8-1 | AL33: AVPE-8633 | AM33: #N/A | AN33: 2 | AO33: 2 | AP33: 2 | AQ33: 2
A34: PT-H2606-PC-021 | B34: Jul30-01 | C34: 12125012 | D34: 2332200-0-C-CN | E34: 1001916996 | F34: 11134237 | G34: 1436196-Q-A | H34: AHW14R004S CN | I34: 350 | J34: 46233 | K34: 0103553808 | L34: 260715A25A | M34: 354 | N34: 4 | O34: 0 | P34: China | Q34: 46223 | R34: 0 | S34: 46224 | T34: 46224 | U34: M1 | V34: F3 | X34: 0 | Y34: 0 | Z34: =IFERROR(VLOOKUP(H34,[2]New!$B:$G,3,0),)*I34/60 -> 247.33333 | AA34: =IFERROR(VLOOKUP(H34,[2]New!$B:$G,4,0),)*I34/60 -> 687.75 | AB34: =IFERROR(VLOOKUP(H34,[2]New!$B:$G,6,0),)*I34/60 -> 338.33333 | AC34: =VLOOKUP(A34,'[4]PO PTCA (2)'!$A:$L,12,0) -> 46255 | AD34: =IFERROR(VLOOKUP(H34,[3]Sheet1!$E:$H,4,0),) -> B | AE34: 350 | AF34: FINISH | AG34: 3 | AH34: 4 | AI34: M1-1 | AL34: AVPE-8631 | AM34: #N/A | AN34: 3 | AO34: 3 | AP34: 2 | AQ34: 2
A35: PT-H2606-PC-021 | B35: Jul30-02 | C35: 12125012 | D35: 2332200-0-C-CN | E35: 1001916997 | F35: 11134237 | G35: 1436196-Q-A | H35: AHW14R004S CN | I35: 3200 | J35: 46233 | K35: 0103553809 | L35: 260715A26A | M35: 3216 | N35: 16 | O35: 0 | P35: China | Q35: 46223 | R35: 0 | S35: 46224 | T35: 46224 | U35: M1 | V35: F3 | X35: 0 | Y35: 0 | Z35: =IFERROR(VLOOKUP(H35,[2]New!$B:$G,3,0),)*I35/60 -> 2261.3333 | AA35: =IFERROR(VLOOKUP(H35,[2]New!$B:$G,4,0),)*I35/60 -> 6288 | AB35: =IFERROR(VLOOKUP(H35,[2]New!$B:$G,6,0),)*I35/60 -> 3093.3333 | AC35: =VLOOKUP(A35,'[4]PO PTCA (2)'!$A:$L,12,0) -> 46255 | AD35: =IFERROR(VLOOKUP(H35,[3]Sheet1!$E:$H,4,0),) -> B | AE35: 3200 | AF35: FINISH | AG35: 3 | AH35: 16 | AI35: M1-1 | AL35: AVPE-8631 | AM35: #N/A | AN35: 3 | AO35: 3 | AP35: 2 | AQ35: 2
A36: PT-H2606-PC-021 | B36: Jul30-03 | C36: 12125012 | D36: 2332200-0-C-CN | E36: 1001916998 | F36: 11134237 | G36: 1436196-Q-A | H36: AHW14R004S CN | I36: 350 | J36: 46233 | K36: 0103553810 | L36: 260715A27A | M36: 357 | N36: 4 | O36: 0 | P36: China | Q36: 46223 | R36: 0 | S36: 46224 | T36: 46224 | U36: M2 | V36: F3 | X36: 3 | Y36: 0 | Z36: =IFERROR(VLOOKUP(H36,[2]New!$B:$G,3,0),)*I36/60 -> 247.33333 | AA36: =IFERROR(VLOOKUP(H36,[2]New!$B:$G,4,0),)*I36/60 -> 687.75 | AB36: =IFERROR(VLOOKUP(H36,[2]New!$B:$G,6,0),)*I36/60 -> 338.33333 | AC36: =VLOOKUP(A36,'[4]PO PTCA (2)'!$A:$L,12,0) -> 46255 | AD36: =IFERROR(VLOOKUP(H36,[3]Sheet1!$E:$H,4,0),) -> B | AE36: 350 | AF36: FINISH | AG36: 3 | AH36: 7 | AI36: M2-1 | AL36: AVPE-8631 | AM36: #N/A | AN36: 3 | AO36: 3 | AP36: 2 | AQ36: 2
A37: PT-H2606-PC-021 | B37: Jul30-04 | C37: 12125012 | D37: 2332200-0-C-CN | E37: 1001916999 | F37: 11134237 | G37: 1436196-Q-A | H37: AHW14R004S CN | I37: 3195 | J37: 46233 | K37: 0103553811 | L37: 260715A28A | M37: 3216 | N37: 16 | O37: 0 | P37: China | Q37: 46223 | R37: 0 | S37: 46224 | T37: 46224 | U37: M2 | V37: F3 | X37: 0 | Y37: 0 | Z37: =IFERROR(VLOOKUP(H37,[2]New!$B:$G,3,0),)*I37/60 -> 2257.8 | AA37: =IFERROR(VLOOKUP(H37,[2]New!$B:$G,4,0),)*I37/60 -> 6278.175 | AB37: =IFERROR(VLOOKUP(H37,[2]New!$B:$G,6,0),)*I37/60 -> 3088.5 | AC37: =VLOOKUP(A37,'[4]PO PTCA (2)'!$A:$L,12,0) -> 46255 | AD37: =IFERROR(VLOOKUP(H37,[3]Sheet1!$E:$H,4,0),) -> B | AE37: 3195 | AF37: FINISH | AG37: 3 | AH37: 16 | AI37: M2-1 | AL37: AVPE-8631 | AM37: #N/A | AN37: 3 | AO37: 3 | AP37: 2 | AQ37: 2
A38: PT-H2606-PC-021 | B38: Jul30-05 | C38: 12125012 | D38: 2332200-0-C-CN | E38: 1001917000 | F38: 11134237 | G38: 1436196-Q-A | H38: AHW14R004S CN | I38: 2380 | J38: 46233 | K38: 0103553812 | L38: 260715A29A | M38: 2396 | N38: 16 | O38: 0 | P38: China | Q38: 46223 | R38: 0 | S38: 46224 | T38: 46224 | U38: M3 | V38: F3 | X38: 0 | Y38: 0 | Z38: =IFERROR(VLOOKUP(H38,[2]New!$B:$G,3,0),)*I38/60 -> 1681.8667 | AA38: =IFERROR(VLOOKUP(H38,[2]New!$B:$G,4,0),)*I38/60 -> 4676.7 | AB38: =IFERROR(VLOOKUP(H38,[2]New!$B:$G,6,0),)*I38/60 -> 2300.6667 | AC38: =VLOOKUP(A38,'[4]PO PTCA (2)'!$A:$L,12,0) -> 46255 | AD38: =IFERROR(VLOOKUP(H38,[3]Sheet1!$E:$H,4,0),) -> B | AE38: 2380 | AF38: FINISH | AG38: 3 | AH38: 16 | AI38: M3-1 | AL38: AVPE-8631 | AM38: #N/A | AN38: 3 | AO38: 3 | AP38: 2 | AQ38: 2
A39: PT-H2606-PC-019 | B39: Jul30-06 | C39: 12120774 | D39: 2332192-0-C-CN | E39: 1001917001 | F39: 11134235 | G39: 1036068-S-AK | H39: AHW14R001S CN | I39: 2370 | J39: 46233 | K39: 0103553813 | L39: 260715A30A | M39: 2386 | N39: 16 | O39: 0 | P39: China | Q39: 46223 | R39: 0 | S39: 46224 | T39: 46224 | U39: M4 | V39: F3 | X39: 0 | Y39: 0 | Z39: =IFERROR(VLOOKUP(H39,[2]New!$B:$G,3,0),)*I39/60 -> 1674.8 | AA39: =IFERROR(VLOOKUP(H39,[2]New!$B:$G,4,0),)*I39/60 -> 4657.05 | AB39: =IFERROR(VLOOKUP(H39,[2]New!$B:$G,6,0),)*I39/60 -> 2291 | AC39: =VLOOKUP(A39,'[4]PO PTCA (2)'!$A:$L,12,0) -> 46255 | AD39: =IFERROR(VLOOKUP(H39,[3]Sheet1!$E:$H,4,0),) -> B | AE39: 2370 | AF39: FINISH | AG39: 3 | AH39: 16 | AI39: M4-1 | AL39: AVPE-8633 | AM39: #N/A | AN39: 2 | AO39: 2 | AP39: 2 | AQ39: 2
A40: PT-H2605-PC-119-2 | B40: Jul30-07 | C40: 12125069 | D40: 2332495-0-C-CN | E40: 1001917002 | F40: 11134240 | G40: 1436296-J-AK | H40: APW14R009S CN | I40: 3525 | J40: 46233 | K40: 0103553814 | L40: 260715A31A | M40: 3533 | N40: 0 | O40: 0 | P40: China | Q40: 46223 | R40: 0 | S40: 46224 | T40: 46224 | U40: M5 | V40: F3 | X40: 3 | Y40: 0 | Z40: =IFERROR(VLOOKUP(H40,[2]New!$B:$G,3,0),)*I40/60 -> 2491 | AA40: =IFERROR(VLOOKUP(H40,[2]New!$B:$G,4,0),)*I40/60 -> 5440.25 | AB40: =IFERROR(VLOOKUP(H40,[2]New!$B:$G,6,0),)*I40/60 -> 3407.5 | AC40: =VLOOKUP(A40,'[4]PO PTCA (2)'!$A:$L,12,0) -> 46255 | AD40: =IFERROR(VLOOKUP(H40,[3]Sheet1!$E:$H,4,0),) -> C | AE40: 3525 | AF40: FINISH | AG40: 2 | AH40: 3 | AI40: M5-1 | AL40: AVPE-7061 | AM40: #N/A | AN40: 2 | AO40: 2 | AP40: 2 | AQ40: 2
...

Sheet Sheet2
S1: List RC-2607015
L2: Kho type C | M2: Kho FN | S2: Productiom | T2: Code Sap | U2: D.W | V2: Item name | W2: Internal Lot | X2: External Lot Ster | Y2: q'ty | Z2: Remark
C3: 1001930165 | D3: 11127226 | E3: 2351005-0-A | F3: TES0018S US | G3: 21 | H3: 46248 | I3: 0103580105 | J3: 260727G01A | K3: 26 | L3: MA07 | M3: MA09 | N3: 12126472 | S3: 4000017403 | T3: 11134977 | U3: 1931204-K-A | V3: E0018450AG-2 JP | W3: 0103580099 | X3: 260409S02B | Y3: 1 | Z3: Đã sửa Instruction
C4: 4000017403 | D4: 11134977 | E4: 1931204-K-A | F4: E0018450AG-2 JP | G4: 1 | H4: 46248 | I4: 0103580099 | J4: 260409S02B | K4: 1 | L4: ML07 | M4: ML09 | N4: 11122028 | S4: 4000017404 | T4: 11134977 | U4: 1931204-K-A | V4: E0018450AG-2 JP | W4: 0103580100 | X4: 260428S02B | Y4: 1 | Z4: Đã sửa Instruction
C5: 4000017404 | D5: 11134977 | E5: 1931204-K-A | F5: E0018450AG-2 JP | G5: 1 | H5: 46248 | I5: 0103580100 | J5: 260428S02B | K5: 1 | M5: ML09 | N5: 11122028 | S5: 4000017405 | T5: 11134978 | U5: 2051001-D-A | V5: TES0025S JP | W5: 0103580101 | X5: 260415G03B | Y5: 251 | Z5: Đã sửa Instruction
C6: 4000017405 | D6: 11134978 | E6: 2051001-D-A | F6: TES0025S JP | G6: 251 | H6: 46248 | I6: 0103580101 | J6: 260415G03B | K6: 251 | M6: MA09 | N6: 11123531 | S6: 4000017406 | T6: 11134978 | U6: 2051001-D-A | V6: TES0025S JP | W6: 0103580102 | X6: 260428G02B | Y6: 26 | Z6: Đã sửa Instruction
C7: 4000017406 | D7: 11134978 | E7: 2051001-D-A | F7: TES0025S JP | G7: 26 | H7: 46248 | I7: 0103580102 | J7: 260428G02B | K7: 26 | M7: MA09 | N7: 11123531 | S7: 4000017407 | T7: 11134979 | U7: 2051002-D-A | V7: TES0018S JP | W7: 0103580103 | X7: 260209G02B | Y7: 1 | Z7: Đã sửa Instruction
C8: 4000017407 | D8: 11134979 | E8: 2051002-D-A | F8: TES0018S JP | G8: 1 | H8: 46248 | I8: 0103580103 | J8: 260209G02B | K8: 1 | M8: MA09 | N8: 11123532 | S8: 4000017408 | T8: 11134979 | U8: 2051002-D-A | V8: TES0018S JP | W8: 0103580104 | X8: 260415G01B | Y8: 8 | Z8: Đã sửa Instruction
C9: 4000017408 | D9: 11134979 | E9: 2051002-D-A | F9: TES0018S JP | G9: 8 | H9: 46248 | I9: 0103580104 | J9: 260415G01B | K9: 8 | M9: MA09 | N9: 11123532
C10: 1001930166 | D10: 11122032 | E10: 2051047-E-A | F10: MTS0025N45S JP | G10: 7 | H10: 46248 | I10: 0103580106 | J10: 260727S01A | K10: 9 | M10: ML09 | N10: 12120940
C11: 1001930167 | D11: 11134977 | E11: 1931204-K-A | F11: E0018450AG-2 JP | G11: 230 | H11: 46248 | I11: 0103580107 | J11: 260727S02A | K11: 232 | M11: ML09 | N11: 12120936
Q25: PldOrd | R25: Material No | S25: Item code | T25: Item name | U25: Q'ty | V25: Complete Date | W25: Internal Lot | X25: External Lot Ster | Y25: Q'ty Input | Z25: Test Endotoxin ( pcs) | AA25: Test Particle ( pcs)
Q26: 1001931991 | R26: 11132336 | S26: 1731162-F-A | T26: AHW14R313S US | U26: 65 | V26: 46251 | W26: 0103584121 | X26: 260729A57A | Y26: 65 | Z26: 0 | AA26: 0
Q27: 1001931992 | R27: 11132337 | S27: 1731163-F-A | T27: AHW14R313P US | U27: 135 | V27: 46251 | W27: 0103584122 | X27: 260729A58A | Y27: 135 | Z27: 10 | AA27: 0
W41: Seal date | X41: KT date | Z41: ETD | AA41: Test Endotoxin ( pcs) | AB41: Test Particle ( pcs)
Q42: 1001930872 | R42: 11126857 | S42: 2231010-B-AK | T42: 0103582069 | U42: 260729A13A | V42: 135 | W42: 46241 | X42: 46241 | Y42: M11 | Z42: 46252 | AA42: 0 | AB42: 0
Q43: 1001931985 | R43: 11113866 | S43: 1831227-B-AK | T43: 0103584114 | U43: 260729A52A | V43: 10 | W43: 46241 | X43: 46241 | Y43: M8 | Z43: 46251 | AA43: 0 | AB43: 0
L44: 11134526 | Q44: 1001933345 | R44: 11135012 | S44: 2431136-0-A | T44: 0103586850 | U44: 260731A08A | V44: 23 | W44: 46240 | X44: 46240 | Y44: M6 | Z44: 46254 | AA44: 3 | AB44: 0
L45: 11133755 | Q45: 1001933346 | R45: 11135013 | S45: 2431137-0-A | T45: 0103586852 | U45: 260731A09A | V45: 20 | W45: 46240 | X45: 46240 | Y45: M6 | Z45: 46254 | AA45: 0 | AB45: 0
Q46: 1001933347 | R46: 11135014 | S46: 2431138-0-A | T46: 0103586853 | U46: 260731A10A | V46: 40 | W46: 46240 | X46: 46240 | Y46: M6 | Z46: 46254 | AA46: 0 | AB46: 0
Q47: 1001935075 | R47: 11134340 | S47: 2331156-A-A | T47: 0103589880 | U47: 260731A11A | V47: 60 | W47: 46240 | X47: 46240 | Y47: M8 | Z47: 46258 | AA47: 0 | AB47: 0
Q48: 1001935076 | R48: 11134339 | S48: 2331167-A-A | T48: 0103589881 | U48: 260731A44A | V48: 10 | W48: 46240 | X48: 46240 | Y48: M8 | Z48: 46258 | AA48: 0 | AB48: 0
Q62: 2631199-0-B | R62: có giông OHP ko? | S62: 2631199-0-A
Q63: 2631201-0-B | R63: có giông OHP ko? | S63: 2631201-0-A
Q64: 2631200-0-B | R64: có giông OHP ko? | S64: 2631200-0-A

Sheet Label new
A1: DIV/ SECTION | C1: DAILY PLAN AND IN-OUT LABEL CONTROL LIST ( Kế hoạch sản xuất hàng ngày và quản lý việc In-Out Label) | N1: F-1469 Ver 1.07
A2: GPC/ Order control | N2: Page : / 1
A4: PLAN DATE : | C4: 46258
A5: No | B5: Material | C5: Drawing List No | D5: Item name/Description | E5: Plnd order / PO | F5: Schuled Finish Date | G5: Internal Lot (SAP Lot) | H5: External Lot (Hanoi Lot) | I5: Q'ty | J5: Sterilize | L5: Finish | M5: Out label control | O5: Remark
J6: Date | K6: Batch | M6: Bag | N6: Box
A7: Jul22-11 | B7: =VLOOKUP(A7,PLAN!B:T,5,0) -> 11111223 | C7: =VLOOKUP(A7,PLAN!B:T,6,0) -> 1631042-F-A | D7: =VLOOKUP(A7,PLAN!B:T,7,0) -> AMS-180-1445 JP | E7: =VLOOKUP(A7,PLAN!B:T,4,0) -> 1001907448 | F7: =VLOOKUP(A7,PLAN!B:T,9,0) -> 46236 | G7: =VLOOKUP(A7,PLAN!B:T,10,0) -> 0103536427 | H7: =VLOOKUP(A7,PLAN!B:T,11,0) -> 260707A14A | I7: =VLOOKUP(A7,PLAN!B:T,12,0) -> 380 | J7: =VLOOKUP(A7,PLAN!B:AB,19,0) -> 46238 | K7: =VLOOKUP(A7,PLAN!B:AB,20,0) -> M7 | O7: =VLOOKUP(A7,PLAN!B:AB,21,0) -> CAG | Q7: =VLOOKUP(A7,PLAN!B:AB,16,0) -> 46217
A8: Jul23-04 | B8: =VLOOKUP(A8,PLAN!B:T,5,0) -> 11134237 | C8: =VLOOKUP(A8,PLAN!B:T,6,0) -> 1436196-Q-A | D8: =VLOOKUP(A8,PLAN!B:T,7,0) -> AHW14R004S CN | E8: =VLOOKUP(A8,PLAN!B:T,4,0) -> 1001907463 | F8: =VLOOKUP(A8,PLAN!B:T,9,0) -> 46226 | G8: =VLOOKUP(A8,PLAN!B:T,10,0) -> 0103536442 | H8: =VLOOKUP(A8,PLAN!B:T,11,0) -> 260707A29A | I8: =VLOOKUP(A8,PLAN!B:T,12,0) -> 2389 | J8: =VLOOKUP(A8,PLAN!B:AB,19,0) -> 46217 | K8: =VLOOKUP(A8,PLAN!B:AB,20,0) -> M3 | O8: =VLOOKUP(A8,PLAN!B:AB,21,0) -> F3 | Q8: =VLOOKUP(A8,PLAN!B:AB,16,0) -> 46216
A9: Jul24-40 | B9: =VLOOKUP(A9,PLAN!B:T,5,0) -> 11133759 | C9: =VLOOKUP(A9,PLAN!B:T,6,0) -> 1456045-Q-A | D9: =VLOOKUP(A9,PLAN!B:T,7,0) -> STM180-14S CN | E9: =VLOOKUP(A9,PLAN!B:T,4,0) -> 1001912046 | F9: =VLOOKUP(A9,PLAN!B:T,9,0) -> 46227 | G9: =VLOOKUP(A9,PLAN!B:T,10,0) -> 0103544302 | H9: =VLOOKUP(A9,PLAN!B:T,11,0) -> 260709A36A | I9: =VLOOKUP(A9,PLAN!B:T,12,0) -> 5 | J9: =VLOOKUP(A9,PLAN!B:AB,19,0) -> 46218 | K9: =VLOOKUP(A9,PLAN!B:AB,20,0) -> M5 | O9: =VLOOKUP(A9,PLAN!B:AB,21,0) -> F3 | Q9: =VLOOKUP(A9,PLAN!B:AB,16,0) -> 46217
A10: Jul24-41 | B10: =VLOOKUP(A10,PLAN!B:T,5,0) -> 11133759 | C10: =VLOOKUP(A10,PLAN!B:T,6,0) -> 1456045-Q-A | D10: =VLOOKUP(A10,PLAN!B:T,7,0) -> STM180-14S CN | E10: =VLOOKUP(A10,PLAN!B:T,4,0) -> 1001912047 | F10: =VLOOKUP(A10,PLAN!B:T,9,0) -> 46227 | G10: =VLOOKUP(A10,PLAN!B:T,10,0) -> 0103544305 | H10: =VLOOKUP(A10,PLAN!B:T,11,0) -> 260709A37A | I10: =VLOOKUP(A10,PLAN!B:T,12,0) -> 5 | J10: =VLOOKUP(A10,PLAN!B:AB,19,0) -> 46218 | K10: =VLOOKUP(A10,PLAN!B:AB,20,0) -> M5 | O10: =VLOOKUP(A10,PLAN!B:AB,21,0) -> F3 | Q10: =VLOOKUP(A10,PLAN!B:AB,16,0) -> 46217
A11: Jul24-42 | B11: =VLOOKUP(A11,PLAN!B:T,5,0) -> 11133759 | C11: =VLOOKUP(A11,PLAN!B:T,6,0) -> 1456045-Q-A | D11: =VLOOKUP(A11,PLAN!B:T,7,0) -> STM180-14S CN | E11: =VLOOKUP(A11,PLAN!B:T,4,0) -> 1001912048 | F11: =VLOOKUP(A11,PLAN!B:T,9,0) -> 46227 | G11: =VLOOKUP(A11,PLAN!B:T,10,0) -> 0103544306 | H11: =VLOOKUP(A11,PLAN!B:T,11,0) -> 260709A38A | I11: =VLOOKUP(A11,PLAN!B:T,12,0) -> 5 | J11: =VLOOKUP(A11,PLAN!B:AB,19,0) -> 46218 | K11: =VLOOKUP(A11,PLAN!B:AB,20,0) -> M5 | O11: =VLOOKUP(A11,PLAN!B:AB,21,0) -> F3 | Q11: =VLOOKUP(A11,PLAN!B:AB,16,0) -> 46217
A12: Jul24-43 | B12: =VLOOKUP(A12,PLAN!B:T,5,0) -> 11133759 | C12: =VLOOKUP(A12,PLAN!B:T,6,0) -> 1456045-Q-A | D12: =VLOOKUP(A12,PLAN!B:T,7,0) -> STM180-14S CN | E12: =VLOOKUP(A12,PLAN!B:T,4,0) -> 1001912049 | F12: =VLOOKUP(A12,PLAN!B:T,9,0) -> 46227 | G12: =VLOOKUP(A12,PLAN!B:T,10,0) -> 0103544307 | H12: =VLOOKUP(A12,PLAN!B:T,11,0) -> 260709A39A | I12: =VLOOKUP(A12,PLAN!B:T,12,0) -> 5 | J12: =VLOOKUP(A12,PLAN!B:AB,19,0) -> 46218 | K12: =VLOOKUP(A12,PLAN!B:AB,20,0) -> M5 | O12: =VLOOKUP(A12,PLAN!B:AB,21,0) -> F3 | Q12: =VLOOKUP(A12,PLAN!B:AB,16,0) -> 46217
A13: Jul24-44 | B13: =VLOOKUP(A13,PLAN!B:T,5,0) -> 11133759 | C13: =VLOOKUP(A13,PLAN!B:T,6,0) -> 1456045-Q-A | D13: =VLOOKUP(A13,PLAN!B:T,7,0) -> STM180-14S CN | E13: =VLOOKUP(A13,PLAN!B:T,4,0) -> 1001912051 | F13: =VLOOKUP(A13,PLAN!B:T,9,0) -> 46227 | G13: =VLOOKUP(A13,PLAN!B:T,10,0) -> 0103544308 | H13: =VLOOKUP(A13,PLAN!B:T,11,0) -> 260709A40A | I13: =VLOOKUP(A13,PLAN!B:T,12,0) -> 5 | J13: =VLOOKUP(A13,PLAN!B:AB,19,0) -> 46218 | K13: =VLOOKUP(A13,PLAN!B:AB,20,0) -> M5 | O13: =VLOOKUP(A13,PLAN!B:AB,21,0) -> F3 | Q13: =VLOOKUP(A13,PLAN!B:AB,16,0) -> 46217
A14: Jul24-45 | B14: =VLOOKUP(A14,PLAN!B:T,5,0) -> 11133759 | C14: =VLOOKUP(A14,PLAN!B:T,6,0) -> 1456045-Q-A | D14: =VLOOKUP(A14,PLAN!B:T,7,0) -> STM180-14S CN | E14: =VLOOKUP(A14,PLAN!B:T,4,0) -> 1001912052 | F14: =VLOOKUP(A14,PLAN!B:T,9,0) -> 46227 | G14: =VLOOKUP(A14,PLAN!B:T,10,0) -> 0103544309 | H14: =VLOOKUP(A14,PLAN!B:T,11,0) -> 260709A41A | I14: =VLOOKUP(A14,PLAN!B:T,12,0) -> 5 | J14: =VLOOKUP(A14,PLAN!B:AB,19,0) -> 46218 | K14: =VLOOKUP(A14,PLAN!B:AB,20,0) -> M5 | O14: =VLOOKUP(A14,PLAN!B:AB,21,0) -> F3 | Q14: =VLOOKUP(A14,PLAN!B:AB,16,0) -> 46217
A15: Jul24-46 | B15: =VLOOKUP(A15,PLAN!B:T,5,0) -> 11133759 | C15: =VLOOKUP(A15,PLAN!B:T,6,0) -> 1456045-Q-A | D15: =VLOOKUP(A15,PLAN!B:T,7,0) -> STM180-14S CN | E15: =VLOOKUP(A15,PLAN!B:T,4,0) -> 1001912053 | F15: =VLOOKUP(A15,PLAN!B:T,9,0) -> 46227 | G15: =VLOOKUP(A15,PLAN!B:T,10,0) -> 0103544311 | H15: =VLOOKUP(A15,PLAN!B:T,11,0) -> 260709A42A | I15: =VLOOKUP(A15,PLAN!B:T,12,0) -> 5 | J15: =VLOOKUP(A15,PLAN!B:AB,19,0) -> 46218 | K15: =VLOOKUP(A15,PLAN!B:AB,20,0) -> M5 | O15: =VLOOKUP(A15,PLAN!B:AB,21,0) -> F3 | Q15: =VLOOKUP(A15,PLAN!B:AB,16,0) -> 46217
A16: Jul24-47 | B16: =VLOOKUP(A16,PLAN!B:T,5,0) -> 11133759 | C16: =VLOOKUP(A16,PLAN!B:T,6,0) -> 1456045-Q-A | D16: =VLOOKUP(A16,PLAN!B:T,7,0) -> STM180-14S CN | E16: =VLOOKUP(A16,PLAN!B:T,4,0) -> 1001912054 | F16: =VLOOKUP(A16,PLAN!B:T,9,0) -> 46227 | G16: =VLOOKUP(A16,PLAN!B:T,10,0) -> 0103544312 | H16: =VLOOKUP(A16,PLAN!B:T,11,0) -> 260709A43A | I16: =VLOOKUP(A16,PLAN!B:T,12,0) -> 5 | J16: =VLOOKUP(A16,PLAN!B:AB,19,0) -> 46218 | K16: =VLOOKUP(A16,PLAN!B:AB,20,0) -> M5 | O16: =VLOOKUP(A16,PLAN!B:AB,21,0) -> F3 | Q16: =VLOOKUP(A16,PLAN!B:AB,16,0) -> 46217
A17: Jul24-48 | B17: =VLOOKUP(A17,PLAN!B:T,5,0) -> 11133759 | C17: =VLOOKUP(A17,PLAN!B:T,6,0) -> 1456045-Q-A | D17: =VLOOKUP(A17,PLAN!B:T,7,0) -> STM180-14S CN | E17: =VLOOKUP(A17,PLAN!B:T,4,0) -> 1001912055 | F17: =VLOOKUP(A17,PLAN!B:T,9,0) -> 46227 | G17: =VLOOKUP(A17,PLAN!B:T,10,0) -> 0103544313 | H17: =VLOOKUP(A17,PLAN!B:T,11,0) -> 260709A44A | I17: =VLOOKUP(A17,PLAN!B:T,12,0) -> 5 | J17: =VLOOKUP(A17,PLAN!B:AB,19,0) -> 46218 | K17: =VLOOKUP(A17,PLAN!B:AB,20,0) -> M5 | O17: =VLOOKUP(A17,PLAN!B:AB,21,0) -> F3 | Q17: =VLOOKUP(A17,PLAN!B:AB,16,0) -> 46217
A18: Jul24-49 | B18: =VLOOKUP(A18,PLAN!B:T,5,0) -> 11133759 | C18: =VLOOKUP(A18,PLAN!B:T,6,0) -> 1456045-Q-A | D18: =VLOOKUP(A18,PLAN!B:T,7,0) -> STM180-14S CN | E18: =VLOOKUP(A18,PLAN!B:T,4,0) -> 1001912056 | F18: =VLOOKUP(A18,PLAN!B:T,9,0) -> 46227 | G18: =VLOOKUP(A18,PLAN!B:T,10,0) -> 0103544314 | H18: =VLOOKUP(A18,PLAN!B:T,11,0) -> 260709A45A | I18: =VLOOKUP(A18,PLAN!B:T,12,0) -> 5 | J18: =VLOOKUP(A18,PLAN!B:AB,19,0) -> 46218 | K18: =VLOOKUP(A18,PLAN!B:AB,20,0) -> M5 | O18: =VLOOKUP(A18,PLAN!B:AB,21,0) -> F3 | Q18: =VLOOKUP(A18,PLAN!B:AB,16,0) -> 46217
... A103: Aug04-10 | B103: =VLOOKUP(A103,PLAN!B:T,5,0) -> 11134235 | C103: =VLOOKUP(A103,PLAN!B:T,6,0) -> 1036068-S-AK | D103: =VLOOKUP(A103,PLAN!B:T,7,0) -> AHW14R001S CN | E103: =VLOOKUP(A103,PLAN!B:T,4,0) -> 1001921504 | F103: =VLOOKUP(A103,PLAN!B:T,9,0) -> 46238 | G103: =VLOOKUP(A103,PLAN!B:T,10,0) -> 0103563270 | H103: =VLOOKUP(A103,PLAN!B:T,11,0) -> 260720A25A | I103: =VLOOKUP(A103,PLAN!B:T,12,0) -> 2386 | J103: =VLOOKUP(A103,PLAN!B:AB,19,0) -> 46230 | K103: =VLOOKUP(A103,PLAN!B:AB,20,0) -> M8 | O103: =VLOOKUP(A103,PLAN!B:AB,21,0) -> CAG | Q103: =VLOOKUP(A103,PLAN!B:AB,16,0) -> 46227
A104: QA-260025-01 | B104: =VLOOKUP(A104,PLAN!B:T,5,0) -> 11105841 | C104: =VLOOKUP(A104,PLAN!B:T,6,0) -> AJ2401173-01-A | D104: =VLOOKUP(A104,PLAN!B:T,7,0) -> WAIN-CKI-300-RC CN | E104: =VLOOKUP(A104,PLAN!B:T,4,0) -> 2000127641 | F104: =VLOOKUP(A104,PLAN!B:T,9,0) -> 46234 | G104: =VLOOKUP(A104,PLAN!B:T,10,0) -> 0103565404 | H104: =VLOOKUP(A104,PLAN!B:T,11,0) -> 260720Y08A | I104: =VLOOKUP(A104,PLAN!B:T,12,0) -> 3 | J104: =VLOOKUP(A104,PLAN!B:AB,19,0) -> N/A | K104: =VLOOKUP(A104,PLAN!B:AB,20,0) -> 0 | O104: =VLOOKUP(A104,PLAN!B:AB,21,0) -> F2 | Q104: Bio-1
A105: QA-260025-02 | B105: =VLOOKUP(A105,PLAN!B:T,5,0) -> 11105841 | C105: =VLOOKUP(A105,PLAN!B:T,6,0) -> AJ2401173-01-A | D105: =VLOOKUP(A105,PLAN!B:T,7,0) -> WAIN-CKI-300-RC CN | E105: =VLOOKUP(A105,PLAN!B:T,4,0) -> 2000127642 | F105: =VLOOKUP(A105,PLAN!B:T,9,0) -> 46234 | G105: =VLOOKUP(A105,PLAN!B:T,10,0) -> 0103565406 | H105: =VLOOKUP(A105,PLAN!B:T,11,0) -> 260720Y08D | I105: =VLOOKUP(A105,PLAN!B:T,12,0) -> 9 | J105: =VLOOKUP(A105,PLAN!B:AB,19,0) -> 46241 | K105: =VLOOKUP(A105,PLAN!B:AB,20,0) -> 0 | O105: =VLOOKUP(A105,PLAN!B:AB,21,0) -> F2 | Q105: Bio-1
A106: QA-260025-03 | B106: =VLOOKUP(A106,PLAN!B:T,5,0) -> 11105841 | C106: =VLOOKUP(A106,PLAN!B:T,6,0) -> AJ2401173-01-A | D106: =VLOOKUP(A106,PLAN!B:T,7,0) -> WAIN-CKI-300-RC CN | E106: =VLOOKUP(A106,PLAN!B:T,4,0) -> 2000127643 | F106: =VLOOKUP(A106,PLAN!B:T,9,0) -> 46234 | G106: =VLOOKUP(A106,PLAN!B:T,10,0) -> 0103565408 | H106: =VLOOKUP(A106,PLAN!B:T,11,0) -> 260720Y09A | I106: =VLOOKUP(A106,PLAN!B:T,12,0) -> 16 | J106: =VLOOKUP(A106,PLAN!B:AB,19,0) -> 46241 | K106: =VLOOKUP(A106,PLAN!B:AB,20,0) -> 0 | O106: =VLOOKUP(A106,PLAN!B:AB,21,0) -> F2 | Q106: Bio-1
A107: QA-260025-04 | B107: =VLOOKUP(A107,PLAN!B:T,5,0) -> 11105842 | C107: =VLOOKUP(A107,PLAN!B:T,6,0) -> AJ2401170-01-A | D107: =VLOOKUP(A107,PLAN!B:T,7,0) -> WAIN-CKI-300-RC MDR | E107: =VLOOKUP(A107,PLAN!B:T,4,0) -> 2000127644 | F107: =VLOOKUP(A107,PLAN!B:T,9,0) -> 46234 | G107: =VLOOKUP(A107,PLAN!B:T,10,0) -> 0103565410 | H107: =VLOOKUP(A107,PLAN!B:T,11,0) -> 260720Y10A | I107: =VLOOKUP(A107,PLAN!B:T,12,0) -> 40 | J107: =VLOOKUP(A107,PLAN!B:AB,19,0) -> 46241 | K107: =VLOOKUP(A107,PLAN!B:AB,20,0) -> 0 | O107: =VLOOKUP(A107,PLAN!B:AB,21,0) -> F2 | Q107: Bio-1
A108: QA-260025-05 | B108: =VLOOKUP(A108,PLAN!B:T,5,0) -> 11105842 | C108: =VLOOKUP(A108,PLAN!B:T,6,0) -> AJ2401170-01-A | D108: =VLOOKUP(A108,PLAN!B:T,7,0) -> WAIN-CKI-300-RC MDR | E108: =VLOOKUP(A108,PLAN!B:T,4,0) -> 2000127645 | F108: =VLOOKUP(A108,PLAN!B:T,9,0) -> 46234 | G108: =VLOOKUP(A108,PLAN!B:T,10,0) -> 0103565412 | H108: =VLOOKUP(A108,PLAN!B:T,11,0) -> 260720Y11A | I108: =VLOOKUP(A108,PLAN!B:T,12,0) -> 20 | J108: =VLOOKUP(A108,PLAN!B:AB,19,0) -> 46241 | K108: =VLOOKUP(A108,PLAN!B:AB,20,0) -> 0 | O108: =VLOOKUP(A108,PLAN!B:AB,21,0) -> F2 | Q108: Bio-1
A109: QA-260025-06 | B109: =VLOOKUP(A109,PLAN!B:T,5,0) -> 11105842 | C109: =VLOOKUP(A109,PLAN!B:T,6,0) -> AJ2401170-01-A | D109: =VLOOKUP(A109,PLAN!B:T,7,0) -> WAIN-CKI-300-RC MDR | E109: =VLOOKUP(A109,PLAN!B:T,4,0) -> 2000127646 | F109: =VLOOKUP(A109,PLAN!B:T,9,0) -> 46234 | G109: =VLOOKUP(A109,PLAN!B:T,10,0) -> 0103565414 | H109: =VLOOKUP(A109,PLAN!B:T,11,0) -> 260720Y12A | I109: =VLOOKUP(A109,PLAN!B:T,12,0) -> 3 | J109: =VLOOKUP(A109,PLAN!B:AB,19,0) -> N/A | K109: =VLOOKUP(A109,PLAN!B:AB,20,0) -> 0 | O109: =VLOOKUP(A109,PLAN!B:AB,21,0) -> F2 | Q109: Bio-1
A110: QA-260025-07 | B110: =VLOOKUP(A110,PLAN!B:T,5,0) -> 11105842 | C110: =VLOOKUP(A110,PLAN!B:T,6,0) -> AJ2401170-01-A | D110: =VLOOKUP(A110,PLAN!B:T,7,0) -> WAIN-CKI-300-RC MDR | E110: =VLOOKUP(A110,PLAN!B:T,4,0) -> 2000127647 | F110: =VLOOKUP(A110,PLAN!B:T,9,0) -> 46234 | G110: =VLOOKUP(A110,PLAN!B:T,10,0) -> 0103565416 | H110: =VLOOKUP(A110,PLAN!B:T,11,0) -> 260720Y13A | I110: =VLOOKUP(A110,PLAN!B:T,12,0) -> 10 | J110: =VLOOKUP(A110,PLAN!B:AB,19,0) -> 46241 | K110: =VLOOKUP(A110,PLAN!B:AB,20,0) -> 0 | O110: =VLOOKUP(A110,PLAN!B:AB,21,0) -> F2 | Q110: Bio-1
A111: QA-260025-08 | B111: =VLOOKUP(A111,PLAN!B:T,5,0) -> 11105842 | C111: =VLOOKUP(A111,PLAN!B:T,6,0) -> AJ2401170-01-A | D111: =VLOOKUP(A111,PLAN!B:T,7,0) -> WAIN-CKI-300-RC MDR | E111: =VLOOKUP(A111,PLAN!B:T,4,0) -> 2000127648 | F111: =VLOOKUP(A111,PLAN!B:T,9,0) -> 46234 | G111: =VLOOKUP(A111,PLAN!B:T,10,0) -> 0103565418 | H111: =VLOOKUP(A111,PLAN!B:T,11,0) -> 260720Y14A | I111: =VLOOKUP(A111,PLAN!B:T,12,0) -> 3 | J111: =VLOOKUP(A111,PLAN!B:AB,19,0) -> N/A | K111: =VLOOKUP(A111,PLAN!B:AB,20,0) -> 0 | O111: =VLOOKUP(A111,PLAN!B:AB,21,0) -> F2 | Q111: Bio-1
A112: QA-260025-09 | B112: =VLOOKUP(A112,PLAN!B:T,5,0) -> 11105842 | C112: =VLOOKUP(A112,PLAN!B:T,6,0) -> AJ2401170-01-A | D112: =VLOOKUP(A112,PLAN!B:T,7,0) -> WAIN-CKI-300-RC MDR | E112: =VLOOKUP(A112,PLAN!B:T,4,0) -> 2000127649 | F112: =VLOOKUP(A112,PLAN!B:T,9,0) -> 46234 | G112: =VLOOKUP(A112,PLAN!B:T,10,0) -> 0103565420 | H112: =VLOOKUP(A112,PLAN!B:T,11,0) -> 260720Y14D | I112: =VLOOKUP(A112,PLAN!B:T,12,0) -> 9 | J112: =VLOOKUP(A112,PLAN!B:AB,19,0) -> 46241 | K112: =VLOOKUP(A112,PLAN!B:AB,20,0) -> 0 | O112: =VLOOKUP(A112,PLAN!B:AB,21,0) -> F2 | Q112: Bio-1
A113: QA-260025-10 | B113: =VLOOKUP(A113,PLAN!B:T,5,0) -> 11105842 | C113: =VLOOKUP(A113,PLAN!B:T,6,0) -> AJ2401170-01-A | D113: =VLOOKUP(A113,PLAN!B:T,7,0) -> WAIN-CKI-300-RC MDR | E113: =VLOOKUP(A113,PLAN!B:T,4,0) -> 2000127650 | F113: =VLOOKUP(A113,PLAN!B:T,9,0) -> 46234 | G113: =VLOOKUP(A113,PLAN!B:T,10,0) -> 0103565422 | H113: =VLOOKUP(A113,PLAN!B:T,11,0) -> 260720Y15A | I113: =VLOOKUP(A113,PLAN!B:T,12,0) -> 15 | J113: =VLOOKUP(A113,PLAN!B:AB,19,0) -> 46241 | K113: =VLOOKUP(A113,PLAN!B:AB,20,0) -> 0 | O113: =VLOOKUP(A113,PLAN!B:AB,21,0) -> F2 | Q113: Bio-1
A114: QA-260025-11 | B114: =VLOOKUP(A114,PLAN!B:T,5,0) -> 11105843 | C114: =VLOOKUP(A114,PLAN!B:T,6,0) -> AJ2401189-01-A | D114: =VLOOKUP(A114,PLAN!B:T,7,0) -> WAIN-CKI-200-BS CN | E114: =VLOOKUP(A114,PLAN!B:T,4,0) -> 2000127651 | F114: =VLOOKUP(A114,PLAN!B:T,9,0) -> 46234 | G114: =VLOOKUP(A114,PLAN!B:T,10,0) -> 0103565424 | H114: =VLOOKUP(A114,PLAN!B:T,11,0) -> 260720Y16A | I114: =VLOOKUP(A114,PLAN!B:T,12,0) -> 3 | J114: =VLOOKUP(A114,PLAN!B:AB,19,0) -> N/A | K114: =VLOOKUP(A114,PLAN!B:AB,20,0) -> 0 | O114: =VLOOKUP(A114,PLAN!B:AB,21,0) -> F2 | Q114: Bio-1
A115: QA-260025-12 | B115: =VLOOKUP(A115,PLAN!B:T,5,0) -> 11105843 | C115: =VLOOKUP(A115,PLAN!B:T,6,0) -> AJ2401189-01-A | D115: =VLOOKUP(A115,PLAN!B:T,7,0) -> WAIN-CKI-200-BS CN | E115: =VLOOKUP(A115,PLAN!B:T,4,0) -> 2000127652 | F115: =VLOOKUP(A115,PLAN!B:T,9,0) -> 46234 | G115: =VLOOKUP(A115,PLAN!B:T,10,0) -> 0103565426 | H115: =VLOOKUP(A115,PLAN!B:T,11,0) -> 260720Y16B | I115: =VLOOKUP(A115,PLAN!B:T,12,0) -> 6 | J115: =VLOOKUP(A115,PLAN!B:AB,19,0) -> 46241 | K115: =VLOOKUP(A115,PLAN!B:AB,20,0) -> 0 | O115: =VLOOKUP(A115,PLAN!B:AB,21,0) -> F2 | Q115: Bio-1
A116: QA-260025-13 | B116: =VLOOKUP(A116,PLAN!B:T,5,0) -> 11105843 | C116: =VLOOKUP(A116,PLAN!B:T,6,0) -> AJ2401189-01-A | D116: =VLOOKUP(A116,PLAN!B:T,7,0) -> WAIN-CKI-200-BS CN | E116: =VLOOKUP(A116,PLAN!B:T,4,0) -> 2000127653 | F116: =VLOOKUP(A116,PLAN!B:T,9,0) -> 46234 | G116: =VLOOKUP(A116,PLAN!B:T,10,0) -> 0103565428 | H116: =VLOOKUP(A116,PLAN!B:T,11,0) -> 260720Y16D | I116: =VLOOKUP(A116,PLAN!B:T,12,0) -> 9 | J116: =VLOOKUP(A116,PLAN!B:AB,19,0) -> 46241 | K116: =VLOOKUP(A116,PLAN!B:AB,20,0) -> 0 | O116: =VLOOKUP(A116,PLAN!B:AB,21,0) -> F2 | Q116: Bio-1
A117: Aug05-01 | B117: =VLOOKUP(A117,PLAN!B:T,5,0) -> 11134235 | C117: =VLOOKUP(A117,PLAN!B:T,6,0) -> 1036068-S-AK | D117: =VLOOKUP(A117,PLAN!B:T,7,0) -> AHW14R001S CN | E117: =VLOOKUP(A117,PLAN!B:T,4,0) -> 1001923820 | F117: =VLOOKUP(A117,PLAN!B:T,9,0) -> 46239 | G117: =VLOOKUP(A117,PLAN!B:T,10,0) -> 0103567533 | H117: =VLOOKUP(A117,PLAN!B:T,11,0) -> 260721A01A | I117: =VLOOKUP(A117,PLAN!B:T,12,0) -> 3586 | J117: =VLOOKUP(A117,PLAN!B:AB,19,0) -> 46231 | K117: =VLOOKUP(A117,PLAN!B:AB,20,0) -> M1 | O117: =VLOOKUP(A117,PLAN!B:AB,21,0) -> F3 | Q117: =VLOOKUP(A117,PLAN!B:AB,16,0) -> 46230
A118: Aug05-02 | B118: =VLOOKUP(A118,PLAN!B:T,5,0) -> 11134235 | C118: =VLOOKUP(A118,PLAN!B:T,6,0) -> 1036068-S-AK | D118: =VLOOKUP(A118,PLAN!B:T,7,0) -> AHW14R001S CN | E118: =VLOOKUP(A118,PLAN!B:T,4,0) -> 1001923821 | F118: =VLOOKUP(A118,PLAN!B:T,9,0) -> 46239 | G118: =VLOOKUP(A118,PLAN!B:T,10,0) -> 0103567534 | H118: =VLOOKUP(A118,PLAN!B:T,11,0) -> 260721A02A | I118: =VLOOKUP(A118,PLAN!B:T,12,0) -> 3586 | J118: =VLOOKUP(A118,PLAN!B:AB,19,0) -> 46231 | K118: =VLOOKUP(A118,PLAN!B:AB,20,0) -> M2 | O118: =VLOOKUP(A118,PLAN!B:AB,21,0) -> F3 | Q118: =VLOOKUP(A118,PLAN!B:AB,16,0) -> 46230
A119: Aug05-03 | B119: =VLOOKUP(A119,PLAN!B:T,5,0) -> 11134237 | C119: =VLOOKUP(A119,PLAN!B:T,6,0) -> 1436196-Q-A | D119: =VLOOKUP(A119,PLAN!B:T,7,0) -> AHW14R004S CN | E119: =VLOOKUP(A119,PLAN!B:T,4,0) -> 1001923822 | F119: =VLOOKUP(A119,PLAN!B:T,9,0) -> 46239 | G119: =VLOOKUP(A119,PLAN!B:T,10,0) -> 0103567535 | H119: =VLOOKUP(A119,PLAN!B:T,11,0) -> 260721A03A | I119: =VLOOKUP(A119,PLAN!B:T,12,0) -> 2389 | J119: =VLOOKUP(A119,PLAN!B:AB,19,0) -> 46231 | K119: =VLOOKUP(A119,PLAN!B:AB,20,0) -> M3 | O119: =VLOOKUP(A119,PLAN!B:AB,21,0) -> F3 | Q119: =VLOOKUP(A119,PLAN!B:AB,16,0) -> 46230
A120: Auh15-01 | B120: =VLOOKUP(A120,PLAN!B:T,5,0) -> 11133764 | C120: =VLOOKUP(A120,PLAN!B:T,6,0) -> 1456050-Q-A | D120: =VLOOKUP(A120,PLAN!B:T,7,0) -> STM180-18S CN | E120: =VLOOKUP(A120,PLAN!B:T,4,0) -> 1001923823 | F120: =VLOOKUP(A120,PLAN!B:T,9,0) -> 46249 | G120: =VLOOKUP(A120,PLAN!B:T,10,0) -> 0103567536 | H120: =VLOOKUP(A120,PLAN!B:T,11,0) -> 260721A04A | I120: =VLOOKUP(A120,PLAN!B:T,12,0) -> 482 | J120: =VLOOKUP(A120,PLAN!B:AB,19,0) -> 46231 | K120: =VLOOKUP(A120,PLAN!B:AB,20,0) -> M4 | O120: =VLOOKUP(A120,PLAN!B:AB,21,0) -> F3 | Q120: =VLOOKUP(A120,PLAN!B:AB,16,0) -> 46230
A121: Auh15-02 | B121: =VLOOKUP(A121,PLAN!B:T,5,0) -> 11133764 | C121: =VLOOKUP(A121,PLAN!B:T,6,0) -> 1456050-Q-A | D121: =VLOOKUP(A121,PLAN!B:T,7,0) -> STM180-18S CN | E121: =VLOOKUP(A121,PLAN!B:T,4,0) -> 1001923824 | F121: =VLOOKUP(A121,PLAN!B:T,9,0) -> 46249 | G121: =VLOOKUP(A121,PLAN!B:T,10,0) -> 0103567537 | H121: =VLOOKUP(A121,PLAN!B:T,11,0) -> 260721A05A | I121: =VLOOKUP(A121,PLAN!B:T,12,0) -> 1659 | J121: =VLOOKUP(A121,PLAN!B:AB,19,0) -> 46231 | K121: =VLOOKUP(A121,PLAN!B:AB,20,0) -> M4 | O121: =VLOOKUP(A121,PLAN!B:AB,21,0) -> F3 | Q121: =VLOOKUP(A121,PLAN!B:AB,16,0) -> 46230
A122: Aug05-04 | B122: =VLOOKUP(A122,PLAN!B:T,5,0) -> 11134241 | C122: =VLOOKUP(A122,PLAN!B:T,6,0) -> 1436298-J-AK | D122: =VLOOKUP(A122,PLAN!B:T,7,0) -> APW14R005S CN | E122: =VLOOKUP(A122,PLAN!B:T,4,0) -> 1001923825 | F122: =VLOOKUP(A122,PLAN!B:T,9,0) -> 46239 | G122: =VLOOKUP(A122,PLAN!B:T,10,0) -> 0103567538 | H122: =VLOOKUP(A122,PLAN!B:T,11,0) -> 260721A06A | I122: =VLOOKUP(A122,PLAN!B:T,12,0) -> 124 | J122: =VLOOKUP(A122,PLAN!B:AB,19,0) -> 46231 | K122: =VLOOKUP(A122,PLAN!B:AB,20,0) -> M5 | O122: =VLOOKUP(A122,PLAN!B:AB,21,0) -> F3 | Q122: =VLOOKUP(A122,PLAN!B:AB,16,0) -> 46230
A123: Aug05-05 | B123: =VLOOKUP(A123,PLAN!B:T,5,0) -> 11134241 | C123: =VLOOKUP(A123,PLAN!B:T,6,0) -> 1436298-J-AK | D123: =VLOOKUP(A123,PLAN!B:T,7,0) -> APW14R005S CN | E123: =VLOOKUP(A123,PLAN!B:T,4,0) -> 1001923826 | F123: =VLOOKUP(A123,PLAN!B:T,9,0) -> 46239 | G123: =VLOOKUP(A123,PLAN!B:T,10,0) -> 0103567539 | H123: =VLOOKUP(A123,PLAN!B:T,11,0) -> 260721A07A | I123: =VLOOKUP(A123,PLAN!B:T,12,0) -> 3469 | J123: =VLOOKUP(A123,PLAN!B:AB,19,0) -> 46231 | K123: =VLOOKUP(A123,PLAN!B:AB,20,0) -> M5 | O123: =VLOOKUP(A123,PLAN!B:AB,21,0) -> F3 | Q123: =VLOOKUP(A123,PLAN!B:AB,16,0) -> 46230
A124: Aug05-06 | B124: =VLOOKUP(A124,PLAN!B:T,5,0) -> 11134236 | C124: =VLOOKUP(A124,PLAN!B:T,6,0) -> 1136431-Q-AK | D124: =VLOOKUP(A124,PLAN!B:T,7,0) -> AHW14R007P CN | E124: =VLOOKUP(A124,PLAN!B:T,4,0) -> 1001923827 | F124: =VLOOKUP(A124,PLAN!B:T,9,0) -> 46239 | G124: =VLOOKUP(A124,PLAN!B:T,10,0) -> 0103567540 | H124: =VLOOKUP(A124,PLAN!B:T,11,0) -> 260721A08A | I124: =VLOOKUP(A124,PLAN!B:T,12,0) -> 190 | J124: =VLOOKUP(A124,PLAN!B:AB,19,0) -> 46231 | K124: =VLOOKUP(A124,PLAN!B:AB,20,0) -> M6 | O124: =VLOOKUP(A124,PLAN!B:AB,21,0) -> F2 | Q124: =VLOOKUP(A124,PLAN!B:AB,16,0) -> 46230
A125: Aug05-07 | B125: =VLOOKUP(A125,PLAN!B:T,5,0) -> 11134236 | C125: =VLOOKUP(A125,PLAN!B:T,6,0) -> 1136431-Q-AK | D125: =VLOOKUP(A125,PLAN!B:T,7,0) -> AHW14R007P CN | E125: =VLOOKUP(A125,PLAN!B:T,4,0) -> 1001923829 | F125: =VLOOKUP(A125,PLAN!B:T,9,0) -> 46239 | G125: =VLOOKUP(A125,PLAN!B:T,10,0) -> 0103567541 | H125: =VLOOKUP(A125,PLAN!B:T,11,0) -> 260721A09A | I125: =VLOOKUP(A125,PLAN!B:T,12,0) -> 3380 | J125: =VLOOKUP(A125,PLAN!B:AB,19,0) -> 46231 | K125: =VLOOKUP(A125,PLAN!B:AB,20,0) -> M6 | O125: =VLOOKUP(A125,PLAN!B:AB,21,0) -> F2 | Q125: =VLOOKUP(A125,PLAN!B:AB,16,0) -> 46230
...

Sheet seal
A1: DIV/ SECTION | C1: PRODUCTION PLAN FOR STERILIZE (KẾ HOẠCH SẢN XUẤT CỦA PHÒNG STERILIZE) | U1: F- 5740 Ver: 2
A2: GPC/ Order control | U2: Page: / 2
A4: Plan date: | C4: 46258
A5: No | B5: Material | C5: Drawing list No | D5: Item name/ Description | E5: Plnd order / PO | F5: Scheduled Finish Date | G5: Internal Lot (SAP Lot) | H5: External Lot (Hanoi Lot) | I5: Q`ty | J5: Destination | K5: Test Endotoxin ( pcs) | L5: Test Particle ( pcs) | M5: Wip request infomation | S5: Sterilize | U5: Start date (Sealing) | W5: Remark
M6: Item code Type C | N6: Material Type C | O6: Internal Lot (SAP Lot) | P6: External Lot | Q6: Q`ty | R6: Sheft | S6: Date | T6: No | U6: Date | V6: Time | AB6: 2
A7: =Y7 -> Jul23-04 | B7: =IFERROR(VLOOKUP(A7,PLAN!B:AA,5,0),"") -> 11134237 | C7: =IFERROR(VLOOKUP(A7,PLAN!B:AA,6,0),"") -> 1436196-Q-A | D7: =IFERROR(VLOOKUP(A7,PLAN!B:AA,7,0),"") -> AHW14R004S CN | E7: =IFERROR(VLOOKUP(A7,PLAN!B:AA,4,0),"") -> 1001907463 | F7: =IFERROR(VLOOKUP(A7,PLAN!B:AA,9,0),"") -> 46226 | G7: =IFERROR(VLOOKUP(A7,PLAN!B:AA,10,0),"") -> 0103536442 | H7: =IFERROR(VLOOKUP(A7,PLAN!B:AA,11,0),"") -> 260707A29A | I7: =IFERROR(VLOOKUP(A7,PLAN!B:AA,12,0),"") -> 2389 | J7: =IFERROR(VLOOKUP(A7,PLAN!B:AA,15,0),"") -> China | K7: =IFERROR(VLOOKUP(A7,PLAN!B:AA,23,0),"") -> 3 | L7: =IFERROR(VLOOKUP(A7,PLAN!B:AA,24,0),"") -> 0 | M7: =IFERROR(VLOOKUP(A7,PLAN!B:AA,3,0),"") -> 2332200-0-C-CN | N7: =IFERROR(VLOOKUP(A7,PLAN!B:AA,2,0),"") -> 12125012 | O7: 0103443955 | P7: VD26622AAT6 | Q7: 1260 | R7: =IFERROR(VLOOKUP(P7,[6]Sheet1!$F:$I,4,),"") | S7: =IFERROR(VLOOKUP(A7,PLAN!B:AA,19,0),"") -> 46217 | T7: =IFERROR(VLOOKUP(A7,PLAN!B:AA,20,0),"") -> M3 | W7: =IFERROR(VLOOKUP(A7,PLAN!B:AB,21,),"") -> F3 | Y7: Jul23-04 | Z7: =VLOOKUP(Y7,PLAN!B:AI,19,0) -> 46217
O8: 0103452653 | P8: VD26623AAT9 | Q8: =I7-Q7 -> 1129 | W8: F3 | Z8: 46217
A9: =Y9 -> Jul24-40 | B9: =IFERROR(VLOOKUP(A9,PLAN!B:AA,5,0),"") -> 11133759 | C9: =IFERROR(VLOOKUP(A9,PLAN!B:AA,6,0),"") -> 1456045-Q-A | D9: =IFERROR(VLOOKUP(A9,PLAN!B:AA,7,0),"") -> STM180-14S CN | E9: =IFERROR(VLOOKUP(A9,PLAN!B:AA,4,0),"") -> 1001912046 | F9: =IFERROR(VLOOKUP(A9,PLAN!B:AA,9,0),"") -> 46227 | G9: =IFERROR(VLOOKUP(A9,PLAN!B:AA,10,0),"") -> 0103544302 | H9: =IFERROR(VLOOKUP(A9,PLAN!B:AA,11,0),"") -> 260709A36A | I9: =IFERROR(VLOOKUP(A9,PLAN!B:AA,12,0),"") -> 5 | J9: =IFERROR(VLOOKUP(A9,PLAN!B:AA,15,0),"") -> China | K9: =IFERROR(VLOOKUP(A9,PLAN!B:AA,23,0),"") -> 0 | L9: =IFERROR(VLOOKUP(A9,PLAN!B:AA,24,0),"") -> 0 | M9: =IFERROR(VLOOKUP(A9,PLAN!B:AA,3,0),"") -> 2332447-0-C-CN | N9: =IFERROR(VLOOKUP(A9,PLAN!B:AA,2,0),"") -> 12125021 | O9: 0103510415 | P9: VD26622A8-NU | Q9: =I9 -> 5 | R9: =IFERROR(VLOOKUP(P9,[6]Sheet1!$F:$I,4,),"") -> N1-15 | S9: =IFERROR(VLOOKUP(A9,PLAN!B:AA,19,0),"") -> 46218 | T9: =IFERROR(VLOOKUP(A9,PLAN!B:AA,20,0),"") -> M5 | W9: =IFERROR(VLOOKUP(A9,PLAN!B:AB,21,),"") -> F3 | Y9: Jul24-40 | Z9: =VLOOKUP(Y9,PLAN!B:AI,19,0) -> 46218
A10: =Y10 -> Jul24-41 | B10: =IFERROR(VLOOKUP(A10,PLAN!B:AA,5,0),"") -> 11133759 | C10: =IFERROR(VLOOKUP(A10,PLAN!B:AA,6,0),"") -> 1456045-Q-A | D10: =IFERROR(VLOOKUP(A10,PLAN!B:AA,7,0),"") -> STM180-14S CN | E10: =IFERROR(VLOOKUP(A10,PLAN!B:AA,4,0),"") -> 1001912047 | F10: =IFERROR(VLOOKUP(A10,PLAN!B:AA,9,0),"") -> 46227 | G10: =IFERROR(VLOOKUP(A10,PLAN!B:AA,10,0),"") -> 0103544305 | H10: =IFERROR(VLOOKUP(A10,PLAN!B:AA,11,0),"") -> 260709A37A | I10: =IFERROR(VLOOKUP(A10,PLAN!B:AA,12,0),"") -> 5 | J10: =IFERROR(VLOOKUP(A10,PLAN!B:AA,15,0),"") -> China | K10: =IFERROR(VLOOKUP(A10,PLAN!B:AA,23,0),"") -> 0 | L10: =IFERROR(VLOOKUP(A10,PLAN!B:AA,24,0),"") -> 0 | M10: =IFERROR(VLOOKUP(A10,PLAN!B:AA,3,0),"") -> 2332447-0-C-CN | N10: =IFERROR(VLOOKUP(A10,PLAN!B:AA,2,0),"") -> 12125021 | O10: 0103510415 | P10: VD26622A8-NU | Q10: =I10 -> 5 | R10: =IFERROR(VLOOKUP(P10,[6]Sheet1!$F:$I,4,),"") -> N1-15 | S10: =IFERROR(VLOOKUP(A10,PLAN!B:AA,19,0),"") -> 46218 | T10: =IFERROR(VLOOKUP(A10,PLAN!B:AA,20,0),"") -> M5 | W10: =IFERROR(VLOOKUP(A10,PLAN!B:AB,21,),"") -> F3 | Y10: Jul24-41 | Z10: =VLOOKUP(Y10,PLAN!B:AI,19,0) -> 46218
A11: =Y11 -> Jul24-42 | B11: =IFERROR(VLOOKUP(A11,PLAN!B:AA,5,0),"") -> 11133759 | C11: =IFERROR(VLOOKUP(A11,PLAN!B:AA,6,0),"") -> 1456045-Q-A | D11: =IFERROR(VLOOKUP(A11,PLAN!B:AA,7,0),"") -> STM180-14S CN | E11: =IFERROR(VLOOKUP(A11,PLAN!B:AA,4,0),"") -> 1001912048 | F11: =IFERROR(VLOOKUP(A11,PLAN!B:AA,9,0),"") -> 46227 | G11: =IFERROR(VLOOKUP(A11,PLAN!B:AA,10,0),"") -> 0103544306 | H11: =IFERROR(VLOOKUP(A11,PLAN!B:AA,11,0),"") -> 260709A38A | I11: =IFERROR(VLOOKUP(A11,PLAN!B:AA,12,0),"") -> 5 | J11: =IFERROR(VLOOKUP(A11,PLAN!B:AA,15,0),"") -> China | K11: =IFERROR(VLOOKUP(A11,PLAN!B:AA,23,0),"") -> 0 | L11: =IFERROR(VLOOKUP(A11,PLAN!B:AA,24,0),"") -> 0 | M11: =IFERROR(VLOOKUP(A11,PLAN!B:AA,3,0),"") -> 2332447-0-C-CN | N11: =IFERROR(VLOOKUP(A11,PLAN!B:AA,2,0),"") -> 12125021 | O11: 0103510415 | P11: VD26622A8-NU | Q11: =I11 -> 5 | R11: =IFERROR(VLOOKUP(P11,[6]Sheet1!$F:$I,4,),"") -> N1-15 | S11: =IFERROR(VLOOKUP(A11,PLAN!B:AA,19,0),"") -> 46218 | T11: =IFERROR(VLOOKUP(A11,PLAN!B:AA,20,0),"") -> M5 | W11: =IFERROR(VLOOKUP(A11,PLAN!B:AB,21,),"") -> F3 | Y11: Jul24-42 | Z11: =VLOOKUP(Y11,PLAN!B:AI,19,0) -> 46218
A12: =Y12 -> Jul24-43 | B12: =IFERROR(VLOOKUP(A12,PLAN!B:AA,5,0),"") -> 11133759 | C12: =IFERROR(VLOOKUP(A12,PLAN!B:AA,6,0),"") -> 1456045-Q-A | D12: =IFERROR(VLOOKUP(A12,PLAN!B:AA,7,0),"") -> STM180-14S CN | E12: =IFERROR(VLOOKUP(A12,PLAN!B:AA,4,0),"") -> 1001912049 | F12: =IFERROR(VLOOKUP(A12,PLAN!B:AA,9,0),"") -> 46227 | G12: =IFERROR(VLOOKUP(A12,PLAN!B:AA,10,0),"") -> 0103544307 | H12: =IFERROR(VLOOKUP(A12,PLAN!B:AA,11,0),"") -> 260709A39A | I12: =IFERROR(VLOOKUP(A12,PLAN!B:AA,12,0),"") -> 5 | J12: =IFERROR(VLOOKUP(A12,PLAN!B:AA,15,0),"") -> China | K12: =IFERROR(VLOOKUP(A12,PLAN!B:AA,23,0),"") -> 0 | L12: =IFERROR(VLOOKUP(A12,PLAN!B:AA,24,0),"") -> 0 | M12: =IFERROR(VLOOKUP(A12,PLAN!B:AA,3,0),"") -> 2332447-0-C-CN | N12: =IFERROR(VLOOKUP(A12,PLAN!B:AA,2,0),"") -> 12125021 | O12: 0103510415 | P12: VD26622A8-NU | Q12: =I12 -> 5 | R12: =IFERROR(VLOOKUP(P12,[6]Sheet1!$F:$I,4,),"") -> N1-15 | S12: =IFERROR(VLOOKUP(A12,PLAN!B:AA,19,0),"") -> 46218 | T12: =IFERROR(VLOOKUP(A12,PLAN!B:AA,20,0),"") -> M5 | W12: =IFERROR(VLOOKUP(A12,PLAN!B:AB,21,),"") -> F3 | Y12: Jul24-43 | Z12: =VLOOKUP(Y12,PLAN!B:AI,19,0) -> 46218
